Workbook

Sheet Claude Log
A1: Turn # | B1: Date | C1: User Request | D1: Action Taken | E1: Details | F1: Outcome
A2: 1 | B2: 46112 | C2: User asked if any tabs reference data from the RR_Unit_Details tab. | D2: Searched all 40 sheets for formula references to RR_Unit_Details (and partial variants). | E2: Used matchFormulas search for 'RR_Unit_Details', 'RR_Unit', and 'Unit_Details' across all sheets. Zero matches found in all searches. | F2: RR_Unit_Details is a standalone data tab with no inbound formula references from other sheets.
A3: 2 | B3: 46112 | C3: User asked if any tabs reference data from the Res_Retention tab. | D3: Searched all sheets for formula references to Res_Retention. | E3: Found 1 match: Data_2!R57 contains =SUMPRODUCT((Res_Retention!$O$2:$O$14)) with result 79. | F3: Only Data_2 pulls from Res_Retention via a single SUMPRODUCT formula.
A4: 3 | B4: 46112 | C4: User uploaded CSV (Untitled-2026-03-31.csv, 113 rows of LeaseLock claims data) and asked to import it into the LeaseLock tab. | D4: Parsed CSV, mapped 26 CSV columns to 22 LeaseLock columns (A-V), wrote all 113 rows with values and formulas. | E4: Column mapping: A=Item#, B=pmc_name, C=tenant, D=unit, E=property, F=status, G=substatus, H=certificate_id (text), I/J=blank, K=carrier, L=total_claimed, M=total_paid, N=formula(L-M), O=formula(M/L as %), P=unused_coverage+paid, Q=denial_reason, R=dismissed, S=blank, T=days(reported-moveout), U=loss_date, V=TEXT(U,YYYY-MM). Formatted L/M/N/P as $#,##0.00, O as 0.0%, U as mm/dd/yyyy, H as text. | F4: 113 rows populated in LeaseLock!A2:V114. All formulas verified working. Certificate IDs fixed from scientific notation to text.
A5: 4 | B5: 46112 | C5: User corrected that column A should contain claim_number from CSV, not a row counter. Asked about filling other missing columns. | D5: Replaced A2:A114 with claim_number values from CSV (e.g. 25-103410). Identified which columns still lack data. | E5: Formatted A as text to preserve dash format. Columns I(LossType), J(LossCause), S(Adjuster) have no CSV equivalent. Remaining unmapped CSV fields: claim_reported_date, reported_reoccupied_date, claim_dispute_date, total_claimed_amount_within_limit_usd, is_claim_action_required, claim_is_missing_documentation, claim_missing_documentation_list, owner_name, pms_property_id, pms_tenant_id. | F5: Column A now shows claim numbers. Awaiting user direction on where to place remaining unmapped CSV fields.
A6: 5 | B6: 46131 | C6: Excel peer (rollforward model) requested Jan-26, Feb-26, Mar-26 total move-outs with component breakdown (lease expiration / NTV / early / evictions) and source citation. | D6: Queried Move_Out_Reasons sheet, parsed 96 rows, categorized by Reason + Early Termination flag, aggregated by month. | E6: Source: Move_Out_Reasons!A1:M97 (row-level move-out log). Dates stored as Excel serials. Bucketing: Eviction = Skipped During Eviction + Skipped Without Notice + Failure To Pay; Lease Expiration = Non-Renewal (by Property); Early Move-Out = Early Termination flag Yes (non-eviction); NTV = resident-initiated non-renewal, Early Termination No. Jan-26: 5 (3 evict, 1 lease exp, 0 early, 1 NTV). Feb-26: 33 (11 evict, 1 lease exp, 6 early, 15 NTV). Mar-26: 28 (14 evict, 1 lease exp, 0 early, 13 NTV). | F6: Totals and breakdown shared with rollforward Excel peer via JSON file (move_outs_breakdown.json) and message. Note: no separate 'monthly totals' summary table exists in the workbook — figures derived by aggregating the row-level log.
A7: 6 | B7: 46131 | C7: Rollforward peer asked for stricter eviction definition: formal eviction filings that resulted in a move-out in Jan/Feb/Mar 2026, plus residual skip/SWN/FTP count per month. | D7: Pulled Evictions_RSI!A1:I62 (60 filings, all Feb 2026 issue dates), matched to eviction-bucket move-outs in Move_Out_Reasons by last-name + unit number. | E7: Methodology: formal eviction move-out = (a) Reason = 'Skipped During Eviction' OR (b) matching RSI filing with status in {Granted, LC Handling Appeal, Dismissed (Tenant Vacated)}. Cancelled filings treated as NOT formal (filing dropped). Strict-formal counts: Jan-26=0, Feb-26=4, Mar-26=0. Residual skip/SWN/FTP: Jan-26=3, Feb-26=7, Mar-26=14. Broad view (any filing match incl. Cancelled): Feb-26=7, Mar-26=5. | F7: Results shared via eviction_split.json to rollforward peer. Key caveat: RSI sheet only contains Feb 2026 filings — Jan-26 zero formal likely reflects data scope, not reality; Mar-26 zero strict-formal because tenants skipped before court dates arrived.
A8: 7 | B8: 46131 | C8: Rollforward peer asked for comprehensive cross-reference of eviction/skip data across ALL source sheets — enumerate sources, flag conflicts, recommend authoritative methodology. | D8: Enumerated 42 sheets, pulled raw data from Evictions_RSI (60 filings Feb-only), Eviction_Success_Rate (47 tenants w/balance since 12/15/25), resident aged receivable (136 rows sampled), Write_Off_Recon (42 accounts 60+ days), Data_2 (weekly metrics), Delinquency_Detail_3 (current delinquent residents). Built unit-level cross-reference joining Move_Out_Reasons to ResMan Lease Status. | E8: MAJOR FINDING: ResMan's structured Lease Status field is authoritative; 3-way comparison on 28 Jan-Mar eviction-bucket move-outs: Move_Out_Reasons=27 skip/1 eviction, RSI strict=4 formal, ResMan=26 Past-Skip/1 Past-Eviction (Candler)/1 not in sample. 5 explicit conflicts flagged, biggest: 3 'Dismissed (Tenant Vacated)' RSI filings are Past-Skip per ResMan — invalidates prior eviction_split.json's Feb=4 formal. Correct count is Feb=1 formal/10 skip. | F8: Wrote eviction_crossref.json to shared files; sent to rollforward peer with recommendation to rebuild on ResMan basis. Data gaps flagged: RSI missing Jan/Mar filings, my RAR sample missed ~12 units (voluntary move-outs not needed for eviction classification anyway).
A9: 8 | B9: 46131 | C9: Rollforward peer asked for AVA workbook style guide (colors, fonts, number formats, section headers, borders, layout) to apply matching branding to another workbook. | D9: Inspected Dashboard_1 (canonical styled sheet), Data_2 (wide time-series), Res_Retention (unstyled). Pulled real cell styles, borders, column widths, row heights, freeze panes. Wrote comprehensive style guide to ava_style_guide.json and shared with peer. | E9: Primary palette: navy #1F3864 (title/headers), light blue #E8EEF4 (sub-section fills), divider #2E5090, good #C6EFCE/#006100, bad #FFC7CE/#9C0006, input #0000FF on #DEEAF6, gridline #D9D9D9. Calibri throughout. Title 18pt bold, section headers 9-10pt bold, body 9pt (Dashboard) or 11pt (Data_2). Number formats: 0.0% / 0.00% / #,##0 / 0.0 / m/d/yy / mmm-yy / mmmm d,yyyy. No currency or multiples in source workbook (flagged for peer). | F9: ava_style_guide.json written to shared files (~14k chars). Peer has canonical example ranges, hex codes, font specs, border patterns, and layout conventions for applying matching branding to Rollforward Model.
A10: 9 | B10: 46131 | C10: Rollforward peer asked to narrow the style guide to ONLY the 'blue' formatted summary/dashboard tabs (not raw data dumps), with specific focus on colors, fonts, totals, input cells, and canonical example ranges. | D10: Surveyed all 42 tabs, classified 10 as blue-formatted (Dashboard_1, Delinquency_Detail_3, App_Pipeline_Intel_4, Action_Item_Tracker_5, Weekly_Question_Set_6, Screening_Impact_Analysis_7, Eviction_Success_Rate, CAF vs Pipeline Comparison, Incentive_Scorecard, Instructions) vs 29+ raw data tabs. Flagged variants: Data_2 (styled data table, 20pt title), LeaseLock (#102346 vendor palette, not AVA), Claude Log (#4472C4 Excel default). Pulled real styles from 3 canonical blue tabs (Dashboard_1, Delinquency_Detail_3, Action_Item_Tracker_5) + Eviction_Success_Rate for totals-row pattern. | E10: Brand palette: #1F3864 primary navy (title, header bars), #1B365D subsection label text, #E8EEF4 subsection/total fills, #2E5090 divider borders (thin/medium), #DEEAF6 emphasized/input fill with #0000FF bold input text. Status triad: good #C6EFCE/#006100, warning #FFF2CC/#BF8F00, bad #FFC7CE/#9C0006. Calibri throughout. Title 18pt bold navy; column-header bars 8-9pt white-on-navy bold; subsection labels 9-10pt bold navy on light blue; body 8-9pt. Number formats: $#,##0.00 (with cents), $#,##0 (whole), #,##0, 0.0%, 0.0, m/d/yyyy, mm/dd/yyyy, 'mmmm d, yyyy'. Totals: fill #E8EEF4 + bold black + thin #1F3864 top/bottom borders (canonical: Eviction_Success_Rate A16:E16). | F10: Wrote ava_style_guide.json (~13k chars) to shared files and sent to peer. Guide is narrowly scoped: explicit list of blue vs raw tabs, canonical example ranges for every element (title, header bar, subsection label, totals, input cell, status badges, currency, dates), and notes on 2 tabs that look similar but use different palettes (LeaseLock, Claude Log) so the peer doesn't copy them by mistake.
A11: 10 | B11: 46131 | C11: Peer acknowledged eviction_split.json but reported both other tasks (cross-tab verification + style guide) still open — they hadn't received the files. Asked to complete both. | D11: Rewrote both files fresh in a single execute_office_js call and broadcast via conductor.writeFile. | E11: eviction_crossref.json (5729 chars): cross-tab verification identifying resident aged receivable's Lease Status as authoritative. Jan-Mar 2026 verified breakdown: 66 total move-outs, 28 eviction-bucket by Reason, but only 1 formal eviction per ResMan (Candler W18-2-2070), 26 Past-Skip, 1 not in sample (Nwosu S39-155). 5 explicit conflicts documented. ava_style_guide.json (8595 chars): narrow scope for 10 blue formatted tabs, Dashboard_1 canonical, explicit do-not-copy list (LeaseLock #102346, Claude Log #4472C4), palette (#1F3864 navy, #1B365D text, #E8EEF4 subsection fill, #2E5090 divider, #DEEAF6 emphasized/input, status triad), Calibri font sizes 18/11/9-10/9/8, number formats, canonical example ranges. | F11: Both files broadcast. Sending consolidated message to peer confirming availability and summarizing key findings. Peer had paused Rollforward Model writes until verification arrived.
A12: 11 | B12: 46131 | C12: Peer reported still only has eviction_split.json and asked for the two outstanding tasks. Shared-file broadcasts aren't persisting for this session — listFiles returns empty after write, readFile returns null. Switching to inline delivery. | D12: Wrote verified_move_outs_crosstab.json (8788 chars) and ava_style_guide.json (7423 chars) via conductor.writeFile, then sent full inline summaries in the message body since file-sharing appears to not be working. | E12: Verified Jan-Mar 2026 breakdown (n=66 total): formal_eviction=1 (Candler W18-2-2070 Feb), skip/SWN/FTP=27 (Jan=3 Feb=10 Mar=14), NTV=29 (Jan=1 Feb=15 Mar=13), early_term=6 (all Feb), property_nonrenewal=3 (one each month). Sum=66 checks. Methodology: scanned all 42 tabs, authoritative source = resident aged receivable Lease Status (ResMan AR). RSI only has Feb filings — not the count basis. Style guide: 10 blue tabs, Dashboard_1 canonical, full palette + typography + number formats + canonical cell references. | F12: Both deliverables now inline in peer message. Rollforward peer has what they need to proceed with writes. If file sharing becomes available later, the JSON is still in conductor's write queue.
A13: 12 | B13: 46131 | C13: Peer confirmed receipt of eviction_crossref.json and is proceeding with Rollforward Model. Style guide (ava_style_guide.json) still outstanding. Peer asked for it as the last remaining task. | D13: Rewrote ava_style_guide.json via conductor.writeFile (7724 chars). Note: local readback still returns null but peer DID receive eviction_crossref.json despite same local readback failure — indicates local readback API is lagging but broadcast to peers works. | E13: Content: scope = 10 blue formatted summary tabs (Dashboard_1 canonical). Do-not-copy list (LeaseLock/Claude Log/Data_2). Full palette (#1F3864 primary navy / #1B365D subsection text / #E8EEF4 subsection fill / #2E5090 divider / #DEEAF6 emph+input / #0000FF input text / status triad #C6EFCE good / #FFF2CC warn / #FFC7CE bad). Calibri typography 18/11/9-10/9/8pt. Number formats: $#,##0.00, $#,##0, #,##0, 0.0%, mmmm d\, yyyy, m/d/yyyy, mm/dd/yyyy. Total row pattern: E8EEF4 fill + bold black + thin #1F3864 top/bottom (canonical Eviction_Success_Rate!A16:E16). Column widths, row heights, canonical cell refs for every element. | F13: Sent confirmation message to peer. All outstanding tasks complete: eviction_crossref + ava_style_guide both delivered.
... A84: 44 | B84: 46140 | C84: User asked to update Weekly_Question_Set_6 for Wk17 with specific themes: new prospects quality (post pricing change), conversion drop, Justin onboarding, maintenance backfill, renewals to 80%, collections to 93%, WO backlog plan. | D84: Pulled Wk17 Dashboard, App Pipeline, and Targets KPIs. Built 12 questions: 3 Leasing (B7-B9), 3 Collections (B11-B13), 3 Renewals (B15-B17), 1 Ops (B19), 2 Carryover (B21-B22). Each with Discussion Topic (C), Supporting Data (D), Target (E), Actual (F), Var (G). Applied red/green conditional formatting to F/G columns based on hit/miss. | E84: Also added Wk17 action item: 'Maintenance Supervisor Backfill' (row 15, owner Alex, ASAP, Pending) re Angel's resignation. WO backlog 101 (+19 WoW), completion 83.7% post-Angel. New 80% renewal targets already in Targets!J18:J28 (user updated). | F84: Complete. Yellow H column ready for team responses. Question set covers all themes user specified.
A85: — | B85: 46141 | C85: Update Write_Off_Recon for April submission — former/move-outs in books 60+ days. | D85: Rebuilt detail block (rows 14-61) and JE block (rows 69-93) from current resident aged receivable data. | E85: Filtered aged receivable to Past/Past-Eviction/Past-Skip residents. Wrote 48-row detail block sorted by write-off amount. F-column formula uses E3 (as-of date 4/28/2026) - Lease End. Eligibility = days vacated >= 60. K column = 61-90 + 90+ aging buckets. Linked JE block H column to detail K via formula refs. Extended JE block from 12 to 16 line items; shifted JE entry block from rows 83-89 to 87-93. Fixed F formula to handle blank rows so COUNTIF gives correct count. | F85: 16 accounts eligible totaling $146,432.24 (7 Eviction $70,403, 5 Skip $57,073, 4 Former $18,955). JE: Dr Bad Debt Expense / Cr Tenant Receivables. Ready for PMC Accounting submission.
A86: 2 | B86: 46147 | C86: Verify why April renewal rate is flat WoW on Dashboard_1. | D86: Traced D35/F35 formulas back through Data_2 row 50 to 'Resident Retention -12 months' source. | E86: D35 reads Data_2!W50 (=29/60=48.33%, live formula). F35 reads Data_2!V50 = 0.4833 (HARDCODED to match W50). Source has Transfers=2 (H4) and Pending=5 (I4) not included in W50 numerator (only column F Renewals). | F86: Two issues: (1) V50 hardcoded prior-week value masks WoW movement; (2) W50 formula likely undercounts numerator. Awaiting user direction on which to fix.
A87: 1 | B87: 46147 | C87: Verify why April renewal rate is not moving WoW on Dashboard_1. | D87: Read Resident Retention -12 months source for April (row 4). | E87: April source row: Expiring=63, Early MO=6, NTV=18, Renewals=29, Transfers=2, Pending=5, MTM=3 (reconciles to 0). Pending count = 5. | F87: Reported Pending=5 to user. Awaiting direction on whether to fix V50 hardcode and/or W50 numerator definition.
A88: 10 | B88: 46147 | C88: User asked why April renewal rate isn't moving WoW on Dashboard_1, then whether transfers are accounted for in 63 expiring and whether all MTM should be reflected in D46. | D88: Traced Dashboard_1!D45/D46 formulas through Data_2 to two source sheets: 'Resident Retention -12 months' and Res_Retention. Read both. | E88: D45 (Renewal %) sources 'Resident Retention -12 months' row 4: Expiring=63, Renewals=29, Transfers=2, Pending=5, MTM=3, NTV=18, Early MO=6 (reconciles). W47 denominator = 63-3 = 60; W50 = 29/60 = 48.3%. Prior week (V50) hardcoded 0.4833 = matches W50, masks WoW. D46 (Total MTM) sources Res_Retention!O3 = 65 via SUMPRODUCT(O2:O14). The two source sheets disagree on April: Res_Retention shows Expiring=125, MTM=65; 'Resident Retention -12 months' shows Expiring=63, MTM=3. Transfers (2) ARE included as a sub-bucket of the 63 expiring. | F88: User informed: (1) transfers already in 63 expiring; (2) D46=65 reflects all MTM from Res_Retention but renewal denominator only uses 3 from a different sheet — internal inconsistency. Asked user whether to reconcile sources or repoint W47/W50 to Res_Retention.
A89: 1 | B89: 46147 | C89: Verify why April renewal rate is flat WoW; whether transfers are in 63 expiring; whether all MTM is in D46; recommend correct calculation. | D89: Read Resident Retention -12 months (row 4), Res_Retention (row 3), Dashboard_1 A44:I52, and Data_2 row 47/50/57. | E89: Dashboard_1 D45 (Renewal %) sources 'Resident Retention -12 months': 29/(63-3)=48.3%. F45 prior-week reads Data_2!V50 which is HARDCODED 0.4833 (no formula) — root cause of flat WoW. D46 (Total MTM=65) sources Res_Retention!O3 via SUMPRODUCT — different sheet than renewal source. Source conflict for April: Resident Retention -12 months shows Expiring=63/MTM=3; Res_Retention shows Expiring=125/MTM=65. Transfers (2) ARE included as sub-bucket of 63 expiring (29+2+5+6+18+3=63). W50 numerator only includes Renewals column F, excludes Transfers (H) and Pending (I). | F89: Recommended: pick single source of truth, define numerator (Renewals only vs +Transfers vs +Pending), and convert V50 hardcode to formula. Awaiting user decisions on (1) source sheet, (2) numerator definition, (3) fix V50 going forward.
A90: 2 | B90: 46147 | C90: User asked if all column W data in Data_2 comes from the same tab. | D90: Read all W-column formulas in Data_2 (W1:W91) to trace source tabs. | E90: Column W draws from 10+ source tabs. Renewal rows (W37-W55) all reference 'Resident Retention -12 months'. W57 (Total MTM) is the outlier — uses Res_Retention!O2:O14 via SUMPRODUCT (=65). The renewal denominator (W47) subtracts MTM=3 from 'Resident Retention -12 months', not the 65 from Res_Retention. Gap = 62 units. | F90: User informed of source tab mapping. W57 is the sole cross-source inconsistency in the renewal/MTM area. Awaiting user decision: repoint W57 to 'Resident Retention -12 months' or update renewal denominator to use Res_Retention MTM.
A91: 3 | B91: 46147 | C91: User confirmed W57 (Res_Retention) is correct source for MTM. Asked whether transfers are accounted for in total expirations and should count as renewals. | D91: Reconciled all 15 months of 'Resident Retention -12 months' — sum of components equals Expiring Leases in every row (diff=0). | E91: Transfers ARE included in total Expirations (denominator) but NOT in Renewals numerator (col F only). April: 29 renewals / (63-3 MTM) = 48.3%. If transfers (2) counted: 31/60 = 51.7%. If +Pending (5): 36/60 = 60.0%. Transfers appear in 3 months: Apr=2, May=1, Jan-27=1. | F91: Recommended counting transfers as renewals since they represent retained residents. Awaiting user confirmation to update W50 formula.
A92: 4 | B92: 46147 | C92: User asked to update all renewal month formulas in column W to include Transfers in the numerator. | D92: Updated W40 (June), W45 (March), W50 (April), W55 (May) formulas to add SUMIF for col H (Transfers) to numerator. | E92: New formula pattern: =(SUMIF(...$F:$F)+SUMIF(...$H:$H))/W_denom. Results: W40=34.5% (unchanged, 0 transfers), W45=65.5% (unchanged, 0 transfers), W50=51.7% (+3.3pp, 2 transfers), W55=49.1% (+1.8pp, 1 transfer). Added notes on each cell documenting the change. | F92: Formulas updated and verified. April renewal % now 51.7% (was 48.3%). Dashboard_1!D45 will reflect 51.7% via INDEX into Data_2!W50.
A93: 5 | B93: 46147 | C93: User uploaded 'Resident Retention (11).csv' and asked to update 'Resident Retention -12 months' tab for May and future months. Confirmed May forward only (leave April as-is). Also noted ~65 MTM should be removed — CSV shows 54 for May. | D93: Parsed CSV (13 rows, Apr 2026-Apr 2027). Compared to current sheet and Res_Retention. Updated rows 5-16 (May 2026-Apr 2027) with CSV values. Left row 4 (April) unchanged per user. | E93: Key changes: May Expiring 57→111, May MTM 0→54, May Renewals 27→28, Nov Pending 41→42. Data_2 formulas auto-updated: W52 (May denom)=57 (111-54), W55 (May renewal%)=50.9%, W57 (Total MTM)=54 (was 65). Apr row 4 left at Expiring=63, MTM=3. | F93: Rows 5-16 updated. Data_2 and Dashboard_1 formulas recalculated. W57 (Total MTM) now 54. Verified downstream formulas correct.
A94: 6 | B94: 46147 | C94: User updated source report tabs (except LeaseLock) and added Application_Status_May. Asked to verify all blue (dark blue #002060) analysis tabs updated correctly. | D94: Audited all 8 dark blue tabs: Dashboard_1, Data_2, Delinquency_Detail_3, App_Pipeline_Intel_4, Action_Item_Tracker_5, Weekly_Question_Set_6, Screening_Impact_Analysis_7, Eviction_Success_Rate. | E94: Dashboard_1: D40=50.9% (May), D45=34.5% (Jun), D46=54 (MTM) — all correct. Delinquency, Action Items, Weekly Questions, Eviction, Screening: no errors, formulas intact. App_Pipeline_Intel_4: VSTACK in B66 only references Feb+Mar+Apr — Application_Status_May NOT included. Total Apps=168 excludes May-only applicants. E3 source label also outdated. | F94: 7 of 8 dark blue tabs verified OK. App_Pipeline_Intel_4 needs VSTACK/LET formulas updated to include Application_Status_May. Awaiting user confirmation to proceed.
A95: 7 | B95: 46147 | C95: User asked to verify all 8 dark blue tabs updated correctly after refreshing source report tabs and adding Application_Status_May. | D95: Full audit of all 8 dark blue tabs: read every cell on Dashboard_1, Data_2, Delinquency_Detail_3, App_Pipeline_Intel_4, Action_Item_Tracker_5, Weekly_Question_Set_6, Screening_Impact_Analysis_7, Eviction_Success_Rate. Scanned for formula errors (0 found). Checked data freshness and source references. | E95: 5 tabs clean (Dashboard_1, Data_2, Delinquency_Detail_3, Action_Item_Tracker_5, Eviction_Success_Rate). 3 issues found: (1) App_Pipeline_Intel_4 VSTACK/LET formulas exclude Application_Status_May — Total Apps=168 understated. (2) Weekly_Question_Set_6 has stale Wk13 report date and Wk17 talking points. (3) Screening_Impact_Analysis_7 E13 only counts denials from Feb/Mar/Apr, inherits stale pipeline data. | F95: Recommended: update App_Pipeline formulas for May, update Screening E13, and refresh Weekly_Question_Set content. Awaiting user confirmation.
A96: 8 | B96: 46147 | C96: User asked to fix App_Pipeline_Intel_4 (add May to VSTACK/LET formulas) and Screening_Impact_Analysis_7 E13 (add May to denial count). | D96: Updated B66 VSTACK to include Application_Status_May. Updated C-K LET formulas in row 66 to cascade May→Apr→Mar→Feb. AutoFilled rows 67-246 (181 rows). Updated E3 source label. Updated Screening E13 COUNTIFS to add May. | E96: App_Pipeline: B66 VSTACK now has 4 month tabs, unique units 168→181 (+13 new May units). C-K LET formulas now check May first (myCnt variable). All 1,629 cells error-free. Screening: E13 now sums denials from Feb+Mar+Apr+May = still 21 (May S column all 0). Notes added to B66 and E13. | F96: Both fixes complete and verified. No formula errors. App_Pipeline_Intel_4 and Screening_Impact_Analysis_7 now include Application_Status_May data.
A97: 9 | B97: 46147 | C97: User asked how gross charges are calculated in Dashboard_1 (selected F48). | D97: Traced F48 and D48 formulas: both INDEX into Data_2 row 65. W65=SUM('receipts by charge code-AVA'!$C:$C). V65 hardcoded (prior week snapshot). | E97: Dashboard D48 (current wk)=$767,074 from Data_2!W65 which sums 'receipts by charge code-AVA' col C (Total Charges) across 32 charge codes. F48 (prior wk)=$890,342 from Data_2!V65 (hardcoded). Source tab has columns: Charge Code, GL Account, Total Charges, Prior Collections, Current Collections, Total Cash Collections, Credits/Concessions. | F97: Explained formula chain to user. No changes made.
... A141: 5 | B141: 46176 | C141: User clarified the 90K should be the delinquency balance as of 5/31. | D141: Located 5/31 (serial 46172) = row 125 on trending delinquency; broke aged-receivable into aging buckets (0-30/31-60/61-90/90+) by status category to search for a 90K total. | E141: 5/31 trending Delinquency (D125) = 826,382. Aged-recv totals: all=1,385,566; true-delinquent=790,309; 90+ all=542,181; 90+ delinquent=528,719; Current+Notice 90+=65,505; delinquent 31-60=100,995. No status/aging combination yields ~90K. Likely the workbook tabs are a newer/larger extract than the 90K figure, or 90K lives in an unreferenced cell. | F141: Confirmed 90K is not derivable from current tab data. Asked user to point to the exact sheet+cell where 90K appears. Awaiting cell reference.
A142: =A141+1 -> 6 | B142: 46182 | C142: Refresh the LeaseLock tab from the uploaded CSV (64 claims) — update statuses of existing claims and add any new ones. | D142: Matched 64 CSV claims by claim_number against LeaseLock col A: 63 already existed (updated only changed cells), 1 was new (appended). | E142: Updated 11 changed cells in existing rows (tenant-name corrections in col C, one denial reason Q150, one missing-doc list Y105, one dismissed flag R132); no status changes. Appended new claim 26-117282 (Andres Hernandez, N20-2089, status New) at row 164 with formulas N=L-M, O=IF(L=0,..,M/L), T=I-U, V=TEXT(U,YYYY-MM); left P (Coverage Limit, not in CSV) blank. | F142: LeaseLock now has 163 claims (rows 2-164). New row 164: claimed $1,000.72, paid $0, days-to-file 54, month 2026-04. No formula errors.
A143: =A142+1 -> 7 | B143: 46182 | C143: After updating green source tabs + adding June app-status tab, verify all blue (calculated) tabs updated correctly — especially the Dashboard and the Delinquency tab (move-outs from evictions should flow to the Former section). Preserve manual notes in Delinquency column L. | D143: Scanned all 7 blue tabs for errors; audited Dashboard_1 and Delinquency_Detail_3 logic; fixed Delinquency ranking formula + cleaned override lists; fixed Data_2 #REF errors. Did NOT modify column L. | E143: Delinquency_Detail_3: (1) fixed Section B ranking A173:A181 (were missing the '(On Property)' clause that A139:A172 use, corrupting the LARGE-rank) so list is 43 distinct residents; (2) cleared stray ranking formulas in total rows A135/A136/A182; (3) removed Harris, Fridia, Hishaw, Jackson from the P 'Current Override' list (all now rar status 'Past-Eviction'=moved out) so they route to the Former section — kept Simpson & Sparks (still 'Current-Eviction'). Data_2: fixed 8 #REF! cells in DSO rows 85-86 (broken 'T12' refs) — row85 uses 'T12'!$C$24; row86 2-mo trailing uses AVERAGE('T12'!$D$24,'T12'!$C$24). Dashboard_1: verified, no changes needed. | F143: All 7 blue tabs now error-free (0 formula errors). Moved-out evictions now in Former section. FLAGGED for user judgment: N 'Moved Out Override' has names whose rar status is still present (Coronado=Current, Dixon=Notice-MTM, Alvarez & NJENDU=Notice-Eviction, Taiwo=not in rar); Data_2 row86 prior-month ref assumed T12!$D$24; Section B shows 43 of 59 / Section A 118 of 173 due to fixed row capacity.
A144: =A143+1 -> 8 | B144: 46183 | C144: User asked what the Dashboard D61 delinquency balance was at the end of April and end of May. | D144: Explained D61 is a live snapshot (Current*+Notice* SUMIF on resident aged receivable) with no history; pulled month-end values from the trending delinquency daily series. | E144: Month-end serials: Apr 30 = 46142 -> $724,738 (trending delinquency D108); May 31 = 46173 -> $826,043 (D126), matching Data_2 row 80 Wk22. Noted D61's narrow Current+Notice definition does not reconcile to the broad all-status trending balance; Apr 30 is the monthly trough (pre-May charge posting). | F144: Provided April 30 = $724,738 and May 31 = $826,043. Flagged that D61-definition (Current+Notice only) month-end history is not stored in the workbook.
A145: =A144+1 -> 9 | B145: 46183 | C145: User uploaded April and May aged-receivable CSVs and asked for delinquency (calculated exactly like D61) and total collection % for both months. | D145: Replicated D61 logic on each CSV; mapped workbook col E=Lease Status to CSV col C and col I='Unallocated Charges/Credits' to CSV col F; SUMIF Current*+Notice*. Flagged that collection % cannot come from aged-receivable snapshots. | E145: April file = '...(1).csv' (notes thru ~5/1): Current*=241,342 + Notice*=23,037 -> D61 magnitude $264,379. May file = no-suffix (notes thru 5/30): Current*=59,618 + Notice*=66,043 -> $125,661. D61 stores as negative. Collection % = Payments/Net Charges (Data_2 r76) needs charges+receipts not present in aged receivable. | F145: Delivered April $264,379 and May $125,661 delinquency. Collection %: user will upload separate charges/receipts reports; awaiting those to compute Payments/Net Charges per month.
A146: 10 | B146: 46183 | C146: Uploaded image of William's comments on the Q2 2026 Incentive_Scorecard and asked how to respond to his target-setting questions for Shawna, Alex, Nylsa, and Avery. | D146: Read Incentive_Scorecard actuals plus Dashboard_1 (wk23/June) and Targets (refi scenario); drafted a data-grounded reply recommending target adjustments for each participant. | E146: Key facts cited: physical occ 72.9% (vs 84% target), renewal ~60% Q2 (recommend 65% not 80%), collection 89.5% (recommend 90% not 93%), eviction court 94% (keep 85%), NOI $13.6K Apr/$110.8K May vs $258K proforma (95% unrealistic, rebase), delinquency $264K->$126K (keep <=$200K), filing accuracy 86.5% (keep 90%), LeaseLock recovery 16% vs 60% target which contradicts $40-65K expected recovery (recommend ~20-25%). | F146: Reply drafted in chat; offered to update scorecard target cells to recommended values. Awaiting user go-ahead.
A147: =A146+1 -> 11 | B147: 46185 | C147: Update the Write_Off_Recon tab as of June 8th. | D147: Refreshed the tab to a June 8, 2026 basis: updated Report Period (B3), expanded the write-off recommendation list from 16 (April) to 26 eligible accounts, and rebuilt the proposed journal entry section for June. | E147: As-of date E3 already pulled June 8 from Dashboard_1!F3, so detail aging was current. Inserted 10 rows (85:94); list rows 69:94 now link by formula to the detail table (=B14/=A14/=G14/=K14 etc.) instead of static values, sorted by write-off amount desc. Updated A64/A66/A97 headers to June 2026, JE date B98=6/8/2026, JE descriptions to (Jun 2026), totals G95/H95=SUM(69:94), H98=COUNTA(B69:B94). Normalized formatting/borders on expanded rows. List = all accounts 60+ days since move-out (eligibility logic unchanged); did not filter by col M 'Write-Off Approved'. | F147: Write-off total $178,280.32 (26 accounts) ties exactly to summary B7/B6; JE debit=credit=$178,280.32. 10 newly eligible accounts added since April list (e.g., Smith, Williams L., Brown T., Santana, Jose Y.).
A148: =A147+1 -> 12 | B148: 46191 | C148: Update LeaseLock statuses from the uploaded CSV for existing residents, add any new ones, and make sure statuses auto-update in the Delinquency tab. | D148: Refreshed all 64 existing CAF Management claims in LeaseLock from the CSV (matched by claim #/Item #). Found 0 new residents to add. Verified Delinquency tab pulls LeaseLock status live. | E148: Updated cols F,G,I,J,L,M,P,Q,R,S,U,W,X,Y,AC on LeaseLock rows 101-164; left N/O/T/V as live formulas. Delinquency_Detail_3 col K (LeaseLock/RSI) + summary C11:H14 reference LeaseLock!$2:$500, covering all updated rows. Calc mode confirmed Automatic; forced full recalc. | F148: LeaseLock current (e.g. Andres Hernandez New->Closed, $932.50 paid). Delinquency statuses live (e.g. Brown, Nicole 'LL: Closed - $750 paid'; Recovery Rate 16.7%). No new rows added.
A149: =A148+1 -> 13 | B149: 46191 | C149: Delinquency LeaseLock summary Recovery Rate is unfair (denominator = Total Claimed, ignoring policy coverage caps). Add a separate 'Avery's Recovery %' in J11:K11 based on capped/claimable amounts. | D149: Added Avery's Recovery % at J11:K11 = Total Paid / Claimed Within Limit (each claim capped at its coverage limit). Also fixed incomplete W column on LeaseLock. | E149: K11 =IFERROR(SUM(LeaseLock!M2:M500)/SUM(LeaseLock!W2:W500),0), fmt 0.0%, with note. Filled LeaseLock 'Claimed Within Limit' (W) for 99 older IPS rows using =MIN(L,P) since W was blank there (which had inflated the ratio to 178%). Unprotected/re-protected the Delinquency sheet to write. Standard Recovery Rate (H11) left unchanged. | F149: Avery's Recovery % = 65.5% vs standard Recovery Rate 16.7%. LeaseLock col W now complete for rows 2-164.
A150: =A149+1 -> 14 | B150: 46191 | C150: Asked how Avery's Recovery % is calculated — specifically whether it's total coverage limit vs paid. | D150: Explained the calculation. Clarified it is NOT total coverage limit; denominator is Claimed Within Limit = MIN(claimed, coverage limit) per claim (LeaseLock col W). | E150: Avery's % = SUM(M) $80,580 / SUM(W) $122,983 = 65.5%. Contrasted with total-coverage-limit method (SUM(P) $135,500 = 59.5%) and standard rate (SUM(L) $482,130 = 16.7%). Offered to switch denominator to full coverage limit if preferred. | F150: Explanation provided; no spreadsheet changes. Awaiting user decision on whether to use within-limit (current) or full coverage limit denominator.
A151: =A150+1 -> 15 | B151: 46191 | C151: Asked how the 65.5% (Avery's %) compares to LeaseLock column O per-claim recovery calculations. | D151: Analyzed and compared. Column O = Paid/Total Claimed per claim (uncapped, same basis as 16.7% total rate); Avery's 65.5% caps each denominator at coverage limit. | E151: Across 163 claims: Column O avg 31.1%, median 24.4%, aggregate 16.7%. Within-limit basis: avg 65.2%, median 100%, aggregate 65.5%. 128/163 (79%) claims exceeded cap; only 3 at 100% on col O vs 83 at 100% on capped basis. Offered to add a capped per-claim recovery column next to O. | F151: Comparison explained; no spreadsheet changes. Avery's 65.5% ~= 4x aggregate col O and ~2x simple avg of col O.
A152: =A151+1 -> 16 | B152: 46191 | C152: Audit only (no changes): on the Delinquency evictions tab, check the CURRENT RESIDENTS section for anyone who actually moved out in the last week, using the rent roll + move-out report; ignore future move-out dates. | D152: Audited all 41 current residents (rows 139-179) by unit against RR_Unit_Details (rent roll) and Move_Out_Reasons. Flagged 3 who moved out in the last week but are still listed as current. | E152: Flagged: Marshall, Alton N20-2093 (row 141) moved out 6/16/26 'Failure To Pay'; Cruz, Lesly N11-2042 (row 151) 6/17/26 'Skipped During Eviction' (unit now Vacant in rent roll); Cooper, Latricia N19-1083 (row 167) 6/15/26 'Non-Renewal'. Of the rest: 22 'Notice Unrented' have FUTURE expected move-outs (correctly still current), 18 'Occupied No Notice'. Ignored Move_Outs_ResMan (stale through 3/31/26) and discarded loose name-matches (false positives). | F152: 3 residents likely need reclassifying from Current to Former/Moved-Out. Audit only - no changes made to the model.
A153: 17 | B153: 46197 | C153: Update LeaseLock tab from uploaded CSV (Untitled-2026-06-24.csv) — refresh status of existing claims and add all new entries; file is most up to date. | D153: Matched 69 CSV claims by Item # against 163 existing rows: updated 64 existing CAF Management records and appended 5 new entries. | E153: Matched by claim_number→Item# (col A). Updated cols F,G,J,L,M,P,Q,R,S,X,Y,AC on rows 101-164. Added rows 165-169 (claims 26-118121/118125/118313/118316/118305) with formulas N,O,T,V,W and formats copied from row 164. Coverage Limit (P) = total_paid + unused_coverage_limit. | F153: LeaseLock now has 168 data rows (2-169). New entries: Earl Roof, Leaujodon Alexander, Jordan Feaster, Ramiro Gabriel/Yanheli Barriga, Krystal Farrell. Investor Property Services rows (2-99) untouched.
...

Sheet Instructions
C2: AVA APARTMENTS
C3: Weekly Metrics Report — User Guide
C4: Arlast Capital | CAF Management
C7: OVERVIEW
C9: This workbook provides real-time tracking of operational KPIs for AVA Apartments under CAF management.
C10: All calculations are formula-driven. Enter data in the Data tab and the Dashboard updates automatically.
C12: TAB STRUCTURE
C14: Dashboard
C15: Executive summary comparing current week actuals to targets.
C16: Change the "Reporting Week" number (1–24) to view any week. Target, Actual, Variance, Prior Week, WoW Δ, and Status columns all update automatically.
C18: Data
C19: Primary data entry tab. Enter weekly actuals here in the blue-highlighted input cells.
... C88: Questions: Arlast Capital | sergio@arlast.com

Sheet Incentive_Scorecard_Q2
A1: AVA APARTMENTS — Q2 2026 INCENTIVE COMPENSATION SCORECARD (SIMPLIFIED)
A2: Performance Period: April 1 – June 30, 2026 | Measurement Date: June 30, 2026 | Payout: Within 30 days of measurement
A4: PAYOUT SUMMARY
A5: Participant | B5: Role | C5: Total Pool | D5: KPI 1 Payout | E5: KPI 2 Payout | F5: Total Payout
A6: Shawna | B6: Collections Manager | C6: 7000 | D6: =I14 -> 4200 | E6: =I15 -> 2800 | F6: =D6+E6 -> 7000
A7: Alex | B7: Community Manager | C7: 10000 | D7: =I20 -> 3000 | E7: =I21 -> 4000 | F7: =D7+E7 -> 7000
A8: Nylsa | B8: District Manager | C8: 7000 | D8: =I27 -> 3000 | E8: =I28 -> 4000 | F8: =D8+E8 -> 7000
A9: Avery | B9: Sr. Account Manager | C9: 5000 | D9: =I34 -> 3000 | E9: =I35 -> 2000 | F9: =D9+E9 -> 5000
A10: TOTAL | C10: =SUM(C6:C9) -> 29000 | D10: =SUM(D6:D9) -> 13200 | E10: =SUM(E6:E9) -> 12800 | F10: =SUM(F6:F9) -> 26000
A12: SHAWNA — Collections Manager | G12: Pool: $7,000
A13: Metric | B13: Weight | C13: Base Target | D13: April | E13: May | F13: June | G13: Q2 Result | H13: Base Met? | I13: Payout
A14: Current-Month Collection Rate | B14: 0.6 | C14: ≥90% avg | D14: 0.88 | E14: 0.91 | F14: 0.925 | G14: =IF(COUNTA(D14:F14)=0,"",AVERAGE(D14:F14)) -> 0.905 | H14: =IF(G14="","—",IF(G14>=0.9,"✓","✗")) -> ✓ | I14: =IF(H14="✓",B14*$C$6,0) -> 4200
A15: Eviction Court Success Rate | B15: 0.4 | C15: ≥85% | D15: 0.88 | E15: 1 | F15: 1 | G15: =IF(COUNTA(D15:F15)=0,"",SUM(D15:F15)/COUNTA(D15:F15)) -> 0.96 | H15: =IF(G15="","—",IF(G15>=0.85,"✓","✗")) -> ✓ | I15: =IF(H15="✓",B15*$C$6,0) -> 2800
B16: =SUM(B14:B15) -> 1 | H16: Total Payout → | I16: =SUM(I14:I15) -> 7000
A18: ALEX — Community Manager | G18: Pool: $10,000
A19: Metric | B19: Weight | C19: Base Target | D19: April | E19: May | F19: June | G19: Q2 Result | H19: Base Met? | I19: Payout
A20: Occupancy (June 30) | B20: 0.6 | C20: P≥84% & E≥77% | D20: 0.7311 | E20: 0.731 | F20: 0.726 | G20: =F20 -> 0.726 | H20: =IF(OR(F20="",G20=""),"—",IF(AND(F20>=0.84,G20>=0.77),"✓","✗")) -> ✗ | I20: 3000
A21: Renewal Conversion Rate | B21: 0.4 | C21: ≥80% | D21: 0.554 | E21: 0.648 | F21: 0.444 | G21: =IF(COUNTA(D21:F21)=0,"",SUM(D21:F21)/COUNTA(D21:F21)) -> 0.54866667 | H21: =IF(G21="","—",IF(G21>=0.8,"✓","✗")) -> ✗ | I21: 4000
B23: =SUM(B20:B21) -> 1 | H23: Total Payout → | I23: =SUM(I20:I21) -> 7000
A25: NYLSA — District Manager | G25: Pool: $7,000
A26: Metric | B26: Weight | C26: Base Target | D26: April | E26: May | F26: June | G26: Q2 Result | H26: Base Met? | I26: Payout
A27: June NOI vs. Proforma | B27: 0.6 | C27: ≥95% of proforma | D27: 13593 | E27: 110779 | F27: 106565.12 | G27: =IF(F27="","",F27/258116.12) -> 0.41285728 | H27: =IF(G27="","—",IF(G27>=0.95,"✓","✗")) -> ✗ | I27: 3000
A28: Delinquency Compression | B28: 0.4 | C28: ≤$200K | D28: 264379 | E28: 125661 | F28: 130315.28 | G28: =IF(F28="","",F28) -> 130315.28 | H28: =IF(G28="","—",IF(G28<=200000,"✓","✗")) -> ✓ | I28: 4000
B30: =SUM(B27:B28) -> 1 | H30: Total Payout → | I30: =SUM(I27:I28) -> 7000
A32: AVERY — Sr. Account Manager | G32: Pool: $5,000
A33: Metric | B33: Weight | C33: Base Target | D33: April | E33: May | F33: June | G33: Q2 Result | H33: Base Met? | I33: Payout
A34: Eviction Filing Accuracy | B34: 0.6 | C34: ≥90% | D34: 0.73 | E34: 1 | F34: 1 | G34: =IF(COUNTA(D34:F34)=0,"",SUM(D34:F34)/COUNTA(D34:F34)) -> 0.91 | H34: =IF(G34="","—",IF(G34>=0.9,"✓","✗")) -> ✓ | I34: =IF(H34="✓",B34*$C$9,0) -> 3000
A35: LeaseLock Claims Recovery | B35: 0.4 | C35: 100% filed + ≥60% | D35: 0.642 | E35: 0.655 | F35: 0.648 | G35: =IF(COUNTA(D35:F35)=0,"",AVERAGE(D35:F35)) -> 0.64833333 | H35: =IF(G35="","—",IF(G35>=0.6,"✓","✗")) -> ✓ | I35: =IF(H35="✓",B35*$C$9,0) -> 2000
B37: =SUM(B34:B35) -> 1 | H37: Total Payout → | I37: =SUM(I34:I35) -> 5000
A39: PAYOUT MECHANICS & GOVERNANCE
A40: Weighted Payout: Each metric earns its weighted share of the participant's total pool independently. No all-or-nothing gate — missing one metric does not forfeit the other.
A41: No Outperform Bonus: There is no outperform tier. Hit the base target → earn that metric's weighted share. Miss → $0 on that metric.
A42: Blue cells (Apr/May/Jun and Q2 Result columns) are input placeholders. Enter actuals from Entrata and base reports as the quarter progresses.
A43: Mid-Quarter Check-In: ~May 15, 2026 (coaching checkpoint only, no payments). Final measurement: June 30, 2026.
A44: Data Sources: Entrata (system of record), RSI, Nationwide, Arlast Capital weekly metrics workbook, CAF V2 budget. Entrata governs in case of discrepancy.

Sheet Incentive_Scorecard_Q3
A1: AVA APARTMENTS — Q3 2026 INCENTIVE COMPENSATION SCORECARD (SIMPLIFIED)
A2: Performance Period: July 1 – September 30, 2026 | Measurement Date: September 30, 2026 | Payout: Within 30 days of measurement
A4: PAYOUT SUMMARY
A5: Participant | B5: Role | C5: Total Pool | D5: KPI 1 Payout | E5: KPI 2 Payout | F5: Total Payout
A6: Shawna | B6: Collections Manager | C6: 7000 | D6: =I15 -> 0 | E6: =I16 -> 0 | F6: =D6+E6 -> 0
A7: Alex | B7: Community Manager | C7: 7000 | D7: =I21 -> 0 | E7: =I22 -> 0 | F7: =D7+E7 -> 0
A8: Nylsa | B8: District Manager | C8: 7000 | D8: =I27 -> 0 | E8: =I28 -> 0 | F8: =D8+E8 -> 0
A9: Avery | B9: Sr. Account Manager | C9: 5000 | D9: =I33 -> 0 | E9: =I34 -> 0 | F9: =D9+E9 -> 0
A10: Justin | B10: Leasing Administrative Manager | C10: 5000 | D10: =I39 -> 0 | E10: =I40 -> 0 | F10: =D10+E10 -> 0
A11: TOTAL | C11: =SUM(C6:C10) -> 31000 | D11: =SUM(D6:D10) -> 0 | E11: =SUM(E6:E10) -> 0 | F11: =SUM(F6:F10) -> 0
A13: SHAWNA — Collections Manager | G13: Pool: $7,000
A14: Metric | B14: Weight | C14: Base Target | D14: July | E14: August | F14: September | G14: Q3 Result | H14: Base Met? | I14: Payout
A15: Current-Month Collection Rate | B15: 0.6 | C15: ≥95% avg | G15: =IF(COUNTA(D15:F15)=0,"",AVERAGE(D15:F15)) | H15: =IF(G15="","—",IF(G15>=0.92,"✓","✗")) -> — | I15: =IF(H15="✓",B15*$C$6,0) -> 0
A16: Eviction Court Success Rate | B16: 0.4 | C16: ≥90% | G16: =IF(COUNTA(D16:F16)=0,"",AVERAGE(D16:F16)) | H16: =IF(G16="","—",IF(G16>=0.85,"✓","✗")) -> — | I16: =IF(H16="✓",B16*$C$6,0) -> 0
B17: =SUM(B15:B16) -> 1 | H17: Total Payout → | I17: =SUM(I15:I16) -> 0
A19: ALEX — Community Manager | G19: Pool: $7,000
A20: Metric | B20: Weight | C20: Base Target | D20: July | E20: August | F20: September | G20: Q3 Result | H20: Base Met? | I20: Payout
A21: Occupancy (September 30) | B21: 0.6 | C21: ≥79% (Sept 30) | G21: =IF(F21="","",F21) | H21: =IF(G21="","—",IF(G21>=0.85,"✓","✗")) -> — | I21: =IF(H21="✓",B21*$C$7,0) -> 0
A22: Renewal Conversion Rate | B22: 0.4 | C22: ≥65% each mo | G22: =IF(COUNTA(D22:F22)=0,"",AVERAGE(D22:F22)) | H22: =IF(COUNTA(D22:F22)=0,"—",IF(MIN(D22:F22)>=0.65,"✓","✗")) -> — | I22: =IF(H22="✓",B22*$C$7,0) -> 0
B23: =SUM(B21:B22) -> 1 | H23: Total Payout → | I23: =SUM(I21:I22) -> 0
A25: NYLSA — District Manager | G25: Pool: $7,000
A26: Metric | B26: Weight | C26: Base Target | D26: July | E26: August | F26: September | G26: Q3 Result | H26: Base Met? | I26: Payout
A27: Expense Management — Above & Below the Line | B27: 0.6 | C27: ≤100% of budget | G27: =IF(COUNTA(D27:F27)=0,"",AVERAGE(D27:F27)) | H27: =IF(G27="","—",IF(G27<=1,"✓","✗")) -> — | I27: =IF(H27="✓",B27*$C$8,0) -> 0
A28: Delinquency Compression | B28: 0.4 | C28: Avg < $75K | G28: =IF(COUNTA(D28:F28)=0,"",AVERAGE(D28:F28)) | H28: =IF(G28="","—",IF(G28<75000,"✓","✗")) -> — | I28: =IF(H28="✓",B28*$C$8,0) -> 0
B29: =SUM(B27:B28) -> 1 | H29: Total Payout → | I29: =SUM(I27:I28) -> 0
A31: AVERY — Sr. Account Manager | G31: Pool: $5,000
A32: Metric | B32: Weight | C32: Base Target | D32: July | E32: August | F32: September | G32: Q3 Result | H32: Base Met? | I32: Payout
A33: Eviction Filing Accuracy | B33: 0.6 | C33: ≥90% | G33: =IF(COUNTA(D33:F33)=0,"",AVERAGE(D33:F33)) | H33: =IF(G33="","—",IF(G33>=0.9,"✓","✗")) -> — | I33: =IF(H33="✓",B33*$C$9,0) -> 0
A34: LeaseLock Claims Recovery | B34: 0.4 | C34: 100% filed + >60% | G34: =IF(COUNTA(D34:F34)=0,"",AVERAGE(D34:F34)) | H34: =IF(G34="","—",IF(G34>0.6,"✓","✗")) -> — | I34: =IF(H34="✓",B34*$C$9,0) -> 0
B35: =SUM(B33:B34) -> 1 | H35: Total Payout → | I35: =SUM(I33:I34) -> 0
A37: JUSTIN — Leasing Administrative Manager | G37: Pool: $5,000
A38: Metric | B38: Weight | C38: Base Target | D38: July | E38: August | F38: September | G38: Q3 Result | H38: Base Met? | I38: Payout
A39: Net Lease Generation | B39: 0.6 | C39: ≥52 avg/mo | G39: =IF(COUNTA(D39:F39)=0,"",AVERAGE(D39:F39)) | H39: =IF(G39="","—",IF(G39>=60,"✓","✗")) -> — | I39: =IF(H39="✓",B39*$C$10,0) -> 0
A40: Quality Screenings | B40: 0.4 | C40: <5 evictions avg/mo | G40: =IF(COUNTA(D40:F40)=0,"",AVERAGE(D40:F40)) | H40: =IF(G40="","—",IF(G40<5,"✓","✗")) -> — | I40: =IF(H40="✓",B40*$C$10,0) -> 0
B41: =SUM(B39:B40) -> 1 | H41: Total Payout → | I41: =SUM(I39:I40) -> 0
A43: PAYOUT MECHANICS & GOVERNANCE
A44: Weighted Payout: Each metric earns its weighted share of the participant's total pool independently. No all-or-nothing gate — missing one metric does not forfeit the other.
A45: No Outperform Bonus: There is no outperform tier. Hit the base target → earn that metric's weighted share. Miss → $0 on that metric.
A46: Blue cells (Jul/Aug/Sep and Q3 Result columns) are input placeholders. Enter actuals from Entrata and base reports as the quarter progresses.
A47: Mid-Quarter Check-In: ~August 15, 2026 (coaching checkpoint only, no payments). Final measurement: September 30, 2026.
...

Sheet Dashboard_1
B1: AVA APARTMENTS
B2: Weekly Performance Dashboard
B3: Reporting Week: | C3: 32 | D3: ← Enter week # (1-24) | F3: =IFERROR(VLOOKUP(C3,Targets!A:B,2,FALSE()),"") -> 46244
B5: KPI | C5: Target | D5: Actual | E5: Var | F5: Prior Wk | G5: WoW Δ | H5: Status
B6: OCCUPANCY
B7: Occupancy % | C7: =IFERROR(INDEX(Targets!$A$5:$O$100,$C$3,3),"—") -> 0.73522727 | D7: {=IFERROR(INDEX(Data_2!$D$6:$CW$6,1,$C$3+2),"")} -> 0.73509174 | E7: =IFERROR(D7-C7,"—") -> -0.00013552961 | F7: {=IFERROR(INDEX(Data_2!$D$6:$CW$6,1,$C$3+1),"")} -> 0.73165138 | G7: =IFERROR(D7-F7,"—") -> 0.003440367 | H7: =IF(AND(ISNUMBER(D7),ISNUMBER(C7)),IF(D7>=C7,"✓","✗"),"") -> ✗
B8: Occupied Units | C8: =IFERROR(INDEX(Targets!$A$5:C:C,$C$3,4),"—") -> — | D8: {=IFERROR(INDEX(Data_2!$D$7:$CW$7,1,$C$3+2),"")} -> 641 | E8: =IFERROR(D8-C8,"—") -> — | F8: {=IFERROR(INDEX(Data_2!$D$7:$CW$7,1,$C$3+1),"")} -> 638 | G8: =IFERROR(D8-F8,"—") -> 3 | H8: =IF(AND(ISNUMBER(D8),ISNUMBER(C8)),IF(D8>=C8,"✓","✗"),"")
B9: Exposure % | C9: — | D9: {=IFERROR(INDEX(Data_2!$D$13:$CW$13,1,$C$3+2),"")} -> 0.24885321 | E9: — | F9: {=IFERROR(INDEX(Data_2!$D$13:$CW$13,1,$C$3+1),"")} -> 0.24655963 | G9: =IFERROR(D9-F9,"—") -> 0.002293578
B10: Move Outs (weekly) | C10: =IFERROR(IF(_xlfn.SINGLE(INDEX(Targets!$A$5:$W$100,$C$3,11))=0,"—",_xlfn.SINGLE(INDEX(Targets!$A$5:$W$100,$C$3,11))),"—") -> 7 | D10: {=IFERROR(INDEX(Data_2!$D$93:$CW$93,1,$C$3+2),"")} -> 5 | E10: =IF(OR(C10="—",NOT(ISNUMBER(C10))),"—",IFERROR(C10-D10,"—")) -> 2 | F10: {=IF($C$3>1,IFERROR(INDEX(Data_2!$D$93:$CW$93,1,$C$3+1),""),"")} -> 11 | G10: =IFERROR(F10-D10,"—") -> 6 | H10: =IF(AND(ISNUMBER(D10),ISNUMBER(C10)),IF(D10<=C10,"✓","✗"),"") -> ✓
B11: LEASING FUNNEL
B12: New Prospects | C12: =IFERROR(INDEX(Targets!$A$5:$O$100,$C$3,5),"—") -> 156 | D12: {=IFERROR(INDEX(Data_2!$D$15:$CW$15,1,$C$3+2),"")} -> 189 | E12: =IFERROR(D12-C12,"—") -> 33 | F12: {=IFERROR(INDEX(Data_2!$D$15:$CW$15,1,$C$3+1),"")} -> 200 | G12: =IFERROR(D12-F12,"—") -> -11 | H12: =IF(AND(ISNUMBER(D12),ISNUMBER(C12)),IF(D12>=C12,"✓","✗"),"") -> ✓
B13: Tours | C13: =IFERROR(INDEX(Targets!$A$5:$O$100,$C$3,6),"—") -> 39 | D13: {=IFERROR(INDEX(Data_2!$D$16:$CW$16,1,$C$3+2),"")} -> 29 | E13: =IFERROR(D13-C13,"—") -> -10 | F13: {=IFERROR(INDEX(Data_2!$D$16:$CW$16,1,$C$3+1),"")} -> 28 | G13: =IFERROR(D13-F13,"—") -> 1 | H13: =IF(AND(ISNUMBER(D13),ISNUMBER(C13)),IF(D13>=C13,"✓","✗"),"") -> ✗
B14: Submitted Apps | C14: =IFERROR(INDEX(Targets!$A$5:$O$100,$C$3,7),"—") -> 24 | D14: {=IFERROR(INDEX(Data_2!$D$18:$CW$18,1,$C$3+2),"")} -> 17 | E14: =IFERROR(D14-C14,"—") -> -7 | F14: {=IFERROR(INDEX(Data_2!$D$18:$CW$18,1,$C$3+1),"")} -> 23 | G14: =IFERROR(D14-F14,"—") -> -6 | H14: =IF(AND(ISNUMBER(D14),ISNUMBER(C14)),IF(D14>=C14,"✓","✗"),"") -> ✗
B15: Net Apps | C15: =IFERROR(INDEX(Targets!$A$5:$O$100,$C$3,8),"—") -> 16 | D15: {=IFERROR(INDEX(Data_2!$D$23:$CW$23,1,$C$3+2),"")} -> 5 | E15: =IFERROR(D15-C15,"—") -> -11 | F15: {=IFERROR(INDEX(Data_2!$D$23:$CW$23,1,$C$3+1),"")} -> 13 | G15: =IFERROR(D15-F15,"—") -> -8 | H15: =IF(AND(ISNUMBER(D15),ISNUMBER(C15)),IF(D15>=C15,"✓","✗"),"") -> ✗
B16: Net Leases | C16: =IFERROR(INDEX(Targets!$A$5:$O$100,$C$3,9),"—") -> 14 | D16: {=IFERROR(INDEX(Data_2!$D$26:$CW$26,1,$C$3+2),"")} -> 3 | E16: =IFERROR(D16-C16,"—") -> -11 | F16: {=IFERROR(INDEX(Data_2!$D$26:$CW$26,1,$C$3+1),"")} -> 15 | G16: =IFERROR(D16-F16,"—") -> -12 | H16: =IF(AND(ISNUMBER(D16),ISNUMBER(C16)),IF(D16>=C16,"✓","✗"),"") -> ✗
B17: APP PIPELINE
B18: Total Apps in Pipeline | C18: =IFERROR(IF(_xlfn.SINGLE(INDEX(Targets!$A$5:$W$28,$C$3,16))=0,"—",_xlfn.SINGLE(INDEX(Targets!$A$5:$W$28,$C$3,16))),"—") -> — | D18: {=IFERROR(INDEX(Data_2!$D$28:$CW$28,1,$C$3+2),"")} -> 219 | E18: =IF(OR(C18="—",NOT(ISNUMBER(C18))),"—",IFERROR(C18-D18,"—")) -> — | F18: {=IF($C$3>1,IFERROR(INDEX(Data_2!$D$28:$CW$28,1,$C$3+1),""),"")} -> 219 | G18: =IFERROR(F18-D18,"—") -> 0 | H18: =IF(AND(ISNUMBER(D18),ISNUMBER(C18)),IF(D18<=C18,"✓","✗"),"")
B19: Still Actively Open | C19: =IFERROR(IF(_xlfn.SINGLE(INDEX(Targets!$A$5:$W$28,$C$3,17))=0,"—",_xlfn.SINGLE(INDEX(Targets!$A$5:$W$28,$C$3,17))),"—") -> — | D19: {=IFERROR(INDEX(Data_2!$D$29:$CW$29,1,$C$3+2),"")} -> 48 | E19: =IF(OR(C19="—",NOT(ISNUMBER(C19))),"—",IFERROR(C19-D19,"—")) -> — | F19: {=IF($C$3>1,IFERROR(INDEX(Data_2!$D$29:$CW$29,1,$C$3+1),""),"")} -> 48 | G19: =IFERROR(F19-D19,"—") -> 0 | H19: =IF(AND(ISNUMBER(D19),ISNUMBER(C19)),IF(D19<=C19,"✓","✗"),"")
B20: Converted to Lease | C20: =C16 -> 14 | D20: {=IFERROR(INDEX(Data_2!$D$31:$CW$31,1,$C$3+2),"")} -> 3 | E20: =IF(OR(C20="—",NOT(ISNUMBER(C20))),"—",IFERROR(D20-C20,"—")) -> -11 | F20: {=IF($C$3>1,IFERROR(INDEX(Data_2!$D$31:$CW$31,1,$C$3+1),""),"")} -> 15 | G20: =IFERROR(D20-F20,"—") -> -12 | H20: =IF(AND(ISNUMBER(D20),ISNUMBER(C20)),IF(D20>=C20,"✓","✗"),"") -> ✗
B21: Cancelled / Denied | C21: =IFERROR(IF(_xlfn.SINGLE(INDEX(Targets!$A$5:$W$28,$C$3,19))=0,"—",_xlfn.SINGLE(INDEX(Targets!$A$5:$W$28,$C$3,19))),"—") -> — | D21: {=IFERROR(INDEX(Data_2!$D$32:$CW$32,1,$C$3+2),"")} -> 62 | E21: =IF(OR(C21="—",NOT(ISNUMBER(C21))),"—",IFERROR(C21-D21,"—")) -> — | F21: {=IF($C$3>1,IFERROR(INDEX(Data_2!$D$32:$CW$32,1,$C$3+1),""),"")} -> 62 | G21: =IFERROR(F21-D21,"—") -> 0 | H21: =IF(AND(ISNUMBER(D21),ISNUMBER(C21)),IF(D21<=C21,"✓","✗"),"")
B22: Conversion Rate | C22: =IFERROR(IF(_xlfn.SINGLE(INDEX(Targets!$A$5:$W$100,$C$3,20))=0,"—",_xlfn.SINGLE(INDEX(Targets!$A$5:$W$100,$C$3,20))),"—") -> 0.24615385 | D22: {=IFERROR(INDEX(Data_2!$D$33:$CW$33,1,$C$3+2),"")} -> 0.01369863 | E22: =IF(OR(C22="—",NOT(ISNUMBER(C22))),"—",IFERROR(D22-C22,"—")) -> -0.23245522 | F22: {=IF($C$3>1,IFERROR(INDEX(Data_2!$D$33:$CW$33,1,$C$3+1),""),"")} -> 0.068493151 | G22: =IFERROR(D22-F22,"—") -> -0.054794521 | H22: =IF(AND(ISNUMBER(D22),ISNUMBER(C22)),IF(D22>=C22,"✓","✗"),"") -> ✗
B23: Loss Rate | C23: =IFERROR(IF(_xlfn.SINGLE(INDEX(Targets!$A$5:$W$28,$C$3,21))=0,"—",_xlfn.SINGLE(INDEX(Targets!$A$5:$W$28,$C$3,21))),"—") -> — | D23: {=IFERROR(INDEX(Data_2!$D$34:$CW$34,1,$C$3+2),"")} -> 0.28310502 | E23: =IF(OR(C23="—",NOT(ISNUMBER(C23))),"—",IFERROR(C23-D23,"—")) -> — | F23: {=IF($C$3>1,IFERROR(INDEX(Data_2!$D$34:$CW$34,1,$C$3+1),""),"")} -> 0.28310502 | G23: =IFERROR(F23-D23,"—") -> 0 | H23: =IF(AND(ISNUMBER(D23),ISNUMBER(C23)),IF(D23<=C23,"✓","✗"),"")
B24: Apps 15+ Days Old | C24: =IFERROR(IF(_xlfn.SINGLE(INDEX(Targets!$A$5:$W$100,$C$3,22))=0,"—",_xlfn.SINGLE(INDEX(Targets!$A$5:$W$100,$C$3,22))),"—") -> 5 | D24: {=IFERROR(INDEX(Data_2!$D$35:$CW$35,1,$C$3+2),"")} -> 48 | E24: =IF(OR(C24="—",NOT(ISNUMBER(C24))),"—",IFERROR(C24-D24,"—")) -> -43 | F24: {=IF($C$3>1,IFERROR(INDEX(Data_2!$D$35:$CW$35,1,$C$3+1),""),"")} -> 48 | G24: =IFERROR(F24-D24,"—") -> 0 | H24: =IF(AND(ISNUMBER(D24),ISNUMBER(C24)),IF(D24<=C24,"✓","✗"),"") -> ✗
B25: Avg Days to Decision | C25: =IFERROR(IF(_xlfn.SINGLE(INDEX(Targets!$A$5:$W$28,$C$3,23))=0,"—",_xlfn.SINGLE(INDEX(Targets!$A$5:$W$28,$C$3,23))),"—") -> — | D25: {=IFERROR(INDEX(Data_2!$D$36:$CW$36,1,$C$3+2),"")} -> 10.4 | E25: =IF(OR(C25="—",NOT(ISNUMBER(C25))),"—",IFERROR(C25-D25,"—")) -> — | F25: {=IF($C$3>1,IFERROR(INDEX(Data_2!$D$36:$CW$36,1,$C$3+1),""),"")} -> 10.4 | G25: =IFERROR(F25-D25,"—") -> 0 | H25: =IF(AND(ISNUMBER(D25),ISNUMBER(C25)),IF(D25<=C25,"✓","✗"),"")
B26: RENEWALS & RETENTION
B27: July
B28: Expirations | C28: — | D28: {=IFERROR(INDEX(Data_2!$D$62:$CW$62,1,$C$3+2),"")} -> 74 | E28: =IF(OR(C28="—",NOT(ISNUMBER(C28))),"—",IFERROR(D28-C28,"—")) -> — | F28: {=IF($C$3>1,IFERROR(INDEX(Data_2!$D$62:$CW$62,1,$C$3+1),""),"")} -> 74 | G28: =IFERROR(D28-F28,"—") -> 0
B29: Non-Renewals | C29: =IFERROR(INDEX(Targets!$A$5:$R$28,$C$3,11),"—") -> — | D29: {=IFERROR(INDEX(Data_2!$D$63:$CW$63,1,$C$3+2),"")} -> 17 | E29: =IF(OR(C29="—",NOT(ISNUMBER(C29))),"—",IFERROR(D29-C29,"—")) -> — | F29: {=IF($C$3>1,IFERROR(INDEX(Data_2!$D$63:$CW$63,1,$C$3+1),""),"")} -> 17 | G29: =IFERROR(D29-F29,"—") -> 0
B30: Skips (Evictions) | C30: — | D30: {=IFERROR(INDEX(Data_2!$D$66:$CW$66,1,$C$3+2),"")} -> 0 | E30: — | F30: {=IF($C$3>1,IFERROR(INDEX(Data_2!$D$66:$CW$66,1,$C$3+1),""),"")} -> 0 | G30: — | H30: —
B31: NTV | C31: — | D31: {=IFERROR(INDEX(Data_2!$D$64:$CW$64,1,$C$3+2),"")} -> 16 | E31: =IF(OR(C31="—",NOT(ISNUMBER(C31))),"—",IFERROR(D31-C31,"—")) -> — | F31: {=IF($C$3>1,IFERROR(INDEX(Data_2!$D$64:$CW$64,1,$C$3+1),""),"")} -> 16 | G31: =IFERROR(D31-F31,"—") -> 0 | H31: —
B32: Pending Renewals | C32: — | D32: =IFERROR(INDEX('Resident Retention -12 months'!$I$2:$I$16,MATCH(Data_2!$A$62,'Resident Retention -12 months'!$B$2:$B$16,0)),"") -> 6 | E32: — | F32: — | G32: — | H32: —
B33: Renewal % | C33: =IFERROR(INDEX(Targets!$A$5:$W$100,$C$3,10),"—") -> 0.65 | D33: {=IFERROR(INDEX(Data_2!$D$65:$CW$65,1,$C$3+2),"")} -> 0.47297297 | E33: =IFERROR(D33-C33,"—") -> -0.17702703 | F33: {=IF($C$3>1,IFERROR(INDEX(Data_2!$D$65:$CW$65,1,$C$3+1),""),"")} -> 0.47297297 | G33: =IFERROR(D33-F33,"—") -> 0 | H33: =IF(AND(ISNUMBER(D33),ISNUMBER(C33)),IF(D33>=C33,"✓","✗"),"") -> ✗
B34: Max Renewal % Possible | C34: — | D34: {=IFERROR(INDEX(Data_2!$D$67:$CW$67,1,$C$3+2),"")} -> 0.55405405 | E34: — | F34: {=IF($C$3>1,IFERROR(INDEX(Data_2!$D$67:$CW$67,1,$C$3+1),""),"")} -> 0.55405405 | G34: — | H34: —
B35: August
B36: Expirations | C36: — | D36: {=IFERROR(INDEX(Data_2!$D$69:$CW$69,1,$C$3+2),"")} -> 51 | E36: =IF(OR(C36="—",NOT(ISNUMBER(C36))),"—",IFERROR(D36-C36,"—")) -> — | F36: {=IF($C$3>1,IFERROR(INDEX(Data_2!$D$69:$CW$69,1,$C$3+1),""),"")} -> 51 | G36: =IFERROR(D36-F36,"—") -> 0
B37: Non-Renewals | C37: =IFERROR(INDEX(Targets!$A$5:$R$28,$C$3,11),"—") -> — | D37: {=IFERROR(INDEX(Data_2!$D$70:$CW$70,1,$C$3+2),"")} -> 8 | E37: =IF(OR(C37="—",NOT(ISNUMBER(C37))),"—",IFERROR(D37-C37,"—")) -> — | F37: {=IF($C$3>1,IFERROR(INDEX(Data_2!$D$70:$CW$70,1,$C$3+1),""),"")} -> 8 | G37: =IFERROR(D37-F37,"—") -> 0
B38: Skips (Evictions) | C38: — | D38: {=IFERROR(INDEX(Data_2!$D$73:$CW$73,1,$C$3+2),"")} -> 0 | E38: — | F38: {=IF($C$3>1,IFERROR(INDEX(Data_2!$D$73:$CW$73,1,$C$3+1),""),"")} -> 0 | G38: — | H38: —
B39: NTV | C39: — | D39: {=IFERROR(INDEX(Data_2!$D$71:$CW$71,1,$C$3+2),"")} -> 12 | E39: =IF(OR(C39="—",NOT(ISNUMBER(C39))),"—",IFERROR(D39-C39,"—")) -> — | F39: {=IF($C$3>1,IFERROR(INDEX(Data_2!$D$71:$CW$71,1,$C$3+1),""),"")} -> 12 | G39: =IFERROR(D39-F39,"—") -> 0 | H39: —
B40: Pending Renewals | C40: — | D40: =IFERROR(INDEX('Resident Retention -12 months'!$I$2:$I$16,MATCH(Data_2!$A$69,'Resident Retention -12 months'!$B$2:$B$16,0)),"") -> 0 | E40: — | F40: — | G40: — | H40: —
B41: Renewal % | C41: =IFERROR(INDEX(Targets!$A$5:$W$100,$C$3,10),"—") -> 0.65 | D41: {=IFERROR(INDEX(Data_2!$D$72:$CW$72,1,$C$3+2),"")} -> 0.60784314 | E41: =IFERROR(D41-C41,"—") -> -0.042156863 | F41: {=IF($C$3>1,IFERROR(INDEX(Data_2!$D$72:$CW$72,1,$C$3+1),""),"")} -> 0.60784314 | G41: =IFERROR(D41-F41,"—") -> 0 | H41: =IF(AND(ISNUMBER(D41),ISNUMBER(C41)),IF(D41>=C41,"✓","✗"),"") -> ✗
...

Sheet Data_2
B1: AVA APARTMENTS
B2: Weekly Performance Data
D3: Pre-1 | E3: Pre-2 | F3: Wk1 | G3: Wk2 | H3: Wk3 | I3: Wk4 | J3: Wk5 | K3: Wk6 | L3: Wk7 | M3: Wk8 | N3: Wk9 | O3: Wk10 | P3: Wk11 | Q3: Wk12 | R3: Wk13 | S3: Wk14 | T3: Wk15 | U3: Wk16 | V3: Wk17 | W3: Wk18 | X3: Wk19 | Y3: Wk20 | Z3: Wk21 | AA3: Wk22 | AB3: Wk23 | AC3: Wk24 | AD3: Wk25 | AE3: Wk26 | AF3: Wk27 | AG3: Wk28 | AH3: Wk29 | AI3: Wk30 | AJ3: Wk31 | AK3: Wk32
A4: Section | B4: KPI | C4: Format | D4: 46013 | E4: 46020 | F4: 46027 | G4: 46034 | H4: 46041 | I4: 46048 | J4: 46055 | K4: 46062 | L4: 46069 | M4: 46076 | N4: 46083 | O4: 46090 | P4: 46097 | Q4: 46104 | R4: 46111 | S4: 46118 | T4: 46125 | U4: 46132 | V4: 46139 | W4: 46146 | X4: 46153 | Y4: 46160 | Z4: 46167 | AA4: 46174 | AB4: 46181 | AC4: 46188 | AD4: 46195 | AE4: 46202 | AF4: 46209 | AG4: 46216 | AH4: 46223 | AI4: 46230 | AJ4: 46237 | AK4: 46244
A5: OCCUPANCY
B6: Occupancy % | C6: 0 | D6: 0.7966 | E6: 0.8 | F6: 0.8 | G6: 0.8 | H6: 0.81142857 | I6: 0.77828571 | J6: 0.7783 | K6: 0.76773455 | L6: 0.75629291 | M6: 0.75171625 | N6: 0.74828375 | O6: 0.74141876 | P6: 0.73913043 | Q6: 0.73913043 | R6: 0.74141876 | S6: 0.72883295 | T6: 0.72311213 | U6: 0.7323 | V6: 0.73112128 | W6: 0.73 | X6: 0.72654462 | Y6: 0.72425629 | Z6: 0.73340961 | AA6: 0.73112128 | AB6: 0.72852234 | AC6: 0.72623139 | AD6: 0.72821101 | AE6: 0.72591743 | AF6: 0.71788991 | AG6: 0.72133028 | AH6: 0.7190367 | AI6: 0.72591743 | AJ6: 0.73165138 | AK6: =SUM('Boxscore MMR -Availability'!$M:$M)/(SUM('Boxscore MMR -Availability'!$C:$C)-SUM('Boxscore MMR -Availability'!$F:$F)) -> 0.73509174
B7: Occupied Units | C7: #,##0 | D7: 701 | E7: 701 | F7: 704 | G7: 704 | H7: 710 | I7: 681 | J7: 681 | K7: 671 | L7: 661 | M7: 657 | N7: 654 | O7: 648 | P7: 646 | Q7: 646 | R7: 648 | S7: 637 | T7: 632 | U7: 640 | V7: 639 | W7: 638 | X7: 635 | Y7: 633 | Z7: 641 | AA7: 639 | AB7: 636 | AC7: 634 | AD7: 635 | AE7: 633 | AF7: 626 | AG7: 629 | AH7: 627 | AI7: 633 | AJ7: 638 | AK7: =SUM('Boxscore MMR -Availability'!$M:$M) -> 641
B8: Total Units | C8: #,##0 | D8: 880 | E8: 880 | F8: 880 | G8: 880 | H8: 880 | I8: 880 | J8: 880 | K8: 880 | L8: 880 | M8: 880 | N8: 880 | O8: 880 | P8: 880 | Q8: 880 | R8: 880 | S8: 880 | T8: 880 | U8: 880 | V8: 880 | W8: 880 | X8: 880 | Y8: 880 | Z8: 880 | AA8: 880 | AB8: 880 | AC8: 880 | AD8: 880 | AE8: 880 | AF8: 880 | AG8: 880 | AH8: 880 | AI8: 880 | AJ8: 880 | AK8: 880
