Workbook

Sheet Cover
B4: AVA APARTMENTS
B5: Operating, Debt & Capital Funding Model
B7: Mesa West Asset Services — Loan #330900386
B8: 880 units • 8401 Skillman St, Dallas, TX
B9: Prepared for Pennybacker Capital • July 14, 2026
B11: CONTENTS
B12: =HYPERLINK("#'Dashboard'!A1","Dashboard") -> Dashboard | C12: Funding summary, quarterly contributions, key metrics
B13: =HYPERLINK("#'Cash Burn'!A1","Cash Burn") -> Cash Burn | C13: Monthly cash leak by scenario, with chart
B14: =HYPERLINK("#'Assumptions'!A1","Assumptions") -> Assumptions | C14: All drivers, occupancy path and scenario inputs
B15: =HYPERLINK("#'Action Items'!A1","Action Items") -> Action Items | C15: Open items and responses
B16: =HYPERLINK("#'Draw Model Recon'!A1","Draw Model Recon") -> Draw Model Recon | C16: Prior draw-model projection vs this model, reconciled
B17: =HYPERLINK("#'Uses Detail'!A1","Uses Detail") -> Uses Detail | C17: Draw-by-draw detail of capital funded to date
B18: =HYPERLINK("#'Capex Run Rate'!A1","Capex Run Rate") -> Capex Run Rate | C18: Below-the-line capex by category
B19: =HYPERLINK("#'Operating Actuals'!A1","Operating Actuals") -> Operating Actuals | C19: June 2026 operating results
B20: =HYPERLINK("#'Model - Conservative'!A1","Model - Conservative") -> Model - Conservative | C20: Downside case
B21: =HYPERLINK("#'Model - Expected'!A1","Model - Expected") -> Model - Expected | C21: Base case
B22: =HYPERLINK("#'Model - Recovery'!A1","Model - Recovery") -> Model - Recovery | C22: Upside case
B23: =HYPERLINK("#'Model - Custom'!A1","Model - Custom") -> Model - Custom | C23: User-editable case
B25: Cream cells are inputs. Confidential — prepared for Pennybacker Capital.

Sheet Dashboard
B1: AVA Apartments
B2: ="Active scenario: "&Assumptions!$D$6 -> Active scenario: Expected
B3: Mesa West Loan (matures 4/1/27) • 880 units • figures in green link from the model tabs
B5: PB FUNDING (HORIZON, GROSS) | C5: FORWARD 12-MO NOI | D5: FORWARD 12-MO DSCR | E5: AVG MONTHLY BURN YR1
B6: =CHOOSE(Assumptions!$C$6,'Model - Conservative'!$T$50,'Model - Expected'!$T$50,'Model - Recovery'!$T$50,'Model - Custom'!$T$50) -> 4933550.7 | C6: =CHOOSE(Assumptions!$C$6,'Model - Conservative'!$C$46,'Model - Expected'!$C$46,'Model - Recovery'!$C$46,'Model - Custom'!$C$46) -> 4009726.6 | D6: =CHOOSE(Assumptions!$C$6,'Model - Conservative'!$C$48,'Model - Expected'!$C$48,'Model - Recovery'!$C$48,'Model - Custom'!$C$48) -> 0.53511174 | E6: =CHOOSE(Assumptions!$C$6,'Model - Conservative'!$C$53,'Model - Expected'!$C$53,'Model - Recovery'!$C$53,'Model - Custom'!$C$53) -> -290293.71
B7: REMAINING PB FUNDING | C7: DEBT YIELD | D7: MIN LIQUIDITY (HORIZON) | E7: PB FUNDED TO DATE
B8: =CHOOSE(Assumptions!$C$6,'Model - Conservative'!$T$52,'Model - Expected'!$T$52,'Model - Recovery'!$T$52,'Model - Custom'!$T$52) -> 3632563.5 | C8: =CHOOSE(Assumptions!$C$6,'Model - Conservative'!$C$49,'Model - Expected'!$C$49,'Model - Recovery'!$C$49,'Model - Custom'!$C$49) -> 0.061676666 | D8: =CHOOSE(Assumptions!$C$6,'Model - Conservative'!$C$51,'Model - Expected'!$C$51,'Model - Recovery'!$C$51,'Model - Custom'!$C$51) -> 681204.64 | E8: =CHOOSE(Assumptions!$C$6,'Model - Conservative'!$C$54,'Model - Expected'!$C$54,'Model - Recovery'!$C$54,'Model - Custom'!$C$54) -> 5300000
B10: PB FUNDING — USES (horizon to 4/1/27) | C10: Amount
B11: Below-the-line capex | C11: =CHOOSE(Assumptions!$C$6,'Model - Conservative'!$T$46,'Model - Expected'!$T$46,'Model - Recovery'!$T$46,'Model - Custom'!$T$46) -> 642213
B12: Franchise tax reimbursement (Aug+Sep) | C12: =CHOOSE(Assumptions!$C$6,'Model - Conservative'!$T$47,'Model - Expected'!$T$47,'Model - Recovery'!$T$47,'Model - Custom'!$T$47) -> 126608.63
B13: Closing & legal | C13: =CHOOSE(Assumptions!$C$6,'Model - Conservative'!$T$48,'Model - Expected'!$T$48,'Model - Recovery'!$T$48,'Model - Custom'!$T$48) -> 0
B14: Operating carry + reserve floor | C14: =CHOOSE(Assumptions!$C$6,'Model - Conservative'!$T$49,'Model - Expected'!$T$49,'Model - Recovery'!$T$49,'Model - Custom'!$T$49) -> 4164729.1
B19: TOTAL PB FUNDING (HORIZON) | C19: =CHOOSE(Assumptions!$C$6,'Model - Conservative'!$T$50,'Model - Expected'!$T$50,'Model - Recovery'!$T$50,'Model - Custom'!$T$50) -> 4933550.7
B21: SCENARIO COMPARISON | C21: Conservative | D21: Expected | E21: Recovery
B22: PB funding (horizon) | C22: ='Model - Conservative'!$T$50 -> 5945111 | D22: ='Model - Expected'!$T$50 -> 4933550.7 | E22: ='Model - Recovery'!$T$50 -> 4550931.2
B23: Forward 12-mo NOI | C23: ='Model - Conservative'!$C$46 -> 2998166.3 | D23: ='Model - Expected'!$C$46 -> 4009726.6 | E23: ='Model - Recovery'!$C$46 -> 4392346.1
B24: Forward 12-mo DSCR | C24: ='Model - Conservative'!$C$48 -> 0.40011556 | D24: ='Model - Expected'!$C$48 -> 0.53511174 | E24: ='Model - Recovery'!$C$48 -> 0.58617362
B25: Debt yield | C25: ='Model - Conservative'!$C$49 -> 0.046117085 | D25: ='Model - Expected'!$C$49 -> 0.061676666 | E25: ='Model - Recovery'!$C$49 -> 0.067562028
B26: Avg monthly burn (Yr1) | C26: ='Model - Conservative'!$C$53 -> -374590.39 | D26: ='Model - Expected'!$C$53 -> -290293.71 | E26: ='Model - Recovery'!$C$53 -> -258408.75
B27: Min liquidity (horizon) | C27: ='Model - Conservative'!$C$51 -> 681204.64 | D27: ='Model - Expected'!$C$51 -> 681204.64 | E27: ='Model - Recovery'!$C$51 -> 681204.64
B28: Cumulative op. cash flow | C28: ='Model - Conservative'!$C$52 -> -4495084.7 | D28: ='Model - Expected'!$C$52 -> -3483524.5 | E28: ='Model - Recovery'!$C$52 -> -3100905
B30: Figures in green link from the model tabs. Occupancy path from the stabilization rollforward; capex at the current run rate.
B31: SCOPE: taxes and insurance are now escrowed monthly through the Mesa West payment. Franchise tax reimbursement to PB: July paid, Aug and Sep remain.
B33: NET QUARTERLY PB FUNDING (contributions to hold the reserve floor) | C33: Q3 2026 | D33: Q4 2026 | E33: Q1 2027 | F33: Q2 2027 | G33: Total
B34: Conservative | C34: ='Model - Conservative'!C66 -> 553102.08 | D34: ='Model - Conservative'!D66 -> 1509227.5 | E34: ='Model - Conservative'!E66 -> 1308598.5 | F34: ='Model - Conservative'!F66 -> 1273195.6 | G34: ='Model - Conservative'!$G$66 -> 4644123.8
B35: Expected | C35: ='Model - Expected'!C66 -> 410261.63 | D35: ='Model - Expected'!D66 -> 1185802.1 | E35: ='Model - Expected'!E66 -> 1032957.7 | F35: ='Model - Expected'!F66 -> 1003542 | G35: ='Model - Expected'!$G$66 -> 3632563.5
B36: Recovery | C36: ='Model - Recovery'!C66 -> 352723.64 | D36: ='Model - Recovery'!D66 -> 1083095.3 | E36: ='Model - Recovery'!E66 -> 922894.06 | F36: ='Model - Recovery'!F66 -> 891230.98 | G36: ='Model - Recovery'!$G$66 -> 3249944
B37: Estimated contribution date | C37: Tue 9/1/26 | D37: Tue 10/6/26 | E37: Tue 1/5/27 | F37: Tue 4/6/27
B38: No contribution needed in Q3 until September; the $1.30M WaFd balance carries the account. PB has funded $5.3M in 2026 to date.
B41: chart data
C42: =C33 -> Q3 2026 | D42: =D33 -> Q4 2026 | E42: =E33 -> Q1 2027 | F42: =F33 -> Q2 2027
B43: WaFd reserve balance | C43: =CHOOSE(Assumptions!$C$6,'Model - Conservative'!C43,'Model - Expected'!C43,'Model - Recovery'!C43,'Model - Custom'!C43) -> 3903506.5 | D43: =CHOOSE(Assumptions!$C$6,'Model - Conservative'!D43,'Model - Expected'!D43,'Model - Recovery'!D43,'Model - Custom'!D43) -> 2717704.4 | E43: =CHOOSE(Assumptions!$C$6,'Model - Conservative'!E43,'Model - Expected'!E43,'Model - Recovery'!E43,'Model - Custom'!E43) -> 1684746.6 | F43: =CHOOSE(Assumptions!$C$6,'Model - Conservative'!F43,'Model - Expected'!F43,'Model - Recovery'!F43,'Model - Custom'!F43) -> 681204.64
D44: =D35 -> 1185802.1 | E44: =E35 -> 1032957.7 | F44: =F35 -> 1003542 | G44: =G35 -> 3632563.5
C45: WaFd reserve balance | D45: =CHOOSE(Assumptions!$C$6,'Model - Conservative'!D45,'Model - Expected'!D45,'Model - Recovery'!D45,'Model - Custom'!D45) -> 0
B47: VS INITIAL DRAW-MODEL PROJECTION (see Projection Bridge)
B48: • Initial draw model projected $2.50M (Base) of additional 2026 funding; the current model shows materially less.
B49: • Occupancy recovery lifts the property's contribution to the mortgage: 632 → 763 occupied units by December.
B50: • One-time items are behind us: the $2.0M tax bill, $769K rate cap, $408K AP payoff and $122K RAAM lien sat in the historical run rate.
B51: • Taxes now escrow monthly ($288,460) inside the mortgage rather than in lump-sum draws.
B52: • Added since: franchise tax reimbursement to CPM, $58,622 in August and $67,987 in September.
...

Sheet Assumptions
B1: AVA APARTMENTS
B2: Operating, Debt & Capital Funding Model
B3: Mesa West Loan #330900386 • 880 units • 8401 Skillman St, Dallas, TX
B5: SCENARIO SELECTOR
B6: Active scenario (1=Cons 2=Exp 3=Rec 4=Custom) | C6: 2 | D6: =CHOOSE($C$6,"Conservative","Expected","Recovery","Custom") -> Expected | G6: Drives Dashboard. Each Model tab is bound to its own column.
B8: OPERATING DRIVERS (monthly $ unless noted) | C8: Conservative | D8: Expected | E8: Recovery | F8: Custom
B9: Gross potential rent (mo) | C9: 864935 | D9: 864935 | E9: 864935 | F9: 864935 | G9: June 2026 actual market rent. 880 units.
B10: Quarterly rent growth | C10: 0 | D10: 0.0025 | E10: 0.005 | F10: 0.0025 | G10: Modest; occupancy is the driver here, not rate.
B11: Economic vacancy (see quarterly path below) | C11: 0 | D11: 0 | E11: 0 | F11: 0 | G11: Driven by the quarterly occupancy path on rows 50-53, not a flat rate.
B12: Concessions (mo) | C12: 38000 | D12: 32098 | E12: 26000 | F12: 32098 | G12: June actual $32,098.
B13: Bad debt / write-offs (mo) | C13: 105000 | D13: 68000 | E13: 62000 | F13: 91414 | G13: June actual $91,414. Collections/evictions improving.
B14: Other income (mo) | C14: 145000 | D14: 153059 | E14: 160000 | F14: 153059 | G14: June actual $153,059 (RUBS, fees).
B15: (not used — occupancy in vacancy path) | C15: 0 | D15: 0 | E15: 0 | F15: 0
B16: OPERATING EXPENSES (monthly $; grown quarterly)
B17: Payroll | C17: 125388 | D17: 125388 | E17: 125388 | F17: 125388 | G17: June actual $125,388.
B18: Marketing & other | C18: 15886 | D18: 15886 | E18: 15886 | F18: 15886 | G18: June actual $15,886.
B19: Administrative | C19: 52463 | D19: 52463 | E19: 52463 | F19: 52463 | G19: June: office ops $36,550 + contractual $15,913.
B20: Repairs & maintenance | C20: 72256 | D20: 72256 | E20: 72256 | F20: 72256 | G20: June: redecorating $48,343 + maintenance $23,913.
B21: Utilities | C21: 126685 | D21: 126685 | E21: 126685 | F21: 126685 | G21: June actual $126,685.
B22: Insurance (escrowed via mortgage) | C22: 0 | D22: 0 | E22: 0 | F22: 0 | G22: Now escrowed monthly through the Mesa West payment; carried in debt service, not opex.
B23: Real estate taxes (escrowed via mortgage) | C23: 0 | D23: 0 | E23: 0 | F23: 0 | G23: Now escrowed monthly ($288,460) through the Mesa West payment; carried in debt service.
B24: Management fee (% EGI) | C24: 0.05 | D24: 0.05 | E24: 0.05 | F24: 0.05 | G24: June: $38,127 on $760,996 income.
B25: Quarterly opex growth | C25: 0.0075 | D25: 0.005 | E25: 0.004 | F25: 0.005 | G25: Per quarter.
B27: DEBT — MESA WEST 330900386 (matures 4/1/2027)
B28: Loan principal balance | C28: 65012052 | G28: Mesa West statement 6/16/26. MATURITY 4/1/2027 — extension or refinance to be determined with PBC.
B29: Interest rate (annual) | C29: 0.071 | G29: 7.1% per Mesa West statement. Rate cap in place (~$60,732/mo receipt, see below).
B30: Monthly tax escrow | C30: 288460 | G30: July statement. Lender now escrows RE taxes monthly (replaces lump-sum tax draws).
B31: Monthly insurance escrow | C31: 68822 | G31: July statement.
B32: Monthly rate cap receipt | C32: 60732 | G32: June actual; offsets interest.
B34: CAPITAL & FUNDING
B35: Below-the-line capex (total, remaining) | C35: ='Capex Run Rate'!$C$3 -> 642213 | G35: Run-rate capex for the funded horizon; see Capex Run Rate.
B36: (capex phasing on row 45)
B38: Franchise tax reimbursement (Aug + Sep) | C38: 126608.63 | G38: Per Lingzi Hong (PBC) 6/30 plan: Aug $58,621.63 + Sep $67,987. July $63,508 PAID via DRW-013.
B39: Closing & legal | C39: 0 | G39: None anticipated.
B40: Minimum reserve floor (WaFd) | C40: =(Assumptions!$C$28*Assumptions!$C$29/12)+Assumptions!$C$30+Assumptions!$C$31-Assumptions!$C$32 -> 681204.64 | G40: One month net mortgage outlay (interest + tax escrow + insurance escrow, less the rate cap receipt). Approximately $681,204.
B41: WaFd balance (7/14/26) | C41: 1300987.2 | G41: Reconciled. July mortgage draw ($410,752) and franchise payment ($63,508) already disbursed.
B42: Restricted / memo | C42: 0 | G42: None.
B43: Funding horizon (quarters) | C43: 4 | G43: Q3 2026 through Q2 2027, to the 4/1/2027 loan maturity. Later quarters illustrative.
B44: CAPEX PHASING (quarterly, $) | C44: Q3 2026 | D44: Q4 2026 | E44: Q1 2027 | F44: Q2 2027 | G44: NOTES
B45: Capex draws by quarter | C45: 116766 | D45: 175149 | E45: 175149 | F45: 175149 | G45: 0 | H45: 0 | I45: 0 | J45: 0 | K45: =SUM(C45:J45) -> 642213
...

Sheet Action Items
B1: AVA Apartments
B2: PBC Questions Answered — July 2026
B3: Responses to Pennybacker's two questions, with the supporting tabs noted.
B5: # | C5: Item | D5: Confirmed by | E5: Direction | F5: Cell
B6: 1 | C6: Remaining 2026 cash needs and timing of contributions | D6: PBC | E6: See Dashboard: quarterly schedule. Base case remaining funding shown; first contribution Tue 9/1/26. | F6: =HYPERLINK("#'Dashboard'!A1","Dashboard →") -> Dashboard →
B7: 2 | C7: Downside case for the rest of 2026 | D7: PBC | E7: Conservative case: ~half the rollforward absorption, capex at $70K/mo. | F7: =HYPERLINK("#'Assumptions'!A1","Assumptions →") -> Assumptions →
B8: 3 | C8: FY2027 estimate at low-90s stabilized occupancy | D8: PBC | E8: Model horizon runs to the 4/1/27 maturity; Q1-Q2 2027 quarters carry stabilized occupancy. | F8: =HYPERLINK("#'Model - Expected'!A1","Model - Expected →") -> Model - Expected →
B9: 4 | C9: Loan maturity 4/1/2027 | D9: ARLAST | E9: Extension or refinance terms to be determined with PBC; model assumes current terms carry. | F9: =HYPERLINK("#'Assumptions'!A1","Assumptions →") -> Assumptions →
B10: 5 | C10: Franchise tax reimbursement to CPM | D10: DONE | E10: July $63,508 paid (DRW-013). Aug $58,622 and Sep $67,987 baked into the model. | F10: =HYPERLINK("#'Assumptions'!A1","Assumptions →") -> Assumptions →
B12: PB has funded $5.3M in 2026 to date; $5.73M disbursed across DRW-001 to DRW-013, leaving $1.30M at WaFd.

Sheet 2025 vs 2026
B1: AVA Apartments
B2: Capital Infusion, Uses and Burn — 2025 (IPS) vs 2026 (CAF)
B3: Source: ResMan general ledger, cash basis, Jan–Dec 2025; AVA Capital Draw System and 2026 financials.
B5: PENNYBACKER CAPITAL CONTRIBUTED | C5: 2025 (IPS) | D5: 2026 (CAF) | E5: Change
B6: March 2025 — PBC contribution | C6: 1100000 | D6: 0 | E6: -1 | G6: GL 3100-0010 Equity Capital
B7: April 2025 — title, legal and HFC costs | C7: 1419192 | D7: 0 | E7: -1 | G7: HFC conversion
B8: April 2025 — rate cap purchase | C8: 926000 | D8: 768540 | E8: -0.1700432 | G8: 2026: DRW-008
B9: April 2025 — loan amendment and extension fee | C9: 10325060 | D9: 0 | E9: -1 | G9: One-time recapitalization
B10: 2026 contributions (Jan, Apr, Jun) | C10: 0 | D10: 5300000 | G10: $2.6M + $1.1M + $1.6M; excludes rate cap line above to avoid double count
B11: TOTAL PB CAPITAL CONTRIBUTED | C11: 13770252 | D11: 5300000 | E11: -0.61511235 | G11: Pennybacker put 62% less capital into the asset in 2026 than in 2025.
B13: CAPITAL EXPENDITURES (where IPS placed the spend) | C13: 2025 (IPS) | D13: 2026 (CAF) | E13: Change
B14: Capitalized to the balance sheet (never in the P&L) | C14: 6974242 | D14: 0 | E14: -1 | G14: GL 1700/1730/1740/1750 accounts. Invisible in IPS income statements.
B15: of which: HFC closing and title (one-time) | C15: 2678098 | D15: 0 | E15: -1 | G15: Transaction cost, not property capex
B16: of which: true property capex | C16: 4296144 | D16: 0 | E16: -1 | G16: Appliances, flooring, painting, HVAC, plumbing, interior renovation
B17: Expensed through the P&L (visible) | C17: 0 | D17: 700596 | G17: 2026: capital repairs at $58,383/mo run rate, annualized
B18: TOTAL PROPERTY CAPEX | C18: 4296144 | D18: 700596 | E18: -0.83692446 | G18: CAF is spending 84% less on capital, and reporting all of it through the income statement.
B20: THE STORY
B21: • Pennybacker contributed $13.77M to AVA in 2025 and $5.30M in 2026 through July. That is 62% less capital, even with occupancy materially lower.
B22: • IPS capitalized $6.97M of spend to the balance sheet in 2025, of which $4.30M was true property capex. None of it appeared in the income statements Pennybacker received.
B23: • CAF is running capex at roughly $700K a year, entirely through the P&L. That is an 84% reduction in capital spend, and it is fully visible.
B24: • So the asset is consuming far less Pennybacker capital under CAF, while reporting honestly, despite operating from a weaker occupancy base.
B25: HOW TO READ THIS FAIRLY
B26: • The 2025 total is dominated by a one-time $10.33M loan amendment and extension fee. Excluding that recapitalization event, 2025 contributions were $3.45M against $5.30M in 2026.
B27: • The 2026 figure likewise carries one-time items: the $2.02M 2025 property tax bill inherited from IPS, the $769K rate cap and the $408K payables cleanup, roughly $3.2M of catch-up on prior obligations.
B28: • Netting the one-time items from both years, ongoing capital support is broadly comparable, and the durable difference is the capex reduction and the transparency of reporting.
B31: chart data | C31: 2025 | D31: 2026
B32: PB capital contributed | C32: 13770252 | D32: 5300000
B33: Property capex | C33: 4296144 | D33: 700596
B36: IPS LEGACY OBLIGATIONS SETTLED WITH 2026 CAPITAL | C36: Amount
B37: Proof at handover — IPS balance sheet, December 31, 2025:
B38: Accounts payable left on the books by IPS | C38: 782603.25 | G38: Balance sheet 12/31/25, account 2200-0000
B39: Real estate tax payable left on the books by IPS | C39: 1852067.2 | G39: Balance sheet 12/31/25, account 2465-0000
B41: 2026 Pennybacker draws that settled those IPS-era obligations:
B42: DRW-003 — 2025 property tax bill (8 parcels) | C42: 2016417.3 | G42: IPS accrued the liability; CAF paid it 1/30/26
B43: DRW-009 — accounts payable cleanup | C43: 407984.73 | G43: AP run 4/16/26 against the $782,603 IPS left
B44: DRW-006 — RAAM LLC lien settlement | C44: 121590.96 | G44: Lien arising from unpaid IPS-era work
B45: DRW-013 — franchise tax (tax years 2023-2025) | C45: 63508 | G45: All three tax years predate CAF; $126,609 still due
B46: Subtotal — IPS legacy settled with PB capital | C46: 2609501
B47: Less: lender escrow release applied to taxes | C47: -673478.96 | G47: INF-001, 2/2/26
B48: NET PB CAPITAL CONSUMED ON IPS OBLIGATIONS | C48: 1936022
...

Sheet Cash Burn
B1: AVA Apartments
B2: Monthly Cash Burn — What the Property Is Actually Leaking
B3: Cash leak per month before any Pennybacker contribution. Debt service includes the tax and insurance escrows, net of the rate cap receipt.
B5: WHERE IT STANDS TODAY (June 2026 actual, 632 occupied / 71.8%)
B6: Net operating income | C6: 106565 | E6: June actual
B7: Net mortgage outlay (int + escrows − rate cap) | C7: -681204 | E7: Mesa West; taxes $288,460 + insurance $68,822
B8: Operating cash leak | C8: -574639 | E8: NOI less the mortgage
B9: Below-the-line capex | C9: -58383 | E9: Run rate, $350,299 YTD / 6
B10: TOTAL MONTHLY LEAK | C10: -633022 | E10: Before any PB contribution
B12: PROJECTED MONTHLY BURN BY SCENARIO | C12: Q3 2026 | D12: Q4 2026 | E12: Q1 2027 | F12: Q2 2027
B13: Conservative
B14: NOI per month | C14: ='Model - Conservative'!C26/2 -> 216449.62 | D14: ='Model - Conservative'!D26/3 -> 236511.8 | E14: ='Model - Conservative'!E26/3 -> 303388.13 | F14: ='Model - Conservative'!F26/3 -> 315189.09
B15: Net mortgage per month | C15: ='Model - Conservative'!C31/2 -> -681204.64 | D15: ='Model - Conservative'!D31/3 -> -681204.64 | E15: ='Model - Conservative'!E31/3 -> -681204.64 | F15: ='Model - Conservative'!F31/3 -> -681204.64
B16: Operating leak per month | C16: ='Model - Conservative'!C32/2 -> -464755.02 | D16: ='Model - Conservative'!D32/3 -> -444692.84 | E16: ='Model - Conservative'!E32/3 -> -377816.51 | F16: ='Model - Conservative'!F32/3 -> -366015.55
B17: Below-the-line capex per month | C17: ='Model - Conservative'!C35/2 -> -58383 | D17: ='Model - Conservative'!D35/3 -> -58383 | E17: ='Model - Conservative'!E35/3 -> -58383 | F17: ='Model - Conservative'!F35/3 -> -58383
B18: TOTAL MONTHLY BURN | C18: =('Model - Conservative'!C32+'Model - Conservative'!C35)/2 -> -523138.02 | D18: =('Model - Conservative'!D32+'Model - Conservative'!D35)/3 -> -503075.84 | E18: =('Model - Conservative'!E32+'Model - Conservative'!E35)/3 -> -436199.51 | F18: =('Model - Conservative'!F32+'Model - Conservative'!F35)/3 -> -424398.55
B20: Expected
B21: NOI per month | C21: ='Model - Expected'!C26/2 -> 287869.84 | D21: ='Model - Expected'!D26/3 -> 344320.27 | E21: ='Model - Expected'!E26/3 -> 395268.39 | F21: ='Model - Expected'!F26/3 -> 405073.64
B22: Net mortgage per month | C22: ='Model - Expected'!C31/2 -> -681204.64 | D22: ='Model - Expected'!D31/3 -> -681204.64 | E22: ='Model - Expected'!E31/3 -> -681204.64 | F22: ='Model - Expected'!F31/3 -> -681204.64
B23: Operating leak per month | C23: ='Model - Expected'!C32/2 -> -393334.8 | D23: ='Model - Expected'!D32/3 -> -336884.37 | E23: ='Model - Expected'!E32/3 -> -285936.25 | F23: ='Model - Expected'!F32/3 -> -276131
B24: Below-the-line capex per month | C24: ='Model - Expected'!C35/2 -> -58383 | D24: ='Model - Expected'!D35/3 -> -58383 | E24: ='Model - Expected'!E35/3 -> -58383 | F24: ='Model - Expected'!F35/3 -> -58383
B25: TOTAL MONTHLY BURN | C25: =('Model - Expected'!C32+'Model - Expected'!C35)/2 -> -451717.8 | D25: =('Model - Expected'!D32+'Model - Expected'!D35)/3 -> -395267.37 | E25: =('Model - Expected'!E32+'Model - Expected'!E35)/3 -> -344319.25 | F25: =('Model - Expected'!F32+'Model - Expected'!F35)/3 -> -334514
B27: Recovery
B28: NOI per month | C28: ='Model - Recovery'!C26/2 -> 316638.84 | D28: ='Model - Recovery'!D26/3 -> 378555.87 | E28: ='Model - Recovery'!E26/3 -> 431956.29 | F28: ='Model - Recovery'!F26/3 -> 442510.65
B29: Net mortgage per month | C29: ='Model - Recovery'!C31/2 -> -681204.64 | D29: ='Model - Recovery'!D31/3 -> -681204.64 | E29: ='Model - Recovery'!E31/3 -> -681204.64 | F29: ='Model - Recovery'!F31/3 -> -681204.64
B30: Operating leak per month | C30: ='Model - Recovery'!C32/2 -> -364565.8 | D30: ='Model - Recovery'!D32/3 -> -302648.77 | E30: ='Model - Recovery'!E32/3 -> -249248.35 | F30: ='Model - Recovery'!F32/3 -> -238693.99
B31: Below-the-line capex per month | C31: ='Model - Recovery'!C35/2 -> -58383 | D31: ='Model - Recovery'!D35/3 -> -58383 | E31: ='Model - Recovery'!E35/3 -> -58383 | F31: ='Model - Recovery'!F35/3 -> -58383
B32: TOTAL MONTHLY BURN | C32: =('Model - Recovery'!C32+'Model - Recovery'!C35)/2 -> -422948.8 | D32: =('Model - Recovery'!D32+'Model - Recovery'!D35)/3 -> -361031.77 | E32: =('Model - Recovery'!E32+'Model - Recovery'!E35)/3 -> -307631.35 | F32: =('Model - Recovery'!F32+'Model - Recovery'!F35)/3 -> -297076.99
B34: THE READ
B35: chart data (burn as positive)
B36: Quarter | C36: Q3 26 | D36: Q4 26 | E36: Q1 27 | F36: Q2 27
B37: Conservative | C37: =-C18 -> 523138.02 | D37: =-D18 -> 503075.84 | E37: =-E18 -> 436199.51 | F37: =-F18 -> 424398.55
B38: Expected | C38: =-C25 -> 451717.8 | D38: =-D25 -> 395267.37 | E38: =-E25 -> 344319.25 | F38: =-F25 -> 334514
B39: Recovery | C39: =-C32 -> 422948.8 | D39: =-D32 -> 361031.77 | E39: =-E32 -> 307631.35 | F39: =-F32 -> 297076.99
B40: The leak is structural to the debt, not to operations. Even at stabilized occupancy the property does not cover the mortgage:
B41: • Today the property leaks roughly $633,000 a month, of which $575,000 is the operating gap and $58,000 is capex.
B42: • By Q2 2027 at 91% occupancy the leak narrows to roughly $357,000 a month in the Expected case, but it does not close.
B43: • The mortgage runs $681,204 a month net of the rate cap, including $288,460 of tax escrow and $68,822 of insurance escrow.
B44: • NOI would need to roughly double from the June run rate to break even on debt service alone.

Sheet Draw Model Recon
B1: AVA Apartments
B2: Draw Model Reconciliation — Prior Projection vs Current Model
B3: Both views measure additional Pennybacker funding for the remainder of 2026, net of the $1,300,987 WaFd balance.
B5: SIDE BY SIDE — ADDITIONAL FUNDING, REMAINDER OF 2026 | C5: Prior draw model | D5: Current model | E5: Change
B6: Downside | C6: 2502937 | D6: ='Model - Conservative'!C59+'Model - Conservative'!D59 -> 2062329.6 | E6: =D6-C6 -> -440607.41 | F6: Prior 'Base' — Q1 run-rate extrapolation; no occupancy recovery.
B7: Base | C7: 2894322 | D7: ='Model - Expected'!C59+'Model - Expected'!D59 -> 1596063.8 | E7: =D7-C7 -> -1298258.2 | F7: Prior 'Middle' — operator's capex budget.
B8: Upside | C8: 3353178 | D8: ='Model - Recovery'!C59+'Model - Recovery'!D59 -> 1435819 | E8: =D8-C8 -> -1917359 | F8: Prior 'High' — maximum headroom.
B9: The prior model extrapolated historical draws by category and did not model the lease-up, so its Base behaves as a no-recovery case. Mapping to the new scenarios is therefore directional.
B11: BRIDGE — PRIOR BASE TO CURRENT EXPECTED | C11: Amount
B12: Prior projection (draw model, Base case) | C12: 2502937 | F12: Funding_Summary_Models: Q3 + Q4 run-rate draws, less the WaFd balance.
B13: Less: occupancy recovery lifts property contribution | C13: -520000 | F13: Rollforward 632 → 763 occupied units by December. The property's own contribution to the mortgage rises from roughly $270K to $390K per month, reducing the draw.
B14: Less: one-time items embedded in the historical run rate | C14: -260000 | F14: Q1 draws carried the $2.02M tax bill, $769K rate cap, $408K AP payoff and $122K lien. A category run rate carries an echo of these forward; the bottom-up build does not.
B15: Less: tax escrow smoothing | C15: -120000 | F15: Taxes now escrow at $288,460 per month inside the mortgage payment. No lump-sum tax draws remain in 2026.
B16: Add: franchise tax reimbursement (Aug + Sep) | C16: 126609 | F16: New obligation to CPM, not contemplated in the prior model. July installment of $63,508 already paid via DRW-013.
B17: Other (reserve floor mechanics, interest, timing) | C17: =C18-SUM(C12:C16) -> -133482.24 | F17: Residual: floor-based sizing versus run-rate extrapolation.
B18: CURRENT EXPECTED — remainder of 2026 | C18: ='Model - Expected'!C59+'Model - Expected'!D59 -> 1596063.8
B20: Endpoints are exact and tie to the model; the intermediate attributions are estimates.
B22: WHERE THE TWO MODELS AGREE
B23: • Near-term monthly draw rate: the prior model implied roughly $393K per month in Q3; this model runs a similar shortfall before the lease-up gains land.
B24: • Both credit the same $1,300,987 WaFd balance and the same $5.3M funded to date.
B25: • Both treat the rate cap, AP payoff and 2025 tax bill as completed, non-recurring uses.
B27: WHAT WOULD PULL US BACK TOWARD THE PRIOR PROJECTION
B28: • Lease-up stall: if occupancy holds near 660 units rather than reaching 763 by December, the remaining 2026 need moves toward $2.0M and the Conservative case becomes the base.
B29: • Capex above the $58,383 per month run rate (Conservative carries $70,000).
B30: • A lower rate cap receipt if SOFR falls, reducing the roughly $60,732 monthly offset to interest.

Sheet Uses Detail
B1: AVA Apartments
B2: Uses of Capital to Date — Draw Detail (DRW-001 through DRW-013)
B3: Pennybacker funded $5,300,000 in 2026. Draws disbursed $5,732,407, offset by $3,324,564 of inflows. WaFd balance at 7/14/26: $1,300,987.
B5: Draw # | C5: Date | D5: Category | E5: Description | F5: Amount | G5: Quarter | H5: Status / Notes
B6: DRW-001 | C6: 01/26/26 | D6: Plumbing / Water Heater | E6: Storage tank replacement | F6: 11771.11 | G6: Q1 | H6: Emergency; approved
B7: DRW-002 | C7: 01/26/26 | D7: Deferred Maintenance | E7: Annual inspections, fire extinguishers, service | F7: 4842.87 | G7: Q1 | H7: Approved
B8: DRW-003 | C8: 01/30/26 | D8: Property Tax — 2025 | E8: 8 parcels: Dallas County + Richardson ISD | F8: 2016417.3 | G8: Q1 | H8: Offset by $673,479 lender escrow release
B9: DRW-004 | C9: 02/04/26 | D9: Debt Service | E9: Mortgage payment shortfall | F9: 215000 | G9: Q1 | H9: Refunded by property 02/06
B10: DRW-005 | C10: 03/04/26 | D10: Debt Service | E10: Mortgage payment shortfall | F10: 275000 | G10: Q1 | H10: Refunded by property 03/10
B11: DRW-006 | C11: 03/12/26 | D11: Lien / Legal | E11: RAAM LLC lien settlement + legal/late fees | F11: 121590.96 | G11: Q1 | H11: Approved
B12: DRW-007 | C12: 04/02/26 | D12: Debt Service | E12: April mortgage shortfall | F12: 432000 | G12: Q2 | H12: Refunded by property 04/08
B13: DRW-008 | C13: 04/16/26 | D13: Rate Cap | E13: SOFR rate cap purchase + transaction fee | F13: 768540 | G13: Q2 | H13: Lender requirement
B14: DRW-009 | C14: 04/16/26 | D14: AP Balance | E14: AP run 04/16/2026 (multiple vendors) | F14: 407984.73 | G14: Q2 | H14: Approved. IPS vendors 2025
B15: DRW-010 | C15: 05/04/26 | D15: Debt Service | E15: May mortgage payment | F15: 776000 | G15: Q2 | H15: Approved
B16: DRW-011 | C16: 06/04/26 | D16: Debt Service | E16: May mortgage payment (true-up) | F16: 229000 | G16: Q2 | H16: Approved
B17: DRW-012 | C17: 07/06/26 | D17: Debt Service | E17: Mortgage 07/06/2026 | F17: 410752.3 | G17: Q3 | H17: Property contributed $270,452; draw covered shortfall
B18: DRW-013 | C18: 07/08/26 | D18: Accrued Expenses | E18: Franchise tax reimbursement to CPM (1 of 3) | F18: 63508 | G18: Q3 | H18: Aug $58,622 and Sep $67,987 remain
E19: TOTAL DRAWS | F19: =SUM(F6:F18) -> 5732407.2
B21: INFLOWS (credited back to the account)
B22: INF-001 | C22: 02/02/26 | D22: Lender escrow release | E22: RE tax escrow released by Mesa West | F22: 673478.96
B23: INF-002 | C23: 02/06/26 | D23: Refund | E23: DRW-004 mortgage shortfall repaid by property | F23: 215000
B24: INF-003 | C24: 03/02/26 | D24: Prior management | E24: Operating cash transferred to reserve | F24: 129084.75
B25: INF-004 | C25: 03/10/26 | D25: Refund | E25: DRW-005 mortgage shortfall repaid by property | F25: 275000
B26: INF-005 | C26: 04/08/26 | D26: Refund | E26: DRW-007 mortgage shortfall repaid by property | F26: 432000
B27: INF-006 | C27: 04/16/26 | D27: PB contribution | E27: Q2 funding | F27: 1100000
B28: INF-007 | C28: 06/03/26 | D28: PB contribution | E28: Q3 funding | F28: 1600000
B29: — | C29: Jan–Jun | D29: Interest | E29: WaFd credit interest earned | F29: 8830.78
B31: RECONCILIATION TO WAFD ACCOUNT *7940
E32: PB capital contributions (Jan $2.6M + Apr $1.1M + Jun $1.6M) | F32: 5300000
E33: Plus: lender escrow release, refunds, prior mgmt cash | F33: 1724563.7
E34: Plus: interest earned | F34: 8830.78
E35: Less: draws disbursed (DRW-001 to DRW-013) | F35: -5732407.2
E36: WaFd balance, 7/14/2026 | F36: 1300987.2
B38: Note: the three mortgage-shortfall draws (DRW-004/005/007, $922,000) were repaid by the property and are not a net use of Pennybacker capital.
B39: Source: AVA Capital Draw System, reconciled line by line to WaFd statements. Backup available in the draw packages.

Sheet Capex Run Rate
B1: AVA APARTMENTS — CAPITAL USES & RUN RATE
B2: Below-the-line capex run rate for the funded horizon; 2026 uses funded to date.
B3: TOTAL (horizon, 4 quarters) | C3: =Assumptions!$K$45 -> 642213
B5: Category | C5: Monthly run rate | D5: Basis
B6: A/C & heating | C6: 6866 | D6: YTD $41,194 / 6
B7: Countertops & cabinets | C7: 10839 | D7: YTD $65,036 / 6
B8: Plumbing | C8: 7878 | D8: YTD $47,265 / 6
B9: Carpeting & vinyl | C9: 10910 | D9: YTD $65,459 / 6
B10: Appliances | C10: 3250 | D10: YTD $19,497 / 6
B11: Window coverings | C11: 3356 | D11: YTD $20,138 / 6
B12: Painting & interior | C12: 3193 | D12: YTD $19,159 / 6
B13: Fire sprinkler / extinguishers | C13: 2987 | D13: YTD $17,920 / 6
B14: Exterior, roofing, landscaping and other | C14: 9104 | D14: YTD $54,630 / 6
B15: TOTAL MONTHLY RUN RATE | C15: 58383 | D15: YTD gross capital repairs $350,299 / 6 months
B17: Per the 1/3-of-historical-IPS guide. CAF is tracking under it, which is why the Expected case carries $58,383/mo and Conservative $70,000/mo.

Sheet Operating Actuals
B1: AVA APARTMENTS — JUNE 2026 ACTUALS
B3: Metric | C3: June 2026 | D3: YTD | E3: Note
B4: Total income | C4: 760996 | D4: 4549903 | E4: Occupancy 632/880 = 71.8%
B5: Operating expenses | C5: 654431 | D5: 3891174 | E5: Incl. RE taxes & insurance (now escrowed)
B6: Net Operating Income | C6: 106565 | D6: 658728
B7: Below-the-line capex (gross) | C7: 104735 | D7: 350299 | E7: Capital repairs; reimbursed through draws
B8: Debt service (net of rate cap) | C8: 323923 | D8: 1940693 | E8: Interest $384,655 less rate cap $60,732
B9: Net income | C9: -415496 | D9: -2364797 | E9: Incl. amortization
B11: Source: AVA June 2026 financial prelims (accrual).

Sheet Model - Conservative
B1: Conservative Case — AVA Apartments
B2: Quarterly Operating, Debt & Capital Model ($)
B3: ="Funded horizon: through "&INDEX(C4:J4,Assumptions!$C$43)&" (4/1/27 loan maturity). Later quarters illustrative." -> Funded horizon: through Q2 2027 (4/1/27 loan maturity). Later quarters illustrative.
B4: Quarter | C4: Q3 2026 | D4: Q4 2026 | E4: Q1 2027 | F4: Q2 2027 | G4: Q3 2027 | H4: Q4 2027 | I4: Q1 2028 | J4: Q2 2028 | K4: 2-Yr Total
B5: q-index | C5: 1 | D5: 2 | E5: 3 | F5: 4 | G5: 5 | H5: 6 | I5: 7 | J5: 8
B6: months-in-qtr | C6: 2 | D6: 3 | E6: 3 | F6: 3 | G6: 3 | H6: 3 | I6: 3 | J6: 3
B7: REVENUE BUILD
B8: Gross potential rent | C8: =Assumptions!$C$9*C6*(1+Assumptions!$C$10)^(C5-1) -> 1729870 | D8: =Assumptions!$C$9*D6*(1+Assumptions!$C$10)^(D5-1) -> 2594805 | E8: =Assumptions!$C$9*E6*(1+Assumptions!$C$10)^(E5-1) -> 2594805 | F8: =Assumptions!$C$9*F6*(1+Assumptions!$C$10)^(F5-1) -> 2594805 | G8: =Assumptions!$C$9*G6*(1+Assumptions!$C$10)^(G5-1) -> 2594805 | H8: =Assumptions!$C$9*H6*(1+Assumptions!$C$10)^(H5-1) -> 2594805 | I8: =Assumptions!$C$9*I6*(1+Assumptions!$C$10)^(I5-1) -> 2594805 | J8: =Assumptions!$C$9*J6*(1+Assumptions!$C$10)^(J5-1) -> 2594805 | K8: =SUM(C8:J8) -> 19893505
B9: Vacancy (occupancy path) | C9: =-Assumptions!C$50*C8 -> -451496.07 | D9: =-Assumptions!D$50*D8 -> -604589.57 | E9: =-Assumptions!E$50*E8 -> -384031.14 | F9: =-Assumptions!F$50*F8 -> -337324.65 | G9: =-Assumptions!G$50*G8 -> -337324.65 | H9: =-Assumptions!H$50*H8 -> -337324.65 | I9: =-Assumptions!I$50*I8 -> -337324.65 | J9: =-Assumptions!J$50*J8 -> -337324.65 | K9: =SUM(C9:J9) -> -3126740
B10: Concessions | C10: =-Assumptions!$C$12*C6 -> -76000 | D10: =-Assumptions!$C$12*D6 -> -114000 | E10: =-Assumptions!$C$12*E6 -> -114000 | F10: =-Assumptions!$C$12*F6 -> -114000 | G10: =-Assumptions!$C$12*G6 -> -114000 | H10: =-Assumptions!$C$12*H6 -> -114000 | I10: =-Assumptions!$C$12*I6 -> -114000 | J10: =-Assumptions!$C$12*J6 -> -114000 | K10: =SUM(C10:J10) -> -874000
B11: Bad debt / write-offs | C11: =-Assumptions!$C$13*C6 -> -210000 | D11: =-Assumptions!$C$13*D6 -> -315000 | E11: =-Assumptions!$C$13*E6 -> -315000 | F11: =-Assumptions!$C$13*F6 -> -315000 | G11: =-Assumptions!$C$13*G6 -> -315000 | H11: =-Assumptions!$C$13*H6 -> -315000 | I11: =-Assumptions!$C$13*I6 -> -315000 | J11: =-Assumptions!$C$13*J6 -> -315000 | K11: =SUM(C11:J11) -> -2415000
B12: Net rental income | C12: =SUM(C8:C11) -> 992373.93 | D12: =SUM(D8:D11) -> 1561215.4 | E12: =SUM(E8:E11) -> 1781773.9 | F12: =SUM(F8:F11) -> 1828480.4 | G12: =SUM(G8:G11) -> 1828480.4 | H12: =SUM(H8:H11) -> 1828480.4 | I12: =SUM(I8:I11) -> 1828480.4 | J12: =SUM(J8:J11) -> 1828480.4 | K12: =SUM(C12:J12) -> 13477765
B13: Other income | C13: =Assumptions!$C$14*C6 -> 290000 | D13: =Assumptions!$C$14*D6 -> 435000 | E13: =Assumptions!$C$14*E6 -> 435000 | F13: =Assumptions!$C$14*F6 -> 435000 | G13: =Assumptions!$C$14*G6 -> 435000 | H13: =Assumptions!$C$14*H6 -> 435000 | I13: =Assumptions!$C$14*I6 -> 435000 | J13: =Assumptions!$C$14*J6 -> 435000 | K13: =SUM(C13:J13) -> 3335000
B14: Effective Gross Income | C14: =C12+C13 -> 1282373.9 | D14: =D12+D13 -> 1996215.4 | E14: =E12+E13 -> 2216773.9 | F14: =F12+F13 -> 2263480.4 | G14: =G12+G13 -> 2263480.4 | H14: =H12+H13 -> 2263480.4 | I14: =I12+I13 -> 2263480.4 | J14: =J12+J13 -> 2263480.4 | K14: =SUM(C14:J14) -> 16812765
B16: OPERATING EXPENSES
B17: Payroll | C17: =-Assumptions!$C$17*C6*(1+Assumptions!$C$25)^(C5-1) -> -250776 | D17: =-Assumptions!$C$17*D6*(1+Assumptions!$C$25)^(D5-1) -> -378985.23 | E17: =-Assumptions!$C$17*E6*(1+Assumptions!$C$25)^(E5-1) -> -381827.62 | F17: =-Assumptions!$C$17*F6*(1+Assumptions!$C$25)^(F5-1) -> -384691.33 | G17: =-Assumptions!$C$17*G6*(1+Assumptions!$C$25)^(G5-1) -> -387576.51 | H17: =-Assumptions!$C$17*H6*(1+Assumptions!$C$25)^(H5-1) -> -390483.34 | I17: =-Assumptions!$C$17*I6*(1+Assumptions!$C$25)^(I5-1) -> -393411.96 | J17: =-Assumptions!$C$17*J6*(1+Assumptions!$C$25)^(J5-1) -> -396362.55 | K17: =SUM(C17:J17) -> -2964114.5
B18: Marketing & other | C18: =-Assumptions!$C$18*C6*(1+Assumptions!$C$25)^(C5-1) -> -31772 | D18: =-Assumptions!$C$18*D6*(1+Assumptions!$C$25)^(D5-1) -> -48015.435 | E18: =-Assumptions!$C$18*E6*(1+Assumptions!$C$25)^(E5-1) -> -48375.551 | F18: =-Assumptions!$C$18*F6*(1+Assumptions!$C$25)^(F5-1) -> -48738.367 | G18: =-Assumptions!$C$18*G6*(1+Assumptions!$C$25)^(G5-1) -> -49103.905 | H18: =-Assumptions!$C$18*H6*(1+Assumptions!$C$25)^(H5-1) -> -49472.184 | I18: =-Assumptions!$C$18*I6*(1+Assumptions!$C$25)^(I5-1) -> -49843.226 | J18: =-Assumptions!$C$18*J6*(1+Assumptions!$C$25)^(J5-1) -> -50217.05 | K18: =SUM(C18:J18) -> -375537.72
B19: Administrative | C19: =-Assumptions!$C$19*C6*(1+Assumptions!$C$25)^(C5-1) -> -104926 | D19: =-Assumptions!$C$19*D6*(1+Assumptions!$C$25)^(D5-1) -> -158569.42 | E19: =-Assumptions!$C$19*E6*(1+Assumptions!$C$25)^(E5-1) -> -159758.69 | F19: =-Assumptions!$C$19*F6*(1+Assumptions!$C$25)^(F5-1) -> -160956.88 | G19: =-Assumptions!$C$19*G6*(1+Assumptions!$C$25)^(G5-1) -> -162164.05 | H19: =-Assumptions!$C$19*H6*(1+Assumptions!$C$25)^(H5-1) -> -163380.29 | I19: =-Assumptions!$C$19*I6*(1+Assumptions!$C$25)^(I5-1) -> -164605.64 | J19: =-Assumptions!$C$19*J6*(1+Assumptions!$C$25)^(J5-1) -> -165840.18 | K19: =SUM(C19:J19) -> -1240201.1
B20: Repairs & maintenance | C20: =-Assumptions!$C$20*C6*(1+Assumptions!$C$25)^(C5-1) -> -144512 | D20: =-Assumptions!$C$20*D6*(1+Assumptions!$C$25)^(D5-1) -> -218393.76 | E20: =-Assumptions!$C$20*E6*(1+Assumptions!$C$25)^(E5-1) -> -220031.71 | F20: =-Assumptions!$C$20*F6*(1+Assumptions!$C$25)^(F5-1) -> -221681.95 | G20: =-Assumptions!$C$20*G6*(1+Assumptions!$C$25)^(G5-1) -> -223344.57 | H20: =-Assumptions!$C$20*H6*(1+Assumptions!$C$25)^(H5-1) -> -225019.65 | I20: =-Assumptions!$C$20*I6*(1+Assumptions!$C$25)^(I5-1) -> -226707.3 | J20: =-Assumptions!$C$20*J6*(1+Assumptions!$C$25)^(J5-1) -> -228407.6 | K20: =SUM(C20:J20) -> -1708098.5
B21: Utilities | C21: =-Assumptions!$C$21*C6*(1+Assumptions!$C$25)^(C5-1) -> -253370 | D21: =-Assumptions!$C$21*D6*(1+Assumptions!$C$25)^(D5-1) -> -382905.41 | E21: =-Assumptions!$C$21*E6*(1+Assumptions!$C$25)^(E5-1) -> -385777.2 | F21: =-Assumptions!$C$21*F6*(1+Assumptions!$C$25)^(F5-1) -> -388670.53 | G21: =-Assumptions!$C$21*G6*(1+Assumptions!$C$25)^(G5-1) -> -391585.56 | H21: =-Assumptions!$C$21*H6*(1+Assumptions!$C$25)^(H5-1) -> -394522.45 | I21: =-Assumptions!$C$21*I6*(1+Assumptions!$C$25)^(I5-1) -> -397481.37 | J21: =-Assumptions!$C$21*J6*(1+Assumptions!$C$25)^(J5-1) -> -400462.48 | K21: =SUM(C21:J21) -> -2994775
B22: Insurance (escrowed) | C22: =-Assumptions!$C$22*C6*(1+Assumptions!$C$25)^(C5-1) -> 0 | D22: =-Assumptions!$C$22*D6*(1+Assumptions!$C$25)^(D5-1) -> 0 | E22: =-Assumptions!$C$22*E6*(1+Assumptions!$C$25)^(E5-1) -> 0 | F22: =-Assumptions!$C$22*F6*(1+Assumptions!$C$25)^(F5-1) -> 0 | G22: =-Assumptions!$C$22*G6*(1+Assumptions!$C$25)^(G5-1) -> 0 | H22: =-Assumptions!$C$22*H6*(1+Assumptions!$C$25)^(H5-1) -> 0 | I22: =-Assumptions!$C$22*I6*(1+Assumptions!$C$25)^(I5-1) -> 0 | J22: =-Assumptions!$C$22*J6*(1+Assumptions!$C$25)^(J5-1) -> 0 | K22: =SUM(C22:J22) -> 0
B23: Real estate taxes (escrowed) | C23: =-Assumptions!$C$23*C6*(1+Assumptions!$C$25)^(C5-1) -> 0 | D23: =-Assumptions!$C$23*D6*(1+Assumptions!$C$25)^(D5-1) -> 0 | E23: =-Assumptions!$C$23*E6*(1+Assumptions!$C$25)^(E5-1) -> 0 | F23: =-Assumptions!$C$23*F6*(1+Assumptions!$C$25)^(F5-1) -> 0 | G23: =-Assumptions!$C$23*G6*(1+Assumptions!$C$25)^(G5-1) -> 0 | H23: =-Assumptions!$C$23*H6*(1+Assumptions!$C$25)^(H5-1) -> 0 | I23: =-Assumptions!$C$23*I6*(1+Assumptions!$C$25)^(I5-1) -> 0 | J23: =-Assumptions!$C$23*J6*(1+Assumptions!$C$25)^(J5-1) -> 0 | K23: =SUM(C23:J23) -> 0
B24: Management fee | C24: =-Assumptions!$C$24*C14 -> -64118.696 | D24: =-Assumptions!$C$24*D14 -> -99810.772 | E24: =-Assumptions!$C$24*E14 -> -110838.69 | F24: =-Assumptions!$C$24*F14 -> -113174.02 | G24: =-Assumptions!$C$24*G14 -> -113174.02 | H24: =-Assumptions!$C$24*H14 -> -113174.02 | I24: =-Assumptions!$C$24*I14 -> -113174.02 | J24: =-Assumptions!$C$24*J14 -> -113174.02 | K24: =SUM(C24:J24) -> -840638.25
B25: Total Operating Expenses | C25: =SUM(C17:C24) -> -849474.7 | D25: =SUM(D17:D24) -> -1286680 | E25: =SUM(E17:E24) -> -1306609.5 | F25: =SUM(F17:F24) -> -1317913.1 | G25: =SUM(G17:G24) -> -1326948.6 | H25: =SUM(H17:H24) -> -1336051.9 | I25: =SUM(I17:I24) -> -1345223.5 | J25: =SUM(J17:J24) -> -1354463.9 | K25: =SUM(C25:J25) -> -10123365
B26: NET OPERATING INCOME | C26: =C14+C25 -> 432899.23 | D26: =D14+D25 -> 709535.41 | E26: =E14+E25 -> 910164.39 | F26: =F14+F25 -> 945567.28 | G26: =G14+G25 -> 936531.73 | H26: =H14+H25 -> 927428.42 | I26: =I14+I25 -> 918256.84 | J26: =J14+J25 -> 909016.47 | K26: =SUM(C26:J26) -> 6689399.8
B28: DEBT SERVICE & ESCROWS (Mesa West)
B29: Loan balance | C29: =Assumptions!$C$28 -> 65012052 | D29: =Assumptions!$C$28 -> 65012052 | E29: =Assumptions!$C$28 -> 65012052 | F29: =Assumptions!$C$28 -> 65012052 | G29: =Assumptions!$C$28 -> 65012052 | H29: =Assumptions!$C$28 -> 65012052 | I29: =Assumptions!$C$28 -> 65012052 | J29: =Assumptions!$C$28 -> 65012052 | K29: =J29 -> 65012052
B30: Interest rate (annual) | C30: =Assumptions!$C$29 -> 0.071 | D30: =Assumptions!$C$29 -> 0.071 | E30: =Assumptions!$C$29 -> 0.071 | F30: =Assumptions!$C$29 -> 0.071 | G30: =Assumptions!$C$29 -> 0.071 | H30: =Assumptions!$C$29 -> 0.071 | I30: =Assumptions!$C$29 -> 0.071 | J30: =Assumptions!$C$29 -> 0.071 | K30: =AVERAGE(C30:J30) -> 0.071
B31: Mortgage (int + tax/ins escrow, net cap) | C31: =-((Assumptions!$C$28*Assumptions!$C$29/12)+Assumptions!$C$30+Assumptions!$C$31-Assumptions!$C$32)*C6 -> -1362409.3 | D31: =-((Assumptions!$C$28*Assumptions!$C$29/12)+Assumptions!$C$30+Assumptions!$C$31-Assumptions!$C$32)*D6 -> -2043613.9 | E31: =-((Assumptions!$C$28*Assumptions!$C$29/12)+Assumptions!$C$30+Assumptions!$C$31-Assumptions!$C$32)*E6 -> -2043613.9 | F31: =-((Assumptions!$C$28*Assumptions!$C$29/12)+Assumptions!$C$30+Assumptions!$C$31-Assumptions!$C$32)*F6 -> -2043613.9 | G31: =-((Assumptions!$C$28*Assumptions!$C$29/12)+Assumptions!$C$30+Assumptions!$C$31-Assumptions!$C$32)*G6 -> -2043613.9 | H31: =-((Assumptions!$C$28*Assumptions!$C$29/12)+Assumptions!$C$30+Assumptions!$C$31-Assumptions!$C$32)*H6 -> -2043613.9 | I31: =-((Assumptions!$C$28*Assumptions!$C$29/12)+Assumptions!$C$30+Assumptions!$C$31-Assumptions!$C$32)*I6 -> -2043613.9 | J31: =-((Assumptions!$C$28*Assumptions!$C$29/12)+Assumptions!$C$30+Assumptions!$C$31-Assumptions!$C$32)*J6 -> -2043613.9 | K31: =SUM(C31:J31) -> -15667707
B32: Cash flow after debt service | C32: =C26+C31 -> -929510.05 | D32: =D26+D31 -> -1334078.5 | E32: =E26+E31 -> -1133449.5 | F32: =F26+F31 -> -1098046.6 | G32: =G26+G31 -> -1107082.2 | H32: =H26+H31 -> -1116185.5 | I32: =I26+I31 -> -1125357.1 | J32: =J26+J31 -> -1134597.5 | K32: =SUM(C32:J32) -> -8978306.9
B33: (memo) gross mortgage before rate cap | C33: =-((Assumptions!$C$28*Assumptions!$C$29/12)+Assumptions!$C$30+Assumptions!$C$31)*C6 -> -1483873.3 | D33: =-((Assumptions!$C$28*Assumptions!$C$29/12)+Assumptions!$C$30+Assumptions!$C$31)*D6 -> -2225809.9 | E33: =-((Assumptions!$C$28*Assumptions!$C$29/12)+Assumptions!$C$30+Assumptions!$C$31)*E6 -> -2225809.9 | F33: =-((Assumptions!$C$28*Assumptions!$C$29/12)+Assumptions!$C$30+Assumptions!$C$31)*F6 -> -2225809.9 | G33: =-((Assumptions!$C$28*Assumptions!$C$29/12)+Assumptions!$C$30+Assumptions!$C$31)*G6 -> -2225809.9 | H33: =-((Assumptions!$C$28*Assumptions!$C$29/12)+Assumptions!$C$30+Assumptions!$C$31)*H6 -> -2225809.9 | I33: =-((Assumptions!$C$28*Assumptions!$C$29/12)+Assumptions!$C$30+Assumptions!$C$31)*I6 -> -2225809.9 | J33: =-((Assumptions!$C$28*Assumptions!$C$29/12)+Assumptions!$C$30+Assumptions!$C$31)*J6 -> -2225809.9
B34: CAPITAL & FUNDING USES
B35: Below-the-line capex | C35: =-Assumptions!C45 -> -116766 | D35: =-Assumptions!D45 -> -175149 | E35: =-Assumptions!E45 -> -175149 | F35: =-Assumptions!F45 -> -175149 | G35: =-Assumptions!G45 -> 0 | H35: =-Assumptions!H45 -> 0 | I35: =-Assumptions!I45 -> 0 | J35: =-Assumptions!J45 -> 0 | K35: =SUM(C35:J35) -> -642213
B36: Franchise tax reimbursement (CPM) | C36: =IF(C5=1,-Assumptions!$C$38,0) -> -126608.63 | D36: =IF(D5=1,-Assumptions!$C$38,0) -> 0 | E36: =IF(E5=1,-Assumptions!$C$38,0) -> 0 | F36: =IF(F5=1,-Assumptions!$C$38,0) -> 0 | G36: =IF(G5=1,-Assumptions!$C$38,0) -> 0 | H36: =IF(H5=1,-Assumptions!$C$38,0) -> 0 | I36: =IF(I5=1,-Assumptions!$C$38,0) -> 0 | J36: =IF(J5=1,-Assumptions!$C$38,0) -> 0 | K36: =SUM(C36:J36) -> -126608.63
B37: Closing & legal | C37: =IF(C5=1,-Assumptions!$C$39,0) -> 0 | D37: =IF(D5=1,-Assumptions!$C$39,0) -> 0 | E37: =IF(E5=1,-Assumptions!$C$39,0) -> 0 | F37: =IF(F5=1,-Assumptions!$C$39,0) -> 0 | G37: =IF(G5=1,-Assumptions!$C$39,0) -> 0 | H37: =IF(H5=1,-Assumptions!$C$39,0) -> 0 | I37: =IF(I5=1,-Assumptions!$C$39,0) -> 0 | J37: =IF(J5=1,-Assumptions!$C$39,0) -> 0 | K37: =SUM(C37:J37) -> 0
B38: Net cash flow before funding | C38: =C32+C35+C36+C37 -> -1172884.7 | D38: =D32+D35+D36+D37 -> -1509227.5 | E38: =E32+E35+E36+E37 -> -1308598.5 | F38: =F32+F35+F36+F37 -> -1273195.6 | G38: =G32+G35+G36+G37 -> -1107082.2 | H38: =H32+H35+H36+H37 -> -1116185.5 | I38: =I32+I35+I36+I37 -> -1125357.1 | J38: =J32+J35+J36+J37 -> -1134597.5 | K38: =SUM(C38:J38) -> -9747128.6
B40: PB FUNDING POOL (single initial call)
B41: Pool beginning | C41: 0 | D41: =C43 -> 4772226.3 | E41: =D43 -> 3262998.8 | F41: =E43 -> 1954400.3 | G41: =F43 -> 681204.64 | H41: =G43 -> -425877.55 | I41: =H43 -> -1542063 | J41: =I43 -> -2667420.1
B42: Initial PB funding (at close) | C42: =$T$50 -> 5945111 | D42: 0 | E42: 0 | F42: 0 | G42: 0 | H42: 0 | I42: 0 | J42: 0
B43: Pool ending (liquidity) | C43: =C41+C42+C38 -> 4772226.3 | D43: =D41+D42+D38 -> 3262998.8 | E43: =E41+E42+E38 -> 1954400.3 | F43: =F41+F42+F38 -> 681204.64 | G43: =G41+G42+G38 -> -425877.55 | H43: =H41+H42+H38 -> -1542063 | I43: =I41+I42+I38 -> -2667420.1 | J43: =J41+J42+J38 -> -3802017.6 | K43: =J43 -> -3802017.6
...

Sheet Model - Expected
B1: Expected Case — AVA Apartments
B2: Quarterly Operating, Debt & Capital Model ($)
B3: ="Funded horizon: through "&INDEX(C4:J4,Assumptions!$C$43)&" (4/1/27 loan maturity). Later quarters illustrative." -> Funded horizon: through Q2 2027 (4/1/27 loan maturity). Later quarters illustrative.
B4: Quarter | C4: Q3 2026 | D4: Q4 2026 | E4: Q1 2027 | F4: Q2 2027 | G4: Q3 2027 | H4: Q4 2027 | I4: Q1 2028 | J4: Q2 2028 | K4: 2-Yr Total
B5: q-index | C5: 1 | D5: 2 | E5: 3 | F5: 4 | G5: 5 | H5: 6 | I5: 7 | J5: 8
B6: months-in-qtr | C6: 2 | D6: 3 | E6: 3 | F6: 3 | G6: 3 | H6: 3 | I6: 3 | J6: 3
B7: REVENUE BUILD
B8: Gross potential rent | C8: =Assumptions!$D$9*C6*(1+Assumptions!$D$10)^(C5-1) -> 1729870 | D8: =Assumptions!$D$9*D6*(1+Assumptions!$D$10)^(D5-1) -> 2601292 | E8: =Assumptions!$D$9*E6*(1+Assumptions!$D$10)^(E5-1) -> 2607795.2 | F8: =Assumptions!$D$9*F6*(1+Assumptions!$D$10)^(F5-1) -> 2614314.7 | G8: =Assumptions!$D$9*G6*(1+Assumptions!$D$10)^(G5-1) -> 2620850.5 | H8: =Assumptions!$D$9*H6*(1+Assumptions!$D$10)^(H5-1) -> 2627402.6 | I8: =Assumptions!$D$9*I6*(1+Assumptions!$D$10)^(I5-1) -> 2633971.2 | J8: =Assumptions!$D$9*J6*(1+Assumptions!$D$10)^(J5-1) -> 2640556.1 | K8: =SUM(C8:J8) -> 20076052
B9: Vacancy (occupancy path) | C9: =-Assumptions!C$51*C8 -> -403059.71 | D9: =-Assumptions!D$51*D8 -> -426611.89 | E9: =-Assumptions!E$51*E8 -> -265995.11 | F9: =-Assumptions!F$51*F8 -> -235288.33 | G9: =-Assumptions!G$51*G8 -> -235876.55 | H9: =-Assumptions!H$51*H8 -> -236466.24 | I9: =-Assumptions!I$51*I8 -> -237057.4 | J9: =-Assumptions!J$51*J8 -> -237650.05 | K9: =SUM(C9:J9) -> -2278005.3
B10: Concessions | C10: =-Assumptions!$D$12*C6 -> -64196 | D10: =-Assumptions!$D$12*D6 -> -96294 | E10: =-Assumptions!$D$12*E6 -> -96294 | F10: =-Assumptions!$D$12*F6 -> -96294 | G10: =-Assumptions!$D$12*G6 -> -96294 | H10: =-Assumptions!$D$12*H6 -> -96294 | I10: =-Assumptions!$D$12*I6 -> -96294 | J10: =-Assumptions!$D$12*J6 -> -96294 | K10: =SUM(C10:J10) -> -738254
B11: Bad debt / write-offs | C11: =-Assumptions!$D$13*C6 -> -136000 | D11: =-Assumptions!$D$13*D6 -> -204000 | E11: =-Assumptions!$D$13*E6 -> -204000 | F11: =-Assumptions!$D$13*F6 -> -204000 | G11: =-Assumptions!$D$13*G6 -> -204000 | H11: =-Assumptions!$D$13*H6 -> -204000 | I11: =-Assumptions!$D$13*I6 -> -204000 | J11: =-Assumptions!$D$13*J6 -> -204000 | K11: =SUM(C11:J11) -> -1564000
B12: Net rental income | C12: =SUM(C8:C11) -> 1126614.3 | D12: =SUM(D8:D11) -> 1874386.1 | E12: =SUM(E8:E11) -> 2041506.1 | F12: =SUM(F8:F11) -> 2078732.4 | G12: =SUM(G8:G11) -> 2084680 | H12: =SUM(H8:H11) -> 2090642.4 | I12: =SUM(I8:I11) -> 2096619.7 | J12: =SUM(J8:J11) -> 2102612 | K12: =SUM(C12:J12) -> 15495793
B13: Other income | C13: =Assumptions!$D$14*C6 -> 306118 | D13: =Assumptions!$D$14*D6 -> 459177 | E13: =Assumptions!$D$14*E6 -> 459177 | F13: =Assumptions!$D$14*F6 -> 459177 | G13: =Assumptions!$D$14*G6 -> 459177 | H13: =Assumptions!$D$14*H6 -> 459177 | I13: =Assumptions!$D$14*I6 -> 459177 | J13: =Assumptions!$D$14*J6 -> 459177 | K13: =SUM(C13:J13) -> 3520357
B14: Effective Gross Income | C14: =C12+C13 -> 1432732.3 | D14: =D12+D13 -> 2333563.1 | E14: =E12+E13 -> 2500683.1 | F14: =F12+F13 -> 2537909.4 | G14: =G12+G13 -> 2543857 | H14: =H12+H13 -> 2549819.4 | I14: =I12+I13 -> 2555796.7 | J14: =J12+J13 -> 2561789 | K14: =SUM(C14:J14) -> 19016150
B16: OPERATING EXPENSES
B17: Payroll | C17: =-Assumptions!$D$17*C6*(1+Assumptions!$D$25)^(C5-1) -> -250776 | D17: =-Assumptions!$D$17*D6*(1+Assumptions!$D$25)^(D5-1) -> -378044.82 | E17: =-Assumptions!$D$17*E6*(1+Assumptions!$D$25)^(E5-1) -> -379935.04 | F17: =-Assumptions!$D$17*F6*(1+Assumptions!$D$25)^(F5-1) -> -381834.72 | G17: =-Assumptions!$D$17*G6*(1+Assumptions!$D$25)^(G5-1) -> -383743.89 | H17: =-Assumptions!$D$17*H6*(1+Assumptions!$D$25)^(H5-1) -> -385662.61 | I17: =-Assumptions!$D$17*I6*(1+Assumptions!$D$25)^(I5-1) -> -387590.93 | J17: =-Assumptions!$D$17*J6*(1+Assumptions!$D$25)^(J5-1) -> -389528.88 | K17: =SUM(C17:J17) -> -2937116.9
B18: Marketing & other | C18: =-Assumptions!$D$18*C6*(1+Assumptions!$D$25)^(C5-1) -> -31772 | D18: =-Assumptions!$D$18*D6*(1+Assumptions!$D$25)^(D5-1) -> -47896.29 | E18: =-Assumptions!$D$18*E6*(1+Assumptions!$D$25)^(E5-1) -> -48135.771 | F18: =-Assumptions!$D$18*F6*(1+Assumptions!$D$25)^(F5-1) -> -48376.45 | G18: =-Assumptions!$D$18*G6*(1+Assumptions!$D$25)^(G5-1) -> -48618.333 | H18: =-Assumptions!$D$18*H6*(1+Assumptions!$D$25)^(H5-1) -> -48861.424 | I18: =-Assumptions!$D$18*I6*(1+Assumptions!$D$25)^(I5-1) -> -49105.731 | J18: =-Assumptions!$D$18*J6*(1+Assumptions!$D$25)^(J5-1) -> -49351.26 | K18: =SUM(C18:J18) -> -372117.26
B19: Administrative | C19: =-Assumptions!$D$19*C6*(1+Assumptions!$D$25)^(C5-1) -> -104926 | D19: =-Assumptions!$D$19*D6*(1+Assumptions!$D$25)^(D5-1) -> -158175.94 | E19: =-Assumptions!$D$19*E6*(1+Assumptions!$D$25)^(E5-1) -> -158966.82 | F19: =-Assumptions!$D$19*F6*(1+Assumptions!$D$25)^(F5-1) -> -159761.66 | G19: =-Assumptions!$D$19*G6*(1+Assumptions!$D$25)^(G5-1) -> -160560.47 | H19: =-Assumptions!$D$19*H6*(1+Assumptions!$D$25)^(H5-1) -> -161363.27 | I19: =-Assumptions!$D$19*I6*(1+Assumptions!$D$25)^(I5-1) -> -162170.09 | J19: =-Assumptions!$D$19*J6*(1+Assumptions!$D$25)^(J5-1) -> -162980.94 | K19: =SUM(C19:J19) -> -1228905.2
B20: Repairs & maintenance | C20: =-Assumptions!$D$20*C6*(1+Assumptions!$D$25)^(C5-1) -> -144512 | D20: =-Assumptions!$D$20*D6*(1+Assumptions!$D$25)^(D5-1) -> -217851.84 | E20: =-Assumptions!$D$20*E6*(1+Assumptions!$D$25)^(E5-1) -> -218941.1 | F20: =-Assumptions!$D$20*F6*(1+Assumptions!$D$25)^(F5-1) -> -220035.8 | G20: =-Assumptions!$D$20*G6*(1+Assumptions!$D$25)^(G5-1) -> -221135.98 | H20: =-Assumptions!$D$20*H6*(1+Assumptions!$D$25)^(H5-1) -> -222241.66 | I20: =-Assumptions!$D$20*I6*(1+Assumptions!$D$25)^(I5-1) -> -223352.87 | J20: =-Assumptions!$D$20*J6*(1+Assumptions!$D$25)^(J5-1) -> -224469.64 | K20: =SUM(C20:J20) -> -1692540.9
B21: Utilities | C21: =-Assumptions!$D$21*C6*(1+Assumptions!$D$25)^(C5-1) -> -253370 | D21: =-Assumptions!$D$21*D6*(1+Assumptions!$D$25)^(D5-1) -> -381955.27 | E21: =-Assumptions!$D$21*E6*(1+Assumptions!$D$25)^(E5-1) -> -383865.05 | F21: =-Assumptions!$D$21*F6*(1+Assumptions!$D$25)^(F5-1) -> -385784.38 | G21: =-Assumptions!$D$21*G6*(1+Assumptions!$D$25)^(G5-1) -> -387713.3 | H21: =-Assumptions!$D$21*H6*(1+Assumptions!$D$25)^(H5-1) -> -389651.87 | I21: =-Assumptions!$D$21*I6*(1+Assumptions!$D$25)^(I5-1) -> -391600.12 | J21: =-Assumptions!$D$21*J6*(1+Assumptions!$D$25)^(J5-1) -> -393558.12 | K21: =SUM(C21:J21) -> -2967498.1
B22: Insurance (escrowed) | C22: =-Assumptions!$D$22*C6*(1+Assumptions!$D$25)^(C5-1) -> 0 | D22: =-Assumptions!$D$22*D6*(1+Assumptions!$D$25)^(D5-1) -> 0 | E22: =-Assumptions!$D$22*E6*(1+Assumptions!$D$25)^(E5-1) -> 0 | F22: =-Assumptions!$D$22*F6*(1+Assumptions!$D$25)^(F5-1) -> 0 | G22: =-Assumptions!$D$22*G6*(1+Assumptions!$D$25)^(G5-1) -> 0 | H22: =-Assumptions!$D$22*H6*(1+Assumptions!$D$25)^(H5-1) -> 0 | I22: =-Assumptions!$D$22*I6*(1+Assumptions!$D$25)^(I5-1) -> 0 | J22: =-Assumptions!$D$22*J6*(1+Assumptions!$D$25)^(J5-1) -> 0 | K22: =SUM(C22:J22) -> 0
B23: Real estate taxes (escrowed) | C23: =-Assumptions!$D$23*C6*(1+Assumptions!$D$25)^(C5-1) -> 0 | D23: =-Assumptions!$D$23*D6*(1+Assumptions!$D$25)^(D5-1) -> 0 | E23: =-Assumptions!$D$23*E6*(1+Assumptions!$D$25)^(E5-1) -> 0 | F23: =-Assumptions!$D$23*F6*(1+Assumptions!$D$25)^(F5-1) -> 0 | G23: =-Assumptions!$D$23*G6*(1+Assumptions!$D$25)^(G5-1) -> 0 | H23: =-Assumptions!$D$23*H6*(1+Assumptions!$D$25)^(H5-1) -> 0 | I23: =-Assumptions!$D$23*I6*(1+Assumptions!$D$25)^(I5-1) -> 0 | J23: =-Assumptions!$D$23*J6*(1+Assumptions!$D$25)^(J5-1) -> 0 | K23: =SUM(C23:J23) -> 0
B24: Management fee | C24: =-Assumptions!$D$24*C14 -> -71636.615 | D24: =-Assumptions!$D$24*D14 -> -116678.16 | E24: =-Assumptions!$D$24*E14 -> -125034.16 | F24: =-Assumptions!$D$24*F14 -> -126895.47 | G24: =-Assumptions!$D$24*G14 -> -127192.85 | H24: =-Assumptions!$D$24*H14 -> -127490.97 | I24: =-Assumptions!$D$24*I14 -> -127789.84 | J24: =-Assumptions!$D$24*J14 -> -128089.45 | K24: =SUM(C24:J24) -> -950807.5
B25: Total Operating Expenses | C25: =SUM(C17:C24) -> -856992.61 | D25: =SUM(D17:D24) -> -1300602.3 | E25: =SUM(E17:E24) -> -1314877.9 | F25: =SUM(F17:F24) -> -1322688.5 | G25: =SUM(G17:G24) -> -1328964.8 | H25: =SUM(H17:H24) -> -1335271.8 | I25: =SUM(I17:I24) -> -1341609.6 | J25: =SUM(J17:J24) -> -1347978.3 | K25: =SUM(C25:J25) -> -10148986
B26: NET OPERATING INCOME | C26: =C14+C25 -> 575739.68 | D26: =D14+D25 -> 1032960.8 | E26: =E14+E25 -> 1185805.2 | F26: =F14+F25 -> 1215220.9 | G26: =G14+G25 -> 1214892.1 | H26: =H14+H25 -> 1214547.6 | I26: =I14+I25 -> 1214187.2 | J26: =J14+J25 -> 1213810.7 | K26: =SUM(C26:J26) -> 8867164.2
B28: DEBT SERVICE & ESCROWS (Mesa West)
B29: Loan balance | C29: =Assumptions!$C$28 -> 65012052 | D29: =Assumptions!$C$28 -> 65012052 | E29: =Assumptions!$C$28 -> 65012052 | F29: =Assumptions!$C$28 -> 65012052 | G29: =Assumptions!$C$28 -> 65012052 | H29: =Assumptions!$C$28 -> 65012052 | I29: =Assumptions!$C$28 -> 65012052 | J29: =Assumptions!$C$28 -> 65012052 | K29: =J29 -> 65012052
B30: Interest rate (annual) | C30: =Assumptions!$C$29 -> 0.071 | D30: =Assumptions!$C$29 -> 0.071 | E30: =Assumptions!$C$29 -> 0.071 | F30: =Assumptions!$C$29 -> 0.071 | G30: =Assumptions!$C$29 -> 0.071 | H30: =Assumptions!$C$29 -> 0.071 | I30: =Assumptions!$C$29 -> 0.071 | J30: =Assumptions!$C$29 -> 0.071 | K30: =AVERAGE(C30:J30) -> 0.071
B31: Mortgage (int + tax/ins escrow, net cap) | C31: =-((Assumptions!$C$28*Assumptions!$C$29/12)+Assumptions!$C$30+Assumptions!$C$31-Assumptions!$C$32)*C6 -> -1362409.3 | D31: =-((Assumptions!$C$28*Assumptions!$C$29/12)+Assumptions!$C$30+Assumptions!$C$31-Assumptions!$C$32)*D6 -> -2043613.9 | E31: =-((Assumptions!$C$28*Assumptions!$C$29/12)+Assumptions!$C$30+Assumptions!$C$31-Assumptions!$C$32)*E6 -> -2043613.9 | F31: =-((Assumptions!$C$28*Assumptions!$C$29/12)+Assumptions!$C$30+Assumptions!$C$31-Assumptions!$C$32)*F6 -> -2043613.9 | G31: =-((Assumptions!$C$28*Assumptions!$C$29/12)+Assumptions!$C$30+Assumptions!$C$31-Assumptions!$C$32)*G6 -> -2043613.9 | H31: =-((Assumptions!$C$28*Assumptions!$C$29/12)+Assumptions!$C$30+Assumptions!$C$31-Assumptions!$C$32)*H6 -> -2043613.9 | I31: =-((Assumptions!$C$28*Assumptions!$C$29/12)+Assumptions!$C$30+Assumptions!$C$31-Assumptions!$C$32)*I6 -> -2043613.9 | J31: =-((Assumptions!$C$28*Assumptions!$C$29/12)+Assumptions!$C$30+Assumptions!$C$31-Assumptions!$C$32)*J6 -> -2043613.9 | K31: =SUM(C31:J31) -> -15667707
B32: Cash flow after debt service | C32: =C26+C31 -> -786669.6 | D32: =D26+D31 -> -1010653.1 | E32: =E26+E31 -> -857808.74 | F32: =F26+F31 -> -828393 | G32: =G26+G31 -> -828721.77 | H32: =H26+H31 -> -829066.32 | I32: =I26+I31 -> -829426.75 | J32: =J26+J31 -> -829803.18 | K32: =SUM(C32:J32) -> -6800542.5
B33: (memo) gross mortgage before rate cap | C33: =-((Assumptions!$C$28*Assumptions!$C$29/12)+Assumptions!$C$30+Assumptions!$C$31)*C6 -> -1483873.3 | D33: =-((Assumptions!$C$28*Assumptions!$C$29/12)+Assumptions!$C$30+Assumptions!$C$31)*D6 -> -2225809.9 | E33: =-((Assumptions!$C$28*Assumptions!$C$29/12)+Assumptions!$C$30+Assumptions!$C$31)*E6 -> -2225809.9 | F33: =-((Assumptions!$C$28*Assumptions!$C$29/12)+Assumptions!$C$30+Assumptions!$C$31)*F6 -> -2225809.9 | G33: =-((Assumptions!$C$28*Assumptions!$C$29/12)+Assumptions!$C$30+Assumptions!$C$31)*G6 -> -2225809.9 | H33: =-((Assumptions!$C$28*Assumptions!$C$29/12)+Assumptions!$C$30+Assumptions!$C$31)*H6 -> -2225809.9 | I33: =-((Assumptions!$C$28*Assumptions!$C$29/12)+Assumptions!$C$30+Assumptions!$C$31)*I6 -> -2225809.9 | J33: =-((Assumptions!$C$28*Assumptions!$C$29/12)+Assumptions!$C$30+Assumptions!$C$31)*J6 -> -2225809.9
B34: CAPITAL & FUNDING USES
B35: Below-the-line capex | C35: =-Assumptions!C45 -> -116766 | D35: =-Assumptions!D45 -> -175149 | E35: =-Assumptions!E45 -> -175149 | F35: =-Assumptions!F45 -> -175149 | G35: =-Assumptions!G45 -> 0 | H35: =-Assumptions!H45 -> 0 | I35: =-Assumptions!I45 -> 0 | J35: =-Assumptions!J45 -> 0 | K35: =SUM(C35:J35) -> -642213
B36: Franchise tax reimbursement (CPM) | C36: =IF(C5=1,-Assumptions!$C$38,0) -> -126608.63 | D36: =IF(D5=1,-Assumptions!$C$38,0) -> 0 | E36: =IF(E5=1,-Assumptions!$C$38,0) -> 0 | F36: =IF(F5=1,-Assumptions!$C$38,0) -> 0 | G36: =IF(G5=1,-Assumptions!$C$38,0) -> 0 | H36: =IF(H5=1,-Assumptions!$C$38,0) -> 0 | I36: =IF(I5=1,-Assumptions!$C$38,0) -> 0 | J36: =IF(J5=1,-Assumptions!$C$38,0) -> 0 | K36: =SUM(C36:J36) -> -126608.63
B37: Closing & legal | C37: =IF(C5=1,-Assumptions!$C$39,0) -> 0 | D37: =IF(D5=1,-Assumptions!$C$39,0) -> 0 | E37: =IF(E5=1,-Assumptions!$C$39,0) -> 0 | F37: =IF(F5=1,-Assumptions!$C$39,0) -> 0 | G37: =IF(G5=1,-Assumptions!$C$39,0) -> 0 | H37: =IF(H5=1,-Assumptions!$C$39,0) -> 0 | I37: =IF(I5=1,-Assumptions!$C$39,0) -> 0 | J37: =IF(J5=1,-Assumptions!$C$39,0) -> 0 | K37: =SUM(C37:J37) -> 0
