Workbook

Sheet Rollforward_Model
B1: AVA Stabilization Rollforward
B3: ASSUMPTIONS (edit blue-fill cells)
B4: Weeks per month | C4: 4.33 | D4: Avg weeks per month (52 ÷ 12). Used to convert NL/week to monthly Net Leases.
B5: Renewal rate | C5: 0.65 | D5: % of expiring leases that renew. Lower = more turnover.
B6: Turnover rate (1 - renewal) | C6: 0.35 | D6: Non-renewers as % of expirations (= 1 − renewal rate).
B7: Voluntary turnover share | C7: 0.85 | D7: Of non-renewers, share who give notice and move out at lease end (vs. skip, evict, early term).
B8: Early move-out rate | C8: 0.1 | D8: Mid-lease break rate. % of expirations that terminate early (job transfer, death, unit issue, etc.).
B9: Baseline evictions filed / month | C9: 15 | D9: New formal eviction filings opened each month (May−Dec).
B10: Eviction success rate | C10: 0.55 | D10: % of filings that complete to writ / move-out. Remainder cure, pay, or extend.
B11: Aged delinquent flush (all in May) | C11: 34 | D11: One-time May cleanup of aged delinquent accounts. Hits Skips/FTP row only.
B12: Total units | C12: 880 | D12: Property unit count (denominator for occupancy).
B13: Monthly skip rate | C13: 0.0075 | D13: Monthly skips / FTP as % of occupied units. Baseline run-rate excluding the May aged flush.
B14: MODEL
B15: Property Summary | C15: 46048 | D15: 46079 | E15: 46107 | F15: 46138 | G15: 46168 | H15: 46199 | I15: 46229 | J15: 46260 | K15: 46291 | L15: 46321 | M15: 46352 | N15: 46382
B16: Total Units | C16: =$C$12 -> 880 | D16: =$C$12 -> 880 | E16: =$C$12 -> 880 | F16: =$C$12 -> 880 | G16: =$C$12 -> 880 | H16: =$C$12 -> 880 | I16: =$C$12 -> 880 | J16: =$C$12 -> 880 | ... N16: =$C$12 -> 880
B17: Occupied Units | C17: 681 | D17: 654 | E17: 648 | F17: 638 | G17: =MIN($C$16, F17+G22-G32) -> 641 | H17: =MIN($C$16, G17+H22-H32) -> 672 | I17: =MIN($C$16, H17+I22-I32) -> 691 | J17: =MIN($C$16, I17+J22-J32) -> 714 | K17: =MIN($C$16, J17+K22-K32) -> 723 | L17: =MIN($C$16, K17+L22-L32) -> 729 | M17: =MIN($C$16, L17+M22-M32) -> 734 | N17: =MIN($C$16, M17+N22-N32) -> 748
B18: Occupancy | C18: =C17/C16 -> 0.77386364 | D18: =D17/D16 -> 0.74318182 | E18: =E17/E16 -> 0.73636364 | F18: =F17/F16 -> 0.725 | G18: =G17/G16 -> 0.72840909 | H18: =H17/H16 -> 0.76363636 | I18: =I17/I16 -> 0.78522727 | J18: =J17/J16 -> 0.81136364 | ... N18: =N17/N16 -> 0.85
B20: Leasing
B21: NL / week (input) | C21: 3.2 | D21: 1.6 | E21: 7.6 | F21: 10 | G21: 15 | H21: 15 | I21: 14 | J21: 13 | K21: 10 | L21: 8 | M21: 8 | N21: 8
B22: Net Leases | C22: 14 | D22: 7 | E22: 33 | F22: =25+ROUND(F21*1.83,0) -> 43 | G22: =ROUND(G21*$C$4,0) -> 65 | H22: =ROUND(H21*$C$4,0) -> 65 | I22: =ROUND(I21*$C$4,0) -> 61 | J22: =ROUND(J21*$C$4,0) -> 56 | K22: =ROUND(K21*$C$4,0) -> 43 | L22: =ROUND(L21*$C$4,0) -> 35 | M22: =ROUND(M21*$C$4,0) -> 35 | N22: =ROUND(N21*$C$4,0) -> 35
B24: Exposure
B25: Lease Expirations (input) | C25: 55 | D25: 63 | E25: 58 | F25: 62 | G25: 56 | H25: 54 | I25: 73 | J25: 51 | K25: 53 | L25: 39 | M25: 44 | N25: 16
B26: Property Non-Renewal | C26: 1 | D26: 1 | E26: 1 | F26: 0 | G26: 0 | H26: 0 | I26: 0 | J26: 0 | K26: 0 | L26: 0 | M26: 0 | N26: 0
B27: Early Move Outs | C27: 0 | D27: 6 | E27: 0 | F27: 0 | G27: =ROUND(G25*$C$8,0) -> 6 | H27: =ROUND(H25*$C$8,0) -> 5 | I27: =ROUND(I25*$C$8,0) -> 7 | J27: =ROUND(J25*$C$8,0) -> 5 | K27: =ROUND(K25*$C$8,0) -> 5 | L27: =ROUND(L25*$C$8,0) -> 4 | M27: =ROUND(M25*$C$8,0) -> 4 | N27: =ROUND(N25*$C$8,0) -> 2
B28: NTV Move Outs | C28: 1 | D28: 15 | E28: 13 | F28: =7+ROUND(F25*$C$6*$C$7*(1.83/4.33),0) -> 15 | G28: =ROUND(G25*$C$6*$C$7,0) -> 17 | H28: =ROUND(H25*$C$6*$C$7,0) -> 16 | I28: =ROUND(I25*$C$6*$C$7,0) -> 22 | J28: =ROUND(J25*$C$6*$C$7,0) -> 15 | K28: =ROUND(K25*$C$6*$C$7,0) -> 16 | L28: =ROUND(L25*$C$6*$C$7,0) -> 12 | M28: =ROUND(M25*$C$6*$C$7,0) -> 13 | N28: =ROUND(N25*$C$6*$C$7,0) -> 5
B29: Skips / FTP | C29: 3 | D29: 10 | E29: 14 | F29: =11+ROUND(E17*$C$13*(1.83/4.33),0) -> 13 | G29: =ROUND(F17*$C$13,0)+$C$11 -> 39 | H29: =ROUND(G17*$C$13,0) -> 5 | I29: =ROUND(H17*$C$13,0) -> 5 | J29: =ROUND(I17*$C$13,0) -> 5 | K29: =ROUND(J17*$C$13,0) -> 5 | L29: =ROUND(K17*$C$13,0) -> 5 | M29: =ROUND(L17*$C$13,0) -> 5 | N29: =ROUND(M17*$C$13,0) -> 6
B30: Evictions Filed | C30: 8 | D30: 59 | E30: 20 | F30: 0 | G30: =$C$9 -> 15 | H30: =$C$9 -> 15 | I30: =$C$9 -> 15 | J30: =$C$9 -> 15 | K30: =$C$9 -> 15 | L30: =$C$9 -> 15 | M30: =$C$9 -> 15 | N30: =$C$9 -> 15
B31: Evictions Move Outs | C31: 0 | D31: 1 | E31: 0 | F31: 0 | G31: =ROUND(F30*$C$10,0) -> 0 | H31: =ROUND(G30*$C$10,0) -> 8 | I31: =ROUND(H30*$C$10,0) -> 8 | J31: =ROUND(I30*$C$10,0) -> 8 | K31: =ROUND(J30*$C$10,0) -> 8 | L31: =ROUND(K30*$C$10,0) -> 8 | M31: =ROUND(L30*$C$10,0) -> 8 | N31: =ROUND(M30*$C$10,0) -> 8
B32: Total Move Outs | C32: =C26+C27+C28+C29+C31 -> 5 | D32: =D26+D27+D28+D29+D31 -> 33 | E32: =E26+E27+E28+E29+E31 -> 28 | F32: =F26+F27+F28+F29+F31 -> 28 | G32: =G26+G27+G28+G29+G31 -> 62 | H32: =H26+H27+H28+H29+H31 -> 34 | I32: =I26+I27+I28+I29+I31 -> 42 | J32: =J26+J27+J28+J29+J31 -> 33 | ... N32: =N26+N27+N28+N29+N31 -> 21
B34: Net Leasing Activity | C34: =C22-C32 -> 9 | D34: =D22-D32 -> -26 | E34: =E22-E32 -> 5 | F34: =F22-F32 -> 15 | G34: =G22-G32 -> 3 | H34: =H22-H32 -> 31 | I34: =I22-I32 -> 19 | J34: =J22-J32 -> 23 | ... N34: =N22-N32 -> 14
B36: HOW TO USE — William / PBC
B37: Only edit BLUE cells. Everything else is a formula.
B38: • Assumptions (C4:C13) — global levers for May–Dec. Hover any cell for a description.
B39: • Monthly inputs — NL/week (row 21) and Lease Expirations (row 25). Edit by month.
B40: • Jan–Apr actuals (cols C–F) — Entrata-verified. Replace only with a newer close.
B41: • Month-end refresh — overwrite Occupied Units (row 17), Move-outs (rows 26–31), Net Leases (row 22) with month-end ResMan/Entrata totals.
B42: • Source detail — see Sources tab for the Jan–Apr tie-back and per-unit move-out list.

Sheet Sources
B1: AVA Rollforward Model — Source Data
B2: Linked from AVA_Weekly_Metrics_2026_Report.v2.xlsx — all values mirrored as of 2026-04-20.
B4: 1. MONTHLY ROLL-UP — Jan–Apr Actuals Used in Rollforward Model
B5: Line Item | C5: Jan-26 | D5: Feb-26 | E5: Mar-26 | F5: Apr-26 | G5: Unit | H5: Source
B6: Occupancy
B7: Occupied Units (EOM) | C7: =Rollforward_Model!C17 -> 681 | D7: =Rollforward_Model!D17 -> 654 | E7: =Rollforward_Model!E17 -> 648 | F7: =Rollforward_Model!F17 -> 638 | G7: units | H7: Dashboard_1 EOM snapshot (ResMan)
B8: Total Units | C8: =Rollforward_Model!C16 -> 880 | D8: =Rollforward_Model!D16 -> 880 | E8: =Rollforward_Model!E16 -> 880 | F8: =Rollforward_Model!F16 -> 880 | G8: units | H8: Assumption C12 (property constant)
B9: Occupancy % | C9: =C7/C8 -> 0.77386364 | D9: =D7/D8 -> 0.74318182 | E9: =E7/E8 -> 0.73636364 | F9: =F7/F8 -> 0.725 | G9: % | H9: Calculated (Occupied ÷ Total)
B10: Leasing
B11: NL / week (input) | C11: =Rollforward_Model!C21 -> 3.2 | D11: =Rollforward_Model!D21 -> 1.6 | E11: =Rollforward_Model!E21 -> 7.6 | F11: =Rollforward_Model!F21 -> 10 | G11: leases/wk | H11: Data_2 row "Net Leases" (weekly ÷ weeks)
B12: Net Leases (monthly) | C12: =Rollforward_Model!C22 -> 14 | D12: =Rollforward_Model!D22 -> 7 | E12: =Rollforward_Model!E22 -> 33 | F12: =Rollforward_Model!F22 -> 43 | G12: leases | H12: Data_2 row "Net Leases" summed by month
B13: Lease Expirations | C13: =Rollforward_Model!C25 -> 55 | D13: =Rollforward_Model!D25 -> 63 | E13: =Rollforward_Model!E25 -> 58 | F13: =Rollforward_Model!F25 -> 62 | G13: leases | H13: Data_2 RENEWALS section — Expirations by month
B14: Move-Outs (by category)
B15: Property Non-Renewal | C15: =Rollforward_Model!C26 -> 1 | D15: =Rollforward_Model!D26 -> 1 | E15: =Rollforward_Model!E26 -> 1 | F15: =Rollforward_Model!F26 -> 0 | G15: units | H15: Move_Out_Reasons: Reason = "Non-Renewal (by Property)"
B16: Early Move Outs | C16: =Rollforward_Model!C27 -> 0 | D16: =Rollforward_Model!D27 -> 6 | E16: =Rollforward_Model!E27 -> 0 | F16: =Rollforward_Model!F27 -> 0 | G16: units | H16: Move_Out_Reasons: Early Term = Yes & not skip
B17: NTV Move Outs | C17: =Rollforward_Model!C28 -> 1 | D17: =Rollforward_Model!D28 -> 15 | E17: =Rollforward_Model!E28 -> 13 | F17: =Rollforward_Model!F28 -> 15 | G17: units | H17: Move_Out_Reasons: regular lease-end (non-skip, non-early)
B18: Skips / FTP | C18: =Rollforward_Model!C29 -> 3 | D18: =Rollforward_Model!D29 -> 10 | E18: =Rollforward_Model!E29 -> 14 | F18: =Rollforward_Model!F29 -> 13 | G18: units | H18: Move_Out_Reasons: Skipped*/Failure To Pay (exc. W18-2-2070)
B19: Evictions Filed | C19: =Rollforward_Model!C30 -> 8 | D19: =Rollforward_Model!D30 -> 59 | E19: =Rollforward_Model!E30 -> 20 | F19: =Rollforward_Model!F30 -> 0 | G19: filings | H19: Evictions_RSI: monthly filings count
B20: Formal Evictions MO | C20: =Rollforward_Model!C31 -> 0 | D20: =Rollforward_Model!D31 -> 1 | E20: =Rollforward_Model!E31 -> 0 | F20: =Rollforward_Model!F31 -> 0 | G20: units | H20: Move_Out_Reasons: formal eviction (W18-2-2070 override)
B21: Total Move Outs | C21: =SUM(C15:C20)-C19 -> 5 | D21: =SUM(D15:D20)-D19 -> 33 | E21: =SUM(E15:E20)-E19 -> 28 | F21: =SUM(F15:F20)-F19 -> 28 | G21: units | H21: Sum of categories (Filings excluded — not a move-out)
B23: 2. VALIDATION — Rollforward vs. Weekly Data_2
B24: Check | C24: Jan-26 | D24: Feb-26 | E24: Mar-26 | F24: Apr-26 | G24: Status | H24: Note
B25: Occupied Units — Data_2 week-end | C25: 681 | D25: 657 | E25: 648 | F25: 640 | G25: ► see below | H25: Data_2 last week of each calendar month (2026-01-26/02-23/03-30/04-20)
B26: Δ vs Rollforward (Data_2 − RM) | C26: =C25-C7 -> 0 | D26: =D25-D7 -> 3 | E26: =E25-E7 -> 0 | F26: =F25-F7 -> 2 | G26: {=IF(SUMPRODUCT(ABS(C26:F26))=0,"Match","Review")} -> Review | H26: Reporting-date artifact — Dashboard_1 is month-end ResMan, Data_2 is Friday week-end. Gap is expected.
B27: Move-Outs — Data_2 weekly sum | C27: 21 | D27: 12 | E27: 23 | F27: 22 | G27: ► see below | H27: Data_2 row "Move Outs" — counts physical unit turnovers, different definition than ResMan categories
B28: Δ vs Rollforward Total MO | C28: =C27-C21 -> 16 | D28: =D27-D21 -> -21 | E28: =E27-E21 -> -5 | F28: =F27-F21 -> -6 | G28: {=IF(SUMPRODUCT(ABS(C28:F28))=0,"Match","Review")} -> Review | H28: Expected divergence — different counting methodology (physical vs classified)
B30: 3. DATA_2 — Monthly Aggregation (Weekly Performance KPIs rolled up)
B31: KPI | C31: Jan-26 | D31: Feb-26 | E31: Mar-26 | F31: Apr-26 (partial) | G31: Method | H31: Notes
B32: Occupancy (stocks: EOM)
B33: Occupancy % | C33: 0.81142857 | D33: 0.75629291 | E33: 0.73913043 | F33: 0.72311213 | G33: EOM | H33: Last week of month (Friday snapshot)
B34: Occupied Units | C34: 681 | D34: 657 | E34: 648 | F34: 640 | G34: EOM | H34: Last week of month
B35: Exposure % | C35: 0.24228571 | D35: 0.22425629 | E35: 0.26773455 | F35: 0.27688787 | G35: EOM | H35: Vacant + NTV + evicted as % of total
B36: Leasing Pipeline (flows: monthly sum)
B37: New Prospects | C37: 422 | D37: 495 | E37: 617 | F37: 515 | G37: SUM | H37: Traffic
B38: Tours | C38: 72 | D38: 92 | E38: 163 | F38: 70 | G38: SUM
B39: Submitted Apps | C39: 30 | D39: 80 | E39: 98 | F39: 44 | G39: SUM
B40: Approved Apps | C40: 12 | D40: 9 | E40: 38 | F40: 27 | G40: SUM
B41: New Leases | C41: 10 | D41: 9 | E41: 36 | F41: 25 | G41: SUM
B42: Net Leases | C42: 9 | D42: 9 | E42: 36 | F42: 24 | G42: SUM | H42: New − cancelled. Feeds Rollforward Net Leases row 22
B43: Move Activity (flows: monthly sum)
...
