Workbook

Sheet Claude Log
A1: Turn # | B1: Date | C1: User Request | D1: Action Taken | E1: Details | F1: Outcome
A2: 1 | B2: 46112 | C2: User asked if any tabs reference data from the RR_Unit_Details tab. | D2: Searched all 40 sheets for formula references to RR_Unit_Details (and partial variants). | E2: Used matchFormulas search for 'RR_Unit_Details', 'RR_Unit', and 'Unit_Details' across all sheets. Zero matches found in all searches. | F2: RR_Unit_Details is a standalone data tab with no inbound formula references from other sheets.
A3: 2 | B3: 46112 | C3: User asked if any tabs reference data from the Res_Retention tab. | D3: Searched all sheets for formula references to Res_Retention. | E3: Found 1 match: Data_2!R57 contains =SUMPRODUCT((Res_Retention!$O$2:$O$14)) with result 79. | F3: Only Data_2 pulls from Res_Retention via a single SUMPRODUCT formula.
A4: 3 | B4: 46112 | C4: User uploaded CSV (Untitled-2026-03-31.csv, 113 rows of LeaseLock claims data) and asked to import it into the LeaseLock tab. | D4: Parsed CSV, mapped 26 CSV columns to 22 LeaseLock columns (A-V), wrote all 113 rows with values and formulas. | E4: Column mapping: A=Item#, B=pmc_name, C=tenant, D=unit, E=property, F=status, G=substatus, H=certificate_id (text), I/J=blank, K=carrier, L=total_claimed, M=total_paid, N=formula(L-M), O=formula(M/L as %), P=unused_coverage+paid, Q=denial_reason, R=dismissed, S=blank, T=days(reported-moveout), U=loss_date, V=TEXT(U,YYYY-MM). Formatted L/M/N/P as $#,##0.00, O as 0.0%, U as mm/dd/yyyy, H as text. | F4: 113 rows populated in LeaseLock!A2:V114. All formulas verified working. Certificate IDs fixed from scientific notation to text.
A5: 4 | B5: 46112 | C5: User corrected that column A should contain claim_number from CSV, not a row counter. Asked about filling other missing columns. | D5: Replaced A2:A114 with claim_number values from CSV (e.g. 25-103410). Identified which columns still lack data. | E5: Formatted A as text to preserve dash format. Columns I(LossType), J(LossCause), S(Adjuster) have no CSV equivalent. Remaining unmapped CSV fields: claim_reported_date, reported_reoccupied_date, claim_dispute_date, total_claimed_amount_within_limit_usd, is_claim_action_required, claim_is_missing_documentation, claim_missing_documentation_list, owner_name, pms_property_id, pms_tenant_id. | F5: Column A now shows claim numbers. Awaiting user direction on where to place remaining unmapped CSV fields.
A6: 5 | B6: 46131 | C6: Excel peer (rollforward model) requested Jan-26, Feb-26, Mar-26 total move-outs with component breakdown (lease expiration / NTV / early / evictions) and source citation. | D6: Queried Move_Out_Reasons sheet, parsed 96 rows, categorized by Reason + Early Termination flag, aggregated by month. | E6: Source: Move_Out_Reasons!A1:M97 (row-level move-out log). Dates stored as Excel serials. Bucketing: Eviction = Skipped During Eviction + Skipped Without Notice + Failure To Pay; Lease Expiration = Non-Renewal (by Property); Early Move-Out = Early Termination flag Yes (non-eviction); NTV = resident-initiated non-renewal, Early Termination No. Jan-26: 5 (3 evict, 1 lease exp, 0 early, 1 NTV). Feb-26: 33 (11 evict, 1 lease exp, 6 early, 15 NTV). Mar-26: 28 (14 evict, 1 lease exp, 0 early, 13 NTV). | F6: Totals and breakdown shared with rollforward Excel peer via JSON file (move_outs_breakdown.json) and message. Note: no separate 'monthly totals' summary table exists in the workbook — figures derived by aggregating the row-level log.
A7: 6 | B7: 46131 | C7: Rollforward peer asked for stricter eviction definition: formal eviction filings that resulted in a move-out in Jan/Feb/Mar 2026, plus residual skip/SWN/FTP count per month. | D7: Pulled Evictions_RSI!A1:I62 (60 filings, all Feb 2026 issue dates), matched to eviction-bucket move-outs in Move_Out_Reasons by last-name + unit number. | E7: Methodology: formal eviction move-out = (a) Reason = 'Skipped During Eviction' OR (b) matching RSI filing with status in {Granted, LC Handling Appeal, Dismissed (Tenant Vacated)}. Cancelled filings treated as NOT formal (filing dropped). Strict-formal counts: Jan-26=0, Feb-26=4, Mar-26=0. Residual skip/SWN/FTP: Jan-26=3, Feb-26=7, Mar-26=14. Broad view (any filing match incl. Cancelled): Feb-26=7, Mar-26=5. | F7: Results shared via eviction_split.json to rollforward peer. Key caveat: RSI sheet only contains Feb 2026 filings — Jan-26 zero formal likely reflects data scope, not reality; Mar-26 zero strict-formal because tenants skipped before court dates arrived.
A8: 7 | B8: 46131 | C8: Rollforward peer asked for comprehensive cross-reference of eviction/skip data across ALL source sheets — enumerate sources, flag conflicts, recommend authoritative methodology. | D8: Enumerated 42 sheets, pulled raw data from Evictions_RSI (60 filings Feb-only), Eviction_Success_Rate (47 tenants w/balance since 12/15/25), resident aged receivable (136 rows sampled), Write_Off_Recon (42 accounts 60+ days), Data_2 (weekly metrics), Delinquency_Detail_3 (current delinquent residents). Built unit-level cross-reference joining Move_Out_Reasons to ResMan Lease Status. | E8: MAJOR FINDING: ResMan's structured Lease Status field is authoritative; 3-way comparison on 28 Jan-Mar eviction-bucket move-outs: Move_Out_Reasons=27 skip/1 eviction, RSI strict=4 formal, ResMan=26 Past-Skip/1 Past-Eviction (Candler)/1 not in sample. 5 explicit conflicts flagged, biggest: 3 'Dismissed (Tenant Vacated)' RSI filings are Past-Skip per ResMan — invalidates prior eviction_split.json's Feb=4 formal. Correct count is Feb=1 formal/10 skip. | F8: Wrote eviction_crossref.json to shared files; sent to rollforward peer with recommendation to rebuild on ResMan basis. Data gaps flagged: RSI missing Jan/Mar filings, my RAR sample missed ~12 units (voluntary move-outs not needed for eviction classification anyway).
A9: 8 | B9: 46131 | C9: Rollforward peer asked for AVA workbook style guide (colors, fonts, number formats, section headers, borders, layout) to apply matching branding to another workbook. | D9: Inspected Dashboard_1 (canonical styled sheet), Data_2 (wide time-series), Res_Retention (unstyled). Pulled real cell styles, borders, column widths, row heights, freeze panes. Wrote comprehensive style guide to ava_style_guide.json and shared with peer. | E9: Primary palette: navy #1F3864 (title/headers), light blue #E8EEF4 (sub-section fills), divider #2E5090, good #C6EFCE/#006100, bad #FFC7CE/#9C0006, input #0000FF on #DEEAF6, gridline #D9D9D9. Calibri throughout. Title 18pt bold, section headers 9-10pt bold, body 9pt (Dashboard) or 11pt (Data_2). Number formats: 0.0% / 0.00% / #,##0 / 0.0 / m/d/yy / mmm-yy / mmmm d,yyyy. No currency or multiples in source workbook (flagged for peer). | F9: ava_style_guide.json written to shared files (~14k chars). Peer has canonical example ranges, hex codes, font specs, border patterns, and layout conventions for applying matching branding to Rollforward Model.
A10: 9 | B10: 46131 | C10: Rollforward peer asked to narrow the style guide to ONLY the 'blue' formatted summary/dashboard tabs (not raw data dumps), with specific focus on colors, fonts, totals, input cells, and canonical example ranges. | D10: Surveyed all 42 tabs, classified 10 as blue-formatted (Dashboard_1, Delinquency_Detail_3, App_Pipeline_Intel_4, Action_Item_Tracker_5, Weekly_Question_Set_6, Screening_Impact_Analysis_7, Eviction_Success_Rate, CAF vs Pipeline Comparison, Incentive_Scorecard, Instructions) vs 29+ raw data tabs. Flagged variants: Data_2 (styled data table, 20pt title), LeaseLock (#102346 vendor palette, not AVA), Claude Log (#4472C4 Excel default). Pulled real styles from 3 canonical blue tabs (Dashboard_1, Delinquency_Detail_3, Action_Item_Tracker_5) + Eviction_Success_Rate for totals-row pattern. | E10: Brand palette: #1F3864 primary navy (title, header bars), #1B365D subsection label text, #E8EEF4 subsection/total fills, #2E5090 divider borders (thin/medium), #DEEAF6 emphasized/input fill with #0000FF bold input text. Status triad: good #C6EFCE/#006100, warning #FFF2CC/#BF8F00, bad #FFC7CE/#9C0006. Calibri throughout. Title 18pt bold navy; column-header bars 8-9pt white-on-navy bold; subsection labels 9-10pt bold navy on light blue; body 8-9pt. Number formats: $#,##0.00 (with cents), $#,##0 (whole), #,##0, 0.0%, 0.0, m/d/yyyy, mm/dd/yyyy, 'mmmm d, yyyy'. Totals: fill #E8EEF4 + bold black + thin #1F3864 top/bottom borders (canonical: Eviction_Success_Rate A16:E16). | F10: Wrote ava_style_guide.json (~13k chars) to shared files and sent to peer. Guide is narrowly scoped: explicit list of blue vs raw tabs, canonical example ranges for every element (title, header bar, subsection label, totals, input cell, status badges, currency, dates), and notes on 2 tabs that look similar but use different palettes (LeaseLock, Claude Log) so the peer doesn't copy them by mistake.
A11: 10 | B11: 46131 | C11: Peer acknowledged eviction_split.json but reported both other tasks (cross-tab verification + style guide) still open — they hadn't received the files. Asked to complete both. | D11: Rewrote both files fresh in a single execute_office_js call and broadcast via conductor.writeFile. | E11: eviction_crossref.json (5729 chars): cross-tab verification identifying resident aged receivable's Lease Status as authoritative. Jan-Mar 2026 verified breakdown: 66 total move-outs, 28 eviction-bucket by Reason, but only 1 formal eviction per ResMan (Candler W18-2-2070), 26 Past-Skip, 1 not in sample (Nwosu S39-155). 5 explicit conflicts documented. ava_style_guide.json (8595 chars): narrow scope for 10 blue formatted tabs, Dashboard_1 canonical, explicit do-not-copy list (LeaseLock #102346, Claude Log #4472C4), palette (#1F3864 navy, #1B365D text, #E8EEF4 subsection fill, #2E5090 divider, #DEEAF6 emphasized/input, status triad), Calibri font sizes 18/11/9-10/9/8, number formats, canonical example ranges. | F11: Both files broadcast. Sending consolidated message to peer confirming availability and summarizing key findings. Peer had paused Rollforward Model writes until verification arrived.
A12: 11 | B12: 46131 | C12: Peer reported still only has eviction_split.json and asked for the two outstanding tasks. Shared-file broadcasts aren't persisting for this session — listFiles returns empty after write, readFile returns null. Switching to inline delivery. | D12: Wrote verified_move_outs_crosstab.json (8788 chars) and ava_style_guide.json (7423 chars) via conductor.writeFile, then sent full inline summaries in the message body since file-sharing appears to not be working. | E12: Verified Jan-Mar 2026 breakdown (n=66 total): formal_eviction=1 (Candler W18-2-2070 Feb), skip/SWN/FTP=27 (Jan=3 Feb=10 Mar=14), NTV=29 (Jan=1 Feb=15 Mar=13), early_term=6 (all Feb), property_nonrenewal=3 (one each month). Sum=66 checks. Methodology: scanned all 42 tabs, authoritative source = resident aged receivable Lease Status (ResMan AR). RSI only has Feb filings — not the count basis. Style guide: 10 blue tabs, Dashboard_1 canonical, full palette + typography + number formats + canonical cell references. | F12: Both deliverables now inline in peer message. Rollforward peer has what they need to proceed with writes. If file sharing becomes available later, the JSON is still in conductor's write queue.
A13: 12 | B13: 46131 | C13: Peer confirmed receipt of eviction_crossref.json and is proceeding with Rollforward Model. Style guide (ava_style_guide.json) still outstanding. Peer asked for it as the last remaining task. | D13: Rewrote ava_style_guide.json via conductor.writeFile (7724 chars). Note: local readback still returns null but peer DID receive eviction_crossref.json despite same local readback failure — indicates local readback API is lagging but broadcast to peers works. | E13: Content: scope = 10 blue formatted summary tabs (Dashboard_1 canonical). Do-not-copy list (LeaseLock/Claude Log/Data_2). Full palette (#1F3864 primary navy / #1B365D subsection text / #E8EEF4 subsection fill / #2E5090 divider / #DEEAF6 emph+input / #0000FF input text / status triad #C6EFCE good / #FFF2CC warn / #FFC7CE bad). Calibri typography 18/11/9-10/9/8pt. Number formats: $#,##0.00, $#,##0, #,##0, 0.0%, mmmm d\, yyyy, m/d/yyyy, mm/dd/yyyy. Total row pattern: E8EEF4 fill + bold black + thin #1F3864 top/bottom (canonical Eviction_Success_Rate!A16:E16). Column widths, row heights, canonical cell refs for every element. | F13: Sent confirmation message to peer. All outstanding tasks complete: eviction_crossref + ava_style_guide both delivered.
... A84: 44 | B84: 46140 | C84: User asked to update Weekly_Question_Set_6 for Wk17 with specific themes: new prospects quality (post pricing change), conversion drop, Justin onboarding, maintenance backfill, renewals to 80%, collections to 93%, WO backlog plan. | D84: Pulled Wk17 Dashboard, App Pipeline, and Targets KPIs. Built 12 questions: 3 Leasing (B7-B9), 3 Collections (B11-B13), 3 Renewals (B15-B17), 1 Ops (B19), 2 Carryover (B21-B22). Each with Discussion Topic (C), Supporting Data (D), Target (E), Actual (F), Var (G). Applied red/green conditional formatting to F/G columns based on hit/miss. | E84: Also added Wk17 action item: 'Maintenance Supervisor Backfill' (row 15, owner Alex, ASAP, Pending) re Angel's resignation. WO backlog 101 (+19 WoW), completion 83.7% post-Angel. New 80% renewal targets already in Targets!J18:J28 (user updated). | F84: Complete. Yellow H column ready for team responses. Question set covers all themes user specified.

Sheet Instructions
C2: AVA APARTMENTS
C3: Weekly Metrics Report — User Guide
C4: Arlast Capital | CAF Management
C7: OVERVIEW
C9: This workbook provides real-time tracking of operational KPIs for AVA Apartments under CAF management.
C10: All calculations are formula-driven. Enter data in the Data tab and the Dashboard updates automatically.
C12: TAB STRUCTURE
C14: Dashboard
C15: Executive summary comparing current week actuals to targets.
C16: Change the "Reporting Week" number (1–24) to view any week. Target, Actual, Variance, Prior Week, WoW Δ, and Status columns all update automatically.
C18: Data
C19: Primary data entry tab. Enter weekly actuals here in the blue-highlighted input cells.
... C88: Questions: Arlast Capital | sergio@arlast.com

Sheet Incentive_Scorecard
A1: AVA APARTMENTS — Q2 2026 INCENTIVE COMPENSATION SCORECARD (SIMPLIFIED)
A2: Performance Period: April 1 – June 30, 2026 | Measurement Date: June 30, 2026 | Payout: Within 30 days of measurement
A4: PAYOUT SUMMARY
A5: Participant | B5: Role | C5: Total Pool | D5: KPI 1 Payout | E5: KPI 2 Payout | F5: Total Payout
A6: Shawna | B6: Collections Manager | C6: 7000 | D6: =I14 -> 0 | E6: =I15 -> 0 | F6: =D6+E6 -> 0
A7: Alex | B7: Community Manager | C7: 10000 | D7: =I20 -> 0 | E7: =I21 -> 0 | F7: =D7+E7 -> 0
A8: Nylsa | B8: District Manager | C8: 7000 | D8: =I27 -> 0 | E8: =I28 -> 0 | F8: =D8+E8 -> 0
A9: Avery | B9: Sr. Account Manager | C9: 5000 | D9: =I34 -> 0 | E9: =I35 -> 0 | F9: =D9+E9 -> 0
A10: TOTAL | C10: =SUM(C6:C9) -> 29000 | D10: =SUM(D6:D9) -> 0 | E10: =SUM(E6:E9) -> 0 | F10: =SUM(F6:F9) -> 0
A12: SHAWNA — Collections Manager | G12: Pool: $7,000
A13: Metric | B13: Weight | C13: Base Target | D13: April | E13: May | F13: June | G13: Q2 Result | H13: Base Met? | I13: Payout
A14: Current-Month Collection Rate | B14: 0.6 | C14: ≥93% avg | G14: =IF(COUNTA(D14:F14)=0,"",AVERAGE(D14:F14)) | H14: =IF(G14="","—",IF(G14>=0.93,"✓","✗")) -> — | I14: =IF(H14="✓",B14*$C$6,0) -> 0
A15: Eviction Court Success Rate | B15: 0.4 | C15: ≥85% | G15: =IF(COUNTA(D15:F15)=0,"",SUM(D15:F15)/COUNTA(D15:F15)) | H15: =IF(G15="","—",IF(G15>=0.85,"✓","✗")) -> — | I15: =IF(H15="✓",B15*$C$6,0) -> 0
B16: =SUM(B14:B15) -> 1 | H16: Total Payout → | I16: =SUM(I14:I15) -> 0
A18: ALEX — Community Manager | G18: Pool: $10,000
A19: Metric | B19: Weight | C19: Base Target | D19: April | E19: May | F19: June | G19: Q2 Result | H19: Base Met? | I19: Payout
A20: Occupancy (June 30) | B20: 0.6 | C20: P≥84% & E≥77% | H20: =IF(OR(F20="",G20=""),"—",IF(AND(F20>=0.84,G20>=0.77),"✓","✗")) -> — | I20: =IF(H20="✓",B20*$C$7,0) -> 0
A21: Renewal Conversion Rate | B21: 0.4 | C21: ≥80% | G21: =IF(COUNTA(D21:F21)=0,"",SUM(D21:F21)/COUNTA(D21:F21)) | H21: =IF(G21="","—",IF(G21>=0.8,"✓","✗")) -> — | I21: =IF(H21="✓",B21*$C$7,0) -> 0
B23: =SUM(B20:B21) -> 1 | H23: Total Payout → | I23: =SUM(I20:I21) -> 0
A25: NYLSA — District Manager | G25: Pool: $7,000
A26: Metric | B26: Weight | C26: Base Target | D26: April | E26: May | F26: June | G26: Q2 Result | H26: Base Met? | I26: Payout
A27: June NOI vs. Proforma | B27: 0.6 | C27: ≥95% of proforma | G27: =IF(F27="","",F27/258000) | H27: =IF(G27="","—",IF(G27>=0.95,"✓","✗")) -> — | I27: =IF(H27="✓",B27*$C$8,0) -> 0
A28: Delinquency Compression | B28: 0.4 | C28: ≤$200K | G28: =IF(F28="","",F28) | H28: =IF(G28="","—",IF(G28<=200000,"✓","✗")) -> — | I28: =IF(H28="✓",B28*$C$8,0) -> 0
B30: =SUM(B27:B28) -> 1 | H30: Total Payout → | I30: =SUM(I27:I28) -> 0
A32: AVERY — Sr. Account Manager | G32: Pool: $5,000
A33: Metric | B33: Weight | C33: Base Target | D33: April | E33: May | F33: June | G33: Q2 Result | H33: Base Met? | I33: Payout
A34: Eviction Filing Accuracy | B34: 0.6 | C34: ≥90% | G34: =IF(COUNTA(D34:F34)=0,"",SUM(D34:F34)/COUNTA(D34:F34)) | H34: =IF(G34="","—",IF(G34>=0.9,"✓","✗")) -> — | I34: =IF(H34="✓",B34*$C$9,0) -> 0
A35: LeaseLock Claims Recovery | B35: 0.4 | C35: 100% filed + ≥60% | G35: =IF(COUNTA(D35:F35)=0,"",AVERAGE(D35:F35)) | H35: =IF(G35="","—",IF(G35>=0.6,"✓","✗")) -> — | I35: =IF(H35="✓",B35*$C$9,0) -> 0
B37: =SUM(B34:B35) -> 1 | H37: Total Payout → | I37: =SUM(I34:I35) -> 0
A39: PAYOUT MECHANICS & GOVERNANCE
A40: Weighted Payout: Each metric earns its weighted share of the participant's total pool independently. No all-or-nothing gate — missing one metric does not forfeit the other.
A41: No Outperform Bonus: There is no outperform tier. Hit the base target → earn that metric's weighted share. Miss → $0 on that metric.
A42: Blue cells (Apr/May/Jun and Q2 Result columns) are input placeholders. Enter actuals from Entrata and base reports as the quarter progresses.
A43: Mid-Quarter Check-In: ~May 15, 2026 (coaching checkpoint only, no payments). Final measurement: June 30, 2026.
A44: Data Sources: Entrata (system of record), RSI, Nationwide, Arlast Capital weekly metrics workbook, CAF V2 budget. Entrata governs in case of discrepancy.

Sheet Dashboard_1
B1: AVA APARTMENTS
B2: Weekly Performance Dashboard
B3: Reporting Week: | C3: 17 | D3: ← Enter week # (1-24) | F3: =IFERROR(VLOOKUP(C3,Targets!A:B,2,FALSE()),"") -> 46139
B5: KPI | C5: Target | D5: Actual | E5: Var | F5: Prior Wk | G5: WoW Δ | H5: Status
B6: OCCUPANCY
B7: Occupancy % | C7: =IFERROR(INDEX(Targets!$A$5:$O$28,$C$3,3),"—") -> 0.87 | D7: {=IFERROR(INDEX(Data_2!$D$6:$AC$6,1,$C$3+2),"")} -> 0.73112128 | E7: =IFERROR(D7-C7,"—") -> -0.13887872 | F7: {=IFERROR(INDEX(Data_2!$D$6:$AC$6,1,$C$3+1),"")} -> 0.7323 | G7: =IFERROR(D7-F7,"—") -> -0.0011787185 | H7: =IF(AND(ISNUMBER(D7),ISNUMBER(C7)),IF(D7>=C7,"✓","✗"),"") -> ✗
B8: Occupied Units | C8: =IFERROR(INDEX(Targets!$A$5:$O$28,$C$3,4),"—") -> 766 | D8: {=IFERROR(INDEX(Data_2!$D$7:$AC$7,1,$C$3+2),"")} -> 639 | E8: =IFERROR(D8-C8,"—") -> -127 | F8: {=IFERROR(INDEX(Data_2!$D$7:$AC$7,1,$C$3+1),"")} -> 640 | G8: =IFERROR(D8-F8,"—") -> -1 | H8: =IF(AND(ISNUMBER(D8),ISNUMBER(C8)),IF(D8>=C8,"✓","✗"),"") -> ✗
B9: Exposure % | C9: — | D9: {=IFERROR(INDEX(Data_2!$D$13:$AC$13,1,$C$3+2),"")} -> 0.28489703 | E9: — | F9: {=IFERROR(INDEX(Data_2!$D$13:$AC$13,1,$C$3+1),"")} -> 0.2769 | G9: =IFERROR(D9-F9,"—") -> 0.0079970252
B10: LEASING FUNNEL
B11: New Prospects | C11: =IFERROR(INDEX(Targets!$A$5:$O$28,$C$3,5),"—") -> 120 | D11: {=IFERROR(INDEX(Data_2!$D$15:$AC$15,1,$C$3+2),"")} -> 246 | E11: =IFERROR(D11-C11,"—") -> 126 | F11: {=IFERROR(INDEX(Data_2!$D$15:$AC$15,1,$C$3+1),"")} -> 210 | G11: =IFERROR(D11-F11,"—") -> 36 | H11: =IF(AND(ISNUMBER(D11),ISNUMBER(C11)),IF(D11>=C11,"✓","✗"),"") -> ✓
B12: Tours | C12: =IFERROR(INDEX(Targets!$A$5:$O$28,$C$3,6),"—") -> 23 | D12: {=IFERROR(INDEX(Data_2!$D$16:$AC$16,1,$C$3+2),"")} -> 26 | E12: =IFERROR(D12-C12,"—") -> 3 | F12: {=IFERROR(INDEX(Data_2!$D$16:$AC$16,1,$C$3+1),"")} -> 19 | G12: =IFERROR(D12-F12,"—") -> 7 | H12: =IF(AND(ISNUMBER(D12),ISNUMBER(C12)),IF(D12>=C12,"✓","✗"),"") -> ✓
B13: Submitted Apps | C13: =IFERROR(INDEX(Targets!$A$5:$O$28,$C$3,7),"—") -> 16 | D13: {=IFERROR(INDEX(Data_2!$D$18:$AC$18,1,$C$3+2),"")} -> 20 | E13: =IFERROR(D13-C13,"—") -> 4 | F13: {=IFERROR(INDEX(Data_2!$D$18:$AC$18,1,$C$3+1),"")} -> 13 | G13: =IFERROR(D13-F13,"—") -> 7 | H13: =IF(AND(ISNUMBER(D13),ISNUMBER(C13)),IF(D13>=C13,"✓","✗"),"") -> ✓
B14: Net Apps | C14: =IFERROR(INDEX(Targets!$A$5:$O$28,$C$3,8),"—") -> 12 | D14: {=IFERROR(INDEX(Data_2!$D$23:$AC$23,1,$C$3+2),"")} -> 10 | E14: =IFERROR(D14-C14,"—") -> -2 | F14: {=IFERROR(INDEX(Data_2!$D$23:$AC$23,1,$C$3+1),"")} -> 4 | G14: =IFERROR(D14-F14,"—") -> 6 | H14: =IF(AND(ISNUMBER(D14),ISNUMBER(C14)),IF(D14>=C14,"✓","✗"),"") -> ✗
B15: Net Leases | C15: =IFERROR(INDEX(Targets!$A$5:$O$28,$C$3,9),"—") -> 10 | D15: {=IFERROR(INDEX(Data_2!$D$26:$AC$26,1,$C$3+2),"")} -> 7 | E15: =IFERROR(D15-C15,"—") -> -3 | F15: {=IFERROR(INDEX(Data_2!$D$26:$AC$26,1,$C$3+1),"")} -> 14 | G15: =IFERROR(D15-F15,"—") -> -7 | H15: =IF(AND(ISNUMBER(D15),ISNUMBER(C15)),IF(D15>=C15,"✓","✗"),"") -> ✗
B16: APP PIPELINE
B17: Total Apps in Pipeline | C17: =IFERROR(IF(_xlfn.SINGLE(INDEX(Targets!$A$5:$W$28,$C$3,16))=0,"—",_xlfn.SINGLE(INDEX(Targets!$A$5:$W$28,$C$3,16))),"—") -> 70 | D17: {=IFERROR(INDEX(Data_2!$D$28:$AC$28,1,$C$3+2),"")} -> 168 | E17: =IF(OR(C17="—",NOT(ISNUMBER(C17))),"—",IFERROR(C17-D17,"—")) -> -98 | F17: {=IF($C$3>1,IFERROR(INDEX(Data_2!$D$28:$AC$28,1,$C$3+1),""),"")} -> 145 | G17: =IFERROR(F17-D17,"—") -> -23 | H17: =IF(AND(ISNUMBER(D17),ISNUMBER(C17)),IF(D17<=C17,"✓","✗"),"") -> ✗
B18: Still Actively Open | C18: =IFERROR(IF(_xlfn.SINGLE(INDEX(Targets!$A$5:$W$28,$C$3,17))=0,"—",_xlfn.SINGLE(INDEX(Targets!$A$5:$W$28,$C$3,17))),"—") -> 35 | D18: {=IFERROR(INDEX(Data_2!$D$29:$AC$29,1,$C$3+2),"")} -> 46 | E18: =IF(OR(C18="—",NOT(ISNUMBER(C18))),"—",IFERROR(C18-D18,"—")) -> -11 | F18: {=IF($C$3>1,IFERROR(INDEX(Data_2!$D$29:$AC$29,1,$C$3+1),""),"")} -> 36 | G18: =IFERROR(F18-D18,"—") -> -10 | H18: =IF(AND(ISNUMBER(D18),ISNUMBER(C18)),IF(D18<=C18,"✓","✗"),"") -> ✗
B19: Converted to Lease | C19: =C15 -> 10 | D19: {=IFERROR(INDEX(Data_2!$D$30:$AC$30,1,$C$3+2),"")} -> 7 | E19: =IF(OR(C19="—",NOT(ISNUMBER(C19))),"—",IFERROR(D19-C19,"—")) -> -3 | F19: {=IF($C$3>1,IFERROR(INDEX(Data_2!$D$30:$AC$30,1,$C$3+1),""),"")} -> 14 | G19: =IFERROR(D19-F19,"—") -> -7 | H19: =IF(AND(ISNUMBER(D19),ISNUMBER(C19)),IF(D19>=C19,"✓","✗"),"") -> ✗
B20: Cancelled / Denied | C20: =IFERROR(IF(_xlfn.SINGLE(INDEX(Targets!$A$5:$W$28,$C$3,19))=0,"—",_xlfn.SINGLE(INDEX(Targets!$A$5:$W$28,$C$3,19))),"—") -> 20 | D20: {=IFERROR(INDEX(Data_2!$D$31:$AC$31,1,$C$3+2),"")} -> 80 | E20: =IF(OR(C20="—",NOT(ISNUMBER(C20))),"—",IFERROR(C20-D20,"—")) -> -60 | F20: {=IF($C$3>1,IFERROR(INDEX(Data_2!$D$31:$AC$31,1,$C$3+1),""),"")} -> 74 | G20: =IFERROR(F20-D20,"—") -> -6 | H20: =IF(AND(ISNUMBER(D20),ISNUMBER(C20)),IF(D20<=C20,"✓","✗"),"") -> ✗
B21: Conversion Rate | C21: =IFERROR(IF(_xlfn.SINGLE(INDEX(Targets!$A$5:$W$28,$C$3,20))=0,"—",_xlfn.SINGLE(INDEX(Targets!$A$5:$W$28,$C$3,20))),"—") -> 0.15 | D21: {=IFERROR(INDEX(Data_2!$D$32:$AC$32,1,$C$3+2),"")} -> 0.041666667 | E21: =IF(OR(C21="—",NOT(ISNUMBER(C21))),"—",IFERROR(D21-C21,"—")) -> -0.10833333 | F21: {=IF($C$3>1,IFERROR(INDEX(Data_2!$D$32:$AC$32,1,$C$3+1),""),"")} -> 0.097 | G21: =IFERROR(D21-F21,"—") -> -0.055333333 | H21: =IF(AND(ISNUMBER(D21),ISNUMBER(C21)),IF(D21>=C21,"✓","✗"),"") -> ✗
B22: Loss Rate | C22: =IFERROR(IF(_xlfn.SINGLE(INDEX(Targets!$A$5:$W$28,$C$3,21))=0,"—",_xlfn.SINGLE(INDEX(Targets!$A$5:$W$28,$C$3,21))),"—") -> 0.25 | D22: {=IFERROR(INDEX(Data_2!$D$33:$AC$33,1,$C$3+2),"")} -> 0.47619048 | E22: =IF(OR(C22="—",NOT(ISNUMBER(C22))),"—",IFERROR(C22-D22,"—")) -> -0.22619048 | F22: {=IF($C$3>1,IFERROR(INDEX(Data_2!$D$33:$AC$33,1,$C$3+1),""),"")} -> 0.51 | G22: =IFERROR(F22-D22,"—") -> 0.033809524 | H22: =IF(AND(ISNUMBER(D22),ISNUMBER(C22)),IF(D22<=C22,"✓","✗"),"") -> ✗
B23: Apps 15+ Days Old | C23: =IFERROR(IF(_xlfn.SINGLE(INDEX(Targets!$A$5:$W$28,$C$3,22))=0,"—",_xlfn.SINGLE(INDEX(Targets!$A$5:$W$28,$C$3,22))),"—") -> 8 | D23: {=IFERROR(INDEX(Data_2!$D$34:$AC$34,1,$C$3+2),"")} -> 21 | E23: =IF(OR(C23="—",NOT(ISNUMBER(C23))),"—",IFERROR(C23-D23,"—")) -> -13 | F23: {=IF($C$3>1,IFERROR(INDEX(Data_2!$D$34:$AC$34,1,$C$3+1),""),"")} -> 18 | G23: =IFERROR(F23-D23,"—") -> -3 | H23: =IF(AND(ISNUMBER(D23),ISNUMBER(C23)),IF(D23<=C23,"✓","✗"),"") -> ✗
B24: Avg Days to Decision | C24: =IFERROR(IF(_xlfn.SINGLE(INDEX(Targets!$A$5:$W$28,$C$3,23))=0,"—",_xlfn.SINGLE(INDEX(Targets!$A$5:$W$28,$C$3,23))),"—") -> 7 | D24: {=IFERROR(INDEX(Data_2!$D$35:$AC$35,1,$C$3+2),"")} -> 15.8 | E24: =IF(OR(C24="—",NOT(ISNUMBER(C24))),"—",IFERROR(C24-D24,"—")) -> -8.8 | F24: {=IF($C$3>1,IFERROR(INDEX(Data_2!$D$35:$AC$35,1,$C$3+1),""),"")} -> 18.1 | G24: =IFERROR(F24-D24,"—") -> 2.3 | H24: =IF(AND(ISNUMBER(D24),ISNUMBER(C24)),IF(D24<=C24,"✓","✗"),"") -> ✗
B25: RENEWALS & RETENTION
B26: March
B27: Expirations | C27: — | D27: {=IFERROR(INDEX(Data_2!$D$42:$AC$42,1,$C$3+2),"")} -> 58 | E27: =IF(OR(C27="—",NOT(ISNUMBER(C27))),"—",IFERROR(D27-C27,"—")) -> — | F27: {=IF($C$3>1,IFERROR(INDEX(Data_2!$D$42:$AC$42,1,$C$3+1),""),"")} -> 58 | G27: =IFERROR(D27-F27,"—") -> 0
B28: Early Move Outs | C28: =IFERROR(INDEX(Targets!$A$5:$R$28,$C$3,11),"—") -> 7 | D28: {=IFERROR(INDEX(Data_2!$D$43:$AC$43,1,$C$3+2),"")} -> 6 | E28: =IF(OR(C28="—",NOT(ISNUMBER(C28))),"—",IFERROR(D28-C28,"—")) -> -1 | F28: {=IF($C$3>1,IFERROR(INDEX(Data_2!$D$43:$AC$43,1,$C$3+1),""),"")} -> 6 | G28: =IFERROR(D28-F28,"—") -> 0
B29: NTV | C29: — | D29: {=IFERROR(INDEX(Data_2!$D$44:$AC$44,1,$C$3+2),"")} -> 14 | E29: =IF(OR(C29="—",NOT(ISNUMBER(C29))),"—",IFERROR(D29-C29,"—")) -> — | F29: {=IF($C$3>1,IFERROR(INDEX(Data_2!$D$44:$AC$44,1,$C$3+1),""),"")} -> 14 | G29: =IFERROR(D29-F29,"—") -> 0
B30: Renewal % | C30: =IFERROR(INDEX(Targets!$A$5:$R$28,$C$3,10),"—") -> 0.8 | D30: {=IFERROR(INDEX(Data_2!$D$45:$AC$45,1,$C$3+2),"")} -> 0.65517241 | E30: =IFERROR(D30-C30,"—") -> -0.14482759 | F30: {=IF($C$3>1,IFERROR(INDEX(Data_2!$D$45:$AC$45,1,$C$3+1),""),"")} -> 0.655 | G30: =IFERROR(D30-F30,"—") -> 0.00017241379 | H30: =IF(AND(ISNUMBER(D30),ISNUMBER(C30)),IF(D30>=C30,"✓","✗"),"") -> ✗
B31: April
B32: Expirations | C32: — | D32: {=IFERROR(INDEX(Data_2!$D$47:$AC$47,1,$C$3+2),"")} -> 60 | E32: =IF(OR(C32="—",NOT(ISNUMBER(C32))),"—",IFERROR(D32-C32,"—")) -> — | F32: {=IF($C$3>1,IFERROR(INDEX(Data_2!$D$47:$AC$47,1,$C$3+1),""),"")} -> 62 | G32: =IFERROR(D32-F32,"—") -> -2
B33: Early Move Outs | C33: =IFERROR(INDEX(Targets!$A$5:$R$28,$C$3,11),"—") -> 7 | D33: {=IFERROR(INDEX(Data_2!$D$48:$AC$48,1,$C$3+2),"")} -> 8 | E33: =IF(OR(C33="—",NOT(ISNUMBER(C33))),"—",IFERROR(D33-C33,"—")) -> 1 | F33: {=IF($C$3>1,IFERROR(INDEX(Data_2!$D$48:$AC$48,1,$C$3+1),""),"")} -> 5 | G33: =IFERROR(D33-F33,"—") -> 3
B34: NTV | C34: — | D34: {=IFERROR(INDEX(Data_2!$D$49:$AC$49,1,$C$3+2),"")} -> 17 | E34: =IF(OR(C34="—",NOT(ISNUMBER(C34))),"—",IFERROR(D34-C34,"—")) -> — | F34: {=IF($C$3>1,IFERROR(INDEX(Data_2!$D$49:$AC$49,1,$C$3+1),""),"")} -> 15 | G34: =IFERROR(D34-F34,"—") -> 2
B35: Renewal % | C35: =IFERROR(INDEX(Targets!$A$5:$R$28,$C$3,10),"—") -> 0.8 | D35: {=IFERROR(INDEX(Data_2!$D$50:$AC$50,1,$C$3+2),"")} -> 0.51666667 | E35: =IFERROR(D35-C35,"—") -> -0.28333333 | F35: {=IF($C$3>1,IFERROR(INDEX(Data_2!$D$50:$AC$50,1,$C$3+1),""),"")} -> 0.403 | G35: =IFERROR(D35-F35,"—") -> 0.11366667 | H35: =IF(AND(ISNUMBER(D35),ISNUMBER(C35)),IF(D35>=C35,"✓","✗"),"") -> ✗
B36: May
B37: Expirations | C37: — | D37: {=IFERROR(INDEX(Data_2!$D$52:$AC$52,1,$C$3+2),"")} -> 56 | E37: =IF(OR(C37="—",NOT(ISNUMBER(C37))),"—",IFERROR(D37-C37,"—")) -> — | F37: {=IF($C$3>1,IFERROR(INDEX(Data_2!$D$52:$AC$52,1,$C$3+1),""),"")} -> 56 | G37: =IFERROR(D37-F37,"—") -> 0
B38: Early Move Outs | C38: =IFERROR(INDEX(Targets!$A$5:$R$28,$C$3,11),"—") -> 7 | D38: {=IFERROR(INDEX(Data_2!$D$53:$AC$53,1,$C$3+2),"")} -> 6 | E38: =IF(OR(C38="—",NOT(ISNUMBER(C38))),"—",IFERROR(D38-C38,"—")) -> -1 | F38: {=IF($C$3>1,IFERROR(INDEX(Data_2!$D$53:$AC$53,1,$C$3+1),""),"")} -> 6 | G38: =IFERROR(D38-F38,"—") -> 0
B39: NTV | C39: — | D39: {=IFERROR(INDEX(Data_2!$D$54:$AC$54,1,$C$3+2),"")} -> 11 | E39: =IF(OR(C39="—",NOT(ISNUMBER(C39))),"—",IFERROR(D39-C39,"—")) -> — | F39: {=IF($C$3>1,IFERROR(INDEX(Data_2!$D$54:$AC$54,1,$C$3+1),""),"")} -> 11 | G39: =IFERROR(D39-F39,"—") -> 0
B40: Renewal % | C40: =IFERROR(INDEX(Targets!$A$5:$R$28,$C$3,10),"—") -> 0.8 | D40: {=IFERROR(INDEX(Data_2!$D$55:$AC$55,1,$C$3+2),"")} -> 0.39285714 | E40: =IFERROR(D40-C40,"—") -> -0.40714286 | F40: {=IF($C$3>1,IFERROR(INDEX(Data_2!$D$55:$AC$55,1,$C$3+1),""),"")} -> 0.304 | G40: =IFERROR(D40-F40,"—") -> 0.088857143 | H40: =IF(AND(ISNUMBER(D40),ISNUMBER(C40)),IF(D40>=C40,"✓","✗"),"") -> ✗
B41: June
...

Sheet Data_2
B1: AVA APARTMENTS
B2: Weekly Performance Data
D3: Pre-1 | E3: Pre-2 | F3: Wk1 | G3: Wk2 | H3: Wk3 | I3: Wk4 | J3: Wk5 | K3: Wk6 | L3: Wk7 | M3: Wk8 | N3: Wk9 | O3: Wk10 | P3: Wk11 | Q3: Wk12 | R3: Wk13 | S3: Wk14 | T3: Wk15 | U3: Wk16 | V3: Wk17 | W3: Wk18 | X3: Wk19 | Y3: Wk20 | Z3: Wk21 | AA3: Wk22 | AB3: Wk23 | AC3: Wk24
A4: Section | B4: KPI | C4: Format | D4: 46013 | E4: 46020 | F4: 46027 | G4: 46034 | H4: 46041 | I4: 46048 | J4: 46055 | K4: 46062 | L4: 46069 | M4: 46076 | N4: 46083 | O4: 46090 | P4: 46097 | Q4: 46104 | R4: 46111 | S4: 46118 | T4: 46125 | U4: 46132 | V4: 46139 | W4: 46146 | X4: 46153 | Y4: 46160 | Z4: 46167 | AA4: 46174 | AB4: 46181 | AC4: 46188
A5: OCCUPANCY
B6: Occupancy % | C6: 0 | D6: 0.7966 | E6: 0.8 | F6: 0.8 | G6: 0.8 | H6: 0.81142857 | I6: 0.77828571 | J6: 0.7783 | K6: 0.76773455 | L6: 0.75629291 | M6: 0.75171625 | N6: 0.74828375 | O6: 0.74141876 | P6: 0.73913043 | Q6: 0.73913043 | R6: 0.74141876 | S6: 0.72883295 | T6: 0.72311213 | U6: 0.7323 | V6: =SUM('Boxscore MMR -Availability'!$M:$M)/(SUM('Boxscore MMR -Availability'!$C:$C)-SUM('Boxscore MMR -Availability'!$F:$F)) -> 0.73112128
B7: Occupied Units | C7: #,##0 | D7: 701 | E7: 701 | F7: 704 | G7: 704 | H7: 710 | I7: 681 | J7: 681 | K7: 671 | L7: 661 | M7: 657 | N7: 654 | O7: 648 | P7: 646 | Q7: 646 | R7: 648 | S7: 637 | T7: 632 | U7: 640 | V7: =SUM('Boxscore MMR -Availability'!$M:$M) -> 639
B8: Total Units | C8: #,##0 | D8: 880 | E8: 880 | F8: 880 | G8: 880 | H8: 880 | I8: 880 | J8: 880 | K8: 880 | L8: 880 | M8: 880 | N8: 880 | O8: 880 | P8: 880 | Q8: 880 | R8: 880 | S8: 880 | T8: 880 | U8: 880 | V8: 880
A9: E1 | B9: Studio Occ % | C9: 0 | D9: 0.75 | E9: 0.8056 | F9: 0.8056 | G9: 0.80555556 | H9: 0.80555556 | I9: 0.77777778 | J9: 0.7778 | K9: 0.77777778 | L9: 0.77777778 | M9: 0.75 | N9: 0.75 | O9: 0.69444444 | P9: 0.72222222 | Q9: 0.72222222 | R9: 0.69444444 | S9: 0.61111111 | T9: 0.55555556 | U9: 0.5556 | V9: =SUMIF('Boxscore MMR -Availability'!$A:$M,Data_2!$A9,'Boxscore MMR -Availability'!$M:$M)/(SUMIF('Boxscore MMR -Availability'!$A:$M,Data_2!$A9,'Boxscore MMR -Availability'!$C:$C)-SUMIF('Boxscore MMR -Availability'!$A:$M,Data_2!$A9,'Boxscore MMR -Availability'!$F:$F)) -> 0.55555556
A10: A1, A2, A3, A4, A5, A6, A8S, A9TH, A10, A11 | B10: 1BR Occ % | C10: 0 | D10: 0.8165 | E10: 0.8339 | F10: 0.8339 | G10: 0.84469697 | H10: 0.85199241 | I10: 0.81214421 | J10: 0.8102 | K10: 0.79506641 | L10: 0.78747628 | M10: 0.78557875 | N10: 0.77798861 | O10: 0.77229602 | P10: 0.76280835 | Q10: 0.76091082 | R10: 0.76091082 | S10: 0.74383302 | T10: 0.73624288 | U10: 0.74 | V10: {=_xlfn.LET( _xlpm.list, TRIM(_xlfn.TEXTSPLIT(Data_2!$A10,",")), SUM(SUMIF('Boxscore MMR -Availability'!$A:$A, _xlpm.list, 'Boxscore MMR -Availability'!$M:$M)) / ( SUM(SUMIF('Boxscore MMR -Availability'!$A:$A, _xlpm.list, 'Boxscore MMR -Availability'!$C:$C)) - SUM(SUMIF('Boxscore MMR -Availability'!$A:$A, _xlpm.list, 'Boxscore MMR -Availability'!$F:$F)) ) )} -> 0.73814042
A11: B1, B2, B3, B4, B5, B6, B7TH, B8 | B11: 2BR Occ % | C11: 0 | D11: 0.7042 | E11: 0.7131 | F11: 0.7131 | G11: 0.71311475 | H11: 0.73333333 | I11: 0.7125 | J11: 0.7167 | K11: 0.71966527 | L11: 0.69456067 | M11: 0.68619247 | N11: 0.69037657 | O11: 0.68200837 | P11: 0.69874477 | Q11: 0.70292887 | R11: 0.71548117 | S11: 0.72384937 | T11: 0.72803347 | U11: 0.7573 | V11: {=_xlfn.LET( _xlpm.list, TRIM(_xlfn.TEXTSPLIT(Data_2!$A11,",")), SUM(SUMIF('Boxscore MMR -Availability'!$A:$A, _xlpm.list, 'Boxscore MMR -Availability'!$M:$M)) / ( SUM(SUMIF('Boxscore MMR -Availability'!$A:$A, _xlpm.list, 'Boxscore MMR -Availability'!$C:$C)) - SUM(SUMIF('Boxscore MMR -Availability'!$A:$A, _xlpm.list, 'Boxscore MMR -Availability'!$F:$F)) ) )} -> 0.75732218
A12: C1 | B12: 3BR Occ % | C12: 0 | D12: 0.875 | E12: 0.875 | F12: 0.875 | G12: 0.875 | H12: 0.875 | I12: 0.875 | J12: 0.875 | K12: 0.875 | L12: 0.875 | M12: 0.875 | N12: 0.875 | O12: 0.875 | P12: 0.875 | Q12: 0.875 | R12: 0.875 | S12: 0.8125 | T12: 0.8125 | U12: 0.8125 | V12: =SUMIF('Boxscore MMR -Availability'!$A:$M,Data_2!$A12,'Boxscore MMR -Availability'!$M:$M)/(SUMIF('Boxscore MMR -Availability'!$A:$M,Data_2!$A12,'Boxscore MMR -Availability'!$C:$C)-SUMIF('Boxscore MMR -Availability'!$A:$M,Data_2!$A12,'Boxscore MMR -Availability'!$F:$F)) -> 0.8125
B13: Exposure % | C13: 0 | D13: 0.2295 | E13: 0.2205 | F13: 0.2125 | G13: 0.2125 | H13: 0.20571429 | I13: 0.24228571 | J13: 0.232 | K13: 0.21167048 | L13: 0.20480549 | M13: 0.22425629 | N13: 0.24713959 | O13: 0.24942792 | P13: 0.25171625 | Q13: 0.26887872 | R13: 0.26773455 | S13: 0.27688787 | T13: 0.27803204 | U13: 0.2769 | V13: {=_xlfn.LET( _xlpm.num, SUM('Boxscore MMR -Availability'!$G:$G) + SUM('Boxscore MMR -Availability'!$K:$K), _xlpm.den, SUM('Boxscore MMR -Availability'!$C:$C) - SUM('Boxscore MMR -Availability'!$F:$F), _xlpm.num/_xlpm.den )} -> 0.28489703
A14: LEASING
B15: New Prospects | C15: #,##0 | D15: 36 | E15: 86 | F15: 141 | G15: 141 | H15: 88 | I15: 52 | J15: 83 | K15: 140 | L15: 149 | M15: 123 | N15: 103 | O15: 114 | P15: 124 | Q15: 147 | R15: 129 | S15: 119 | T15: 186 | U15: 210 | V15: =SUM('Boxscore MMR -Lead Activity'!$B:$B) -> 246
B16: Tours | C16: #,##0 | D16: 13 | E16: 5 | F16: 14 | G16: 14 | H16: 26 | I16: 18 | J16: 10 | K16: 28 | L16: 26 | M16: 28 | N16: 34 | O16: 28 | P16: 39 | Q16: 38 | R16: 24 | S16: 26 | T16: 25 | U16: 19 | V16: =SUM('Boxscore MMR -Lead Activity'!$N:$N) -> 26
B17: Tour Conversion % | C17: 0 | D17: =D16/D15 -> 0.36111111 | E17: =E16/E15 -> 0.058139535 | F17: =F16/F15 -> 0.09929078 | G17: 0.09929078 | H17: 0.29545455 | I17: 0.34615385 | J17: 0.1205 | K17: 0.2 | L17: 0.17449664 | M17: 0.22764228 | N17: 0.33009709 | O17: 0.24561404 | P17: 0.31451613 | Q17: 0.2585034 | R17: 0.18604651 | S17: 0.21848739 | T17: 0.1344086 | U17: 0.0905 | V17: =V16/V15 -> 0.10569106
B18: Submitted Apps | C18: #,##0 | D18: 3 | E18: 11 | F18: 9 | G18: 9 | H18: 7 | I18: 5 | J18: 12 | K18: 29 | L18: 23 | M18: 16 | N18: 13 | O18: 21 | P18: 26 | Q18: 15 | R18: 23 | S18: 12 | T18: 19 | U18: 13 | V18: =SUM('Boxscore MMR- Lead Conversion'!$B:$B) -> 20
B19: Approved Apps | C19: #,##0 | D19: 0 | E19: 0 | F19: 3 | G19: 3 | H19: 5 | I19: 1 | J19: 4 | K19: 2 | L19: 2 | M19: 1 | N19: 6 | O19: 5 | P19: 11 | Q19: 8 | R19: 8 | S19: 8 | T19: 6 | U19: 13 | V19: =SUM('Boxscore MMR- Lead Conversion'!$F:$F) -> 7
B20: Pending Apps | C20: #,##0 | D20: 3 | E20: 9 | F20: 5 | G20: 5 | H20: -2 | I20: -2 | J20: 5 | K20: 23 | L20: 11 | M20: -3 | N20: -19 | O20: -6 | P20: 6 | Q20: -13 | R20: 5 | S20: -10 | T20: 4 | U20: -9 | V20: =V18-V19-V21-V22 -> 3
B21: Cancelled Apps | C21: #,##0 | D21: 0 | E21: 0 | F21: 0 | G21: 0 | H21: 2 | I21: 4 | J21: 2 | K21: 2 | L21: 4 | M21: 16 | N21: 21 | O21: 20 | P21: 8 | Q21: 19 | R21: 9 | S21: 14 | T21: 9 | U21: 8 | V21: =SUM('Boxscore MMR- Lead Conversion'!$C:$C)+SUM('Boxscore MMR- Lead Conversion'!$G:$G) -> 8
B22: Denied Apps | C22: #,##0 | D22: 0 | E22: 2 | F22: 1 | G22: 1 | H22: 2 | I22: 2 | J22: 1 | K22: 2 | L22: 6 | M22: 2 | N22: 5 | O22: 2 | P22: 1 | Q22: 1 | R22: 1 | S22: 0 | T22: 0 | U22: 1 | V22: =SUM('Boxscore MMR- Lead Conversion'!$E:$E) -> 2
B23: Net Apps | C23: #,##0 | D23: =D18-D22-D21 -> 3 | E23: =E18-E22-E21 -> 9 | F23: =F18-F22-F21 -> 8 | G23: 8 | H23: 3 | I23: -1 | J23: 9 | K23: 25 | L23: 13 | M23: -2 | N23: -13 | O23: -1 | P23: 17 | Q23: -5 | R23: 13 | S23: -2 | T23: 10 | U23: 4 | V23: =V18-V22-V21 -> 10
B24: App Approval % | C24: 0 | D24: =D23/D18 -> 1 | E24: =E23/E18 -> 0.81818182 | F24: =F23/F18 -> 0.88888889 | G24: 0.88888889 | H24: 0.42857143 | I24: -0.2 | J24: 0.75 | K24: 0.86206897 | L24: 0.56521739 | M24: -0.125 | N24: -1 | O24: -0.047619048 | P24: 0.65384615 | Q24: -0.33333333 | R24: 0.56521739 | S24: -0.16666667 | T24: 0.52631579 | U24: 0.3077 | V24: =V23/V18 -> 0.5
B25: New Leases | C25: #,##0 | D25: 0 | E25: 0 | F25: 0 | G25: 3 | H25: 5 | I25: 2 | J25: 5 | K25: 2 | L25: 1 | M25: 1 | N25: 3 | O25: 7 | P25: 11 | Q25: 7 | R25: 8 | S25: 8 | T25: 3 | U25: 14 | V25: =SUM('Boxscore MMR- Lead Conversion'!$H:$H) -> 7
B26: Net Leases | C26: #,##0 | D26: 0 | E26: 0 | F26: 0 | G26: 3 | H26: 4 | I26: 2 | J26: 5 | K26: 2 | L26: 1 | M26: 1 | N26: 3 | O26: 7 | P26: 11 | Q26: 7 | R26: 8 | S26: 7 | T26: 3 | U26: 14 | V26: =SUM('Boxscore MMR- Lead Conversion'!$H:$H)-SUM('Boxscore MMR- Lead Conversion'!$I:$I) -> 7
A27: APP PIPELINE
B28: Total Apps in Pipeline | C28: #,##0 | N28: 90 | O28: 103 | P28: 113 | Q28: 116 | R28: 126 | S28: 136 | T28: 141 | U28: 145 | V28: =App_Pipeline_Intel_4!$C$5 -> 168
B29: Still Actively Open | C29: #,##0 | N29: 59 | O29: 53 | P29: 52 | Q29: 51 | R29: 56 | S29: 34 | T29: 37 | U29: 36 | V29: =App_Pipeline_Intel_4!$C$6 -> 46
B30: Converted to Lease | C30: #,##0 | N30: 5 | O30: 7 | P30: 11 | Q30: 7 | R30: 8 | S30: 7 | T30: 3 | U30: 14 | V30: =SUM('Boxscore MMR- Lead Conversion'!$H:$H)-SUM('Boxscore MMR- Lead Conversion'!$I:$I) -> 7
B31: Cancelled / Denied | C31: #,##0 | N31: 26 | O31: 38 | P31: 42 | Q31: 40 | R31: 40 | S31: 73 | T31: 75 | U31: 74 | V31: =App_Pipeline_Intel_4!$C$7 -> 80
B32: Conversion Rate | C32: 0 | N32: 0.055555556 | O32: 0.067961165 | P32: 0.097345133 | Q32: 0.060344828 | R32: 0.063492063 | S32: 0.051470588 | T32: 0.021276596 | U32: 0.097 | V32: =IFERROR(V30/V28,0) -> 0.041666667
B33: Loss Rate | C33: 0 | N33: 0.28888889 | O33: 0.36893204 | P33: 0.37168142 | Q33: 0.34482759 | R33: 0.31746032 | S33: 0.53676471 | T33: 0.53191489 | U33: 0.51 | V33: =IFERROR(V31/V28,0) -> 0.47619048
B34: Apps 15+ Days Old | C34: #,##0 | N34: 21 | O34: 25 | P34: 20 | Q34: 25 | R34: 30 | S34: 11 | T34: 13 | U34: 18 | V34: =App_Pipeline_Intel_4!$H$7+App_Pipeline_Intel_4!$H$8+App_Pipeline_Intel_4!$H$9 -> 21
B35: Avg Days to Decision | C35: 0 | N35: 11 | O35: 11.9 | P35: 11.2 | Q35: 18.1 | R35: 11.8 | S35: 9.8 | T35: 12.8 | U35: 18.1 | V35: =IFERROR(VALUE(LEFT(App_Pipeline_Intel_4!$C$16,FIND(" ",App_Pipeline_Intel_4!$C$16)-1)),0) -> 15.8
A36: RENEWALS - JUNE
A37: 46174 | B37: Expirations | C37: #,##0 | S37: 54 | T37: 54 | U37: 54 | V37: =SUMIF('Resident Retention -12 months'!$B:$J,Data_2!$A$37,'Resident Retention -12 months'!$C:$C)-SUMIF('Resident Retention -12 months'!$B:$J,Data_2!$A$37,'Resident Retention -12 months'!$J:$J) -> 55
B38: Early Move Outs | C38: #,##0 | S38: 10 | T38: 10 | U38: 10 | V38: =SUMIF('Resident Retention -12 months'!$B:$J,Data_2!$A$37,'Resident Retention -12 months'!$D:$D) -> 12
B39: NTV | C39: #,##0 | S39: 1 | T39: 2 | U39: 6 | V39: =SUMIF('Resident Retention -12 months'!$B:$J,Data_2!$A$37,'Resident Retention -12 months'!$E:$E) -> 7
B40: Renewal % | C40: 0 | S40: 0.018518519 | T40: 0.074074074 | U40: 0.148 | V40: =SUMIF('Resident Retention -12 months'!$B:$J,$A$37,'Resident Retention -12 months'!$F:$F)/V37 -> 0.29090909
...

Sheet Delinquency_Detail_3
B1: AVA APARTMENTS | N1: MOVED OUT OVERRIDE | P1: CURRENT OVERRIDE
B2: Delinquency Detail | N2: (Add resident names here to force into Former section) | P2: (Eviction-in-process residents to show in Current section)
B3: As of: | C3: =Dashboard_1!F3 -> 46139 | G3: Min Bal Filter: | H3: 750 | I3: ← Adjust current threshold | N3: Smiley, Brianca | P3: Sanders, Dwayne
B4: DELINQUENCY SUMMARY | N4: Perez, Jocelyn | P4: Harris, Mahogany
B5: Total Delinquency | C5: =SUMIF('resident aged receivable'!I:I,">0",'resident aged receivable'!I:I) -> 810268.66 | G5: 0-30 Days | H5: =SUMIF('resident aged receivable'!J:J,">0",'resident aged receivable'!J:J) -> 144772.62 | N5: Means, Alexxis | P5: Fridia, Rodrinesha
B6: Delinquent Accounts | C6: =COUNTIF('resident aged receivable'!I:I,">0") -> 193 | G6: 31-60 Days | H6: =SUMIF('resident aged receivable'!K:K,">0",'resident aged receivable'!K:K) -> 148400.2 | N6: Cetz, Manuel | P6: Hishaw, Ilona
B7: Evictions | C7: =COUNTIF('resident aged receivable'!E:E,"Past - Eviction")+COUNTIF('resident aged receivable'!E:E,"Current - Eviction") -> 19 | G7: Eviction Exposure | H7: =SUMIFS('resident aged receivable'!I:I,'resident aged receivable'!E:E,"Past - Eviction")+SUMIFS('resident aged receivable'!I:I,'resident aged receivable'!E:E,"Current - Eviction") -> 189054.75 | N7: Elhakim, Ahmed | P7: Meraz, Elvira
B8: Skips | C8: =COUNTIF('resident aged receivable'!E:E,"Past - Skip") -> 51 | G8: Skip Exposure | H8: =SUMIFS('resident aged receivable'!I:I,'resident aged receivable'!E:E,"Past - Skip") -> 317056.23 | N8: Taiwo, Yejide | P8: Simpson, William
B9: Pending Eviction $ | C9: =SUMIFS('resident aged receivable'!I:I,'resident aged receivable'!E:E,"Current - Grace Period")+SUMIFS('resident aged receivable'!I:I,'resident aged receivable'!E:E,"Notice - Grace Period")+SUMIFS('resident aged receivable'!I:I,'resident aged receivable'!E:E,"Current - Eviction") -> 76690.44 | G9: Current Delinq $ | H9: =SUMIFS('resident aged receivable'!I:I,'resident aged receivable'!E:E,"Current")+SUMIFS('resident aged receivable'!I:I,'resident aged receivable'!E:E,"Current - Month To Month") -> 110493.13 | P9: Taylor, Talika
B10: LEASELOCK SUMMARY | P10: Allen, Quentin
B11: Total Claimed | C11: =SUM(LeaseLock!L2:L500) -> 385325.61 | D11: Open Claims | E11: =COUNTIF(LeaseLock!F2:F500,"Open") -> 2 | G11: Recovery Rate | H11: =IFERROR(SUM(LeaseLock!M2:M500)/SUM(LeaseLock!L2:L500),0) -> 0.1844342 | P11: Cooks, Tatiana
B12: Total Paid | C12: =SUM(LeaseLock!M2:M500) -> 71067.22 | D12: Unfiled Claims | E12: {=SUMPRODUCT((B17:B134<>"")*1*(C17:C134<>"")*1*(K17:K134="")*1)} -> 83 | G12: Net Loss | H12: =SUM(LeaseLock!L2:L500)-SUM(LeaseLock!M2:M500) -> 314258.39 | P12: Sparks, Dija
B13: Claims Filed | C13: =COUNTA(LeaseLock!A2:A500) -> 134 | D13: Est. Recovery (unfiled) | E13: {=SUMPRODUCT((B17:B134<>"")*1*(C17:C134<>"")*1*(K17:K134="")*1)*1500} -> 124500 | G13: Claims Denied | H13: =COUNTIF(LeaseLock!F2:F500,"Claim Denied")&" ("&TEXT(IFERROR(COUNTIF(LeaseLock!F2:F500,"Claim Denied")/COUNTA(LeaseLock!A2:A500),0),"0%")&")" -> 13 (10%) | P13: Jackson, Leo
D14: Est. Recovery (total) | E14: {=SUMIFS(LeaseLock!L2:L500,LeaseLock!F2:F500,"Open")+SUMPRODUCT((B17:B134<>"")*1*(C17:C134<>"")*1*(K17:K134="")*1)*1500} -> 131610.5 | G14: Avg Recovery | H14: =IFERROR(SUM(LeaseLock!M2:M500)/COUNTA(LeaseLock!A2:A500),0) -> 530.35239
B15: EVICTIONS & FORMER RESIDENTS
B16: Unit | C16: Resident | D16: Move-In Date | E16: Move-Out Date | F16: IPS/CAF | G16: Status | H16: Total Bal. | I16: 0-30 | J16: 31-60 | K16: LeaseLock | L16: Collection/Leaselock Notes
A17: {=IFERROR(_xlfn.LET(_xlpm.n,ROW()-12,_xlpm.adj,IF((((ISNUMBER(SEARCH("Eviction",'resident aged receivable'!$E$2:$E$500)))+(ISNUMBER(SEARCH("Past",'resident aged receivable'!$E$2:$E$500)))+(ISNUMBER(SEARCH("Skip",'resident aged receivable'!$E$2:$E$500)))+(ISNUMBER(SEARCH("Collections",'resident aged receivable'!$E$2:$E$500)))+(COUNTIF($N$3:$N$24,'resident aged receivable'!$D$2:$D$500)>0))>0)*(COUNTIF($P$3:$P$24,'resident aged receivable'!$D$2:$D$500)=0)*('resident aged receivable'!$I$2:$I$500>0),'resident aged receivable'!$I$2:$I$500-ROW('resident aged receivable'!$I$2:$I$500)/1000000),_xlpm.tgt,LARGE(_xlpm.adj,_xlpm.n),MATCH(_xlpm.tgt,_xlpm.adj,0)+1),"")} -> 193 | B17: {=IF($A17="","",INDEX('resident aged receivable'!$B:$B,$A17))} -> W28-2-1020 | C17: {=IF($A17="","",INDEX('resident aged receivable'!$D:$D,$A17))} -> Alexander, Leaujodon | D17: {=IF($A17="","",INDEX('resident aged receivable'!$F:$F,$A17))} -> 45859 | E17: {=IF($A17="","",_xlfn.LET(_xlpm.leaseEnd,INDEX('resident aged receivable'!$H:$H,$A17),_xlpm.moLookup,IFERROR(_xlfn.LET(_xlpm.lastFirst,C17,_xlpm.lastName,IFERROR(TRIM(LEFT(_xlpm.lastFirst,FIND(",",_xlpm.lastFirst)-1)),_xlpm.lastFirst),_xlpm.firstName,IFERROR(TRIM(MID(_xlpm.lastFirst,FIND(",",_xlpm.lastFirst)+1,100)),""),_xlpm.matches,IF((ISNUMBER(SEARCH(_xlpm.lastName,Move_Outs_ResMan!$C$8:$C$500)))*(ISNUMBER(SEARCH(_xlpm.firstName,Move_Outs_ResMan!$C$8:$C$500))),Move_Outs_ResMan!$G$8:$G$500),_xlpm.maxDate,MAX(_xlpm.matches),IF(_xlpm.maxDate=0,"",_xlpm.maxDate)),""),IF(ISNUMBER(_xlpm.leaseEnd),_xlpm.leaseEnd,IF(_xlpm.moLookup="","",_xlpm.moLookup))))} -> 46223 | F17: =IF(D17="","",IF(D17<DATE(2025,12,15),"IPS","CAF")) -> IPS | G17: {=IF($A17="","",IF(COUNTIF($N$3:$N$24,C17)>0,"Former",_xlfn.LET(_xlpm.s,INDEX('resident aged receivable'!$E:$E,$A17),IF(ISNUMBER(SEARCH("Eviction",_xlpm.s)),"Eviction",IF(ISNUMBER(SEARCH("Skip",_xlpm.s)),"Skip",IF(ISNUMBER(SEARCH("Past",_xlpm.s))+ISNUMBER(SEARCH("Collections",_xlpm.s)),"Former",_xlpm.s))))))} -> Eviction | H17: {=IF($A17="","",INDEX('resident aged receivable'!$I:$I,$A17))} -> 15452.24 | I17: {=IF($A17="","",INDEX('resident aged receivable'!$J:$J,$A17))} -> 1667.27 | J17: {=IF($A17="","",INDEX('resident aged receivable'!$K:$K,$A17))} -> 1674.19 | K17: {=IFERROR(IF(B17="","",IF(SUMPRODUCT((LeaseLock!$D$2:$D$500=B17)*ISNUMBER(SEARCH(LEFT(C17,FIND(",",C17&",")-1),LeaseLock!$C$2:$C$500)))=0,"",IF(LOOKUP(2,1/((LeaseLock!$D$2:$D$500=B17)*ISNUMBER(SEARCH(LEFT(C17,FIND(",",C17&",")-1),LeaseLock!$C$2:$C$500))),LeaseLock!$F$2:$F$500)="Claim Denied","Claim Denied ("&LOOKUP(2,1/((LeaseLock!$D$2:$D$500=B17)*ISNUMBER(SEARCH(LEFT(C17,FIND(",",C17&",")-1),LeaseLock!$C$2:$C$500))),LeaseLock!$G$2:$G$500)&")",IF(LOOKUP(2,1/((LeaseLock!$D$2:$D$500=B17)*ISNUMBER(SEARCH(LEFT(C17,FIND(",",C17&",")-1),LeaseLock!$C$2:$C$500))),LeaseLock!$F$2:$F$500)="Open","Open - "&LOOKUP(2,1/((LeaseLock!$D$2:$D$500=B17)*ISNUMBER(SEARCH(LEFT(C17,FIND(",",C17&",")-1),LeaseLock!$C$2:$C$500))),LeaseLock!$G$2:$G$500),IF(LOOKUP(2,1/((LeaseLock!$D$2:$D$500=B17)*ISNUMBER(SEARCH(LEFT(C17,FIND(",",C17&",")-1),LeaseLock!$C$2:$C$500))),LeaseLock!$M$2:$M$500)>0,LOOKUP(2,1/((LeaseLock!$D$2:$D$500=B17)*ISNUMBER(SEARCH(LEFT(C17,FIND(",",C17&",")-1),LeaseLock!$C$2:$C$500))),LeaseLock!$F$2:$F$500)&" - $"&TEXT(LOOKUP(2,1/((LeaseLock!$D$2:$D$500=B17)*ISNUMBER(SEARCH(LEFT(C17,FIND(",",C17&",")-1),LeaseLock!$C$2:$C$500))),LeaseLock!$M$2:$M$500),"#,##0.00")&" paid",LOOKUP(2,1/((LeaseLock!$D$2:$D$500=B17)*ISNUMBER(SEARCH(LEFT(C17,FIND(",",C17&",")-1),LeaseLock!$C$2:$C$500))),LeaseLock!$F$2:$F$500)&" - no payment"))))),"")}
A18: {=IFERROR(_xlfn.LET(_xlpm.n,ROW()-12,_xlpm.adj,IF((((ISNUMBER(SEARCH("Eviction",'resident aged receivable'!$E$2:$E$500)))+(ISNUMBER(SEARCH("Past",'resident aged receivable'!$E$2:$E$500)))+(ISNUMBER(SEARCH("Skip",'resident aged receivable'!$E$2:$E$500)))+(ISNUMBER(SEARCH("Collections",'resident aged receivable'!$E$2:$E$500)))+(COUNTIF($N$3:$N$24,'resident aged receivable'!$D$2:$D$500)>0))>0)*(COUNTIF($P$3:$P$24,'resident aged receivable'!$D$2:$D$500)=0)*('resident aged receivable'!$I$2:$I$500>0),'resident aged receivable'!$I$2:$I$500-ROW('resident aged receivable'!$I$2:$I$500)/1000000),_xlpm.tgt,LARGE(_xlpm.adj,_xlpm.n),MATCH(_xlpm.tgt,_xlpm.adj,0)+1),"")} -> 11 | B18: {=IF($A18="","",INDEX('resident aged receivable'!$B:$B,$A18))} -> N03-2021 | C18: {=IF($A18="","",INDEX('resident aged receivable'!$D:$D,$A18))} -> Brown, Nicole | D18: {=IF($A18="","",INDEX('resident aged receivable'!$F:$F,$A18))} -> 45757 | E18: {=IF($A18="","",_xlfn.LET(_xlpm.leaseEnd,INDEX('resident aged receivable'!$H:$H,$A18),_xlpm.moLookup,IFERROR(_xlfn.LET(_xlpm.lastFirst,C18,_xlpm.lastName,IFERROR(TRIM(LEFT(_xlpm.lastFirst,FIND(",",_xlpm.lastFirst)-1)),_xlpm.lastFirst),_xlpm.firstName,IFERROR(TRIM(MID(_xlpm.lastFirst,FIND(",",_xlpm.lastFirst)+1,100)),""),_xlpm.matches,IF((ISNUMBER(SEARCH(_xlpm.lastName,Move_Outs_ResMan!$C$8:$C$500)))*(ISNUMBER(SEARCH(_xlpm.firstName,Move_Outs_ResMan!$C$8:$C$500))),Move_Outs_ResMan!$G$8:$G$500),_xlpm.maxDate,MAX(_xlpm.matches),IF(_xlpm.maxDate=0,"",_xlpm.maxDate)),""),IF(ISNUMBER(_xlpm.leaseEnd),_xlpm.leaseEnd,IF(_xlpm.moLookup="","",_xlpm.moLookup))))} -> 46182 | F18: =IF(D18="","",IF(D18<DATE(2025,12,15),"IPS","CAF")) -> IPS | G18: {=IF($A18="","",IF(COUNTIF($N$3:$N$24,C18)>0,"Former",_xlfn.LET(_xlpm.s,INDEX('resident aged receivable'!$E:$E,$A18),IF(ISNUMBER(SEARCH("Eviction",_xlpm.s)),"Eviction",IF(ISNUMBER(SEARCH("Skip",_xlpm.s)),"Skip",IF(ISNUMBER(SEARCH("Past",_xlpm.s))+ISNUMBER(SEARCH("Collections",_xlpm.s)),"Former",_xlpm.s))))))} -> Skip | H18: {=IF($A18="","",INDEX('resident aged receivable'!$I:$I,$A18))} -> 13768.56 | I18: {=IF($A18="","",INDEX('resident aged receivable'!$J:$J,$A18))} -> 5137.76 | J18: {=IF($A18="","",INDEX('resident aged receivable'!$K:$K,$A18))} -> 1112.87 | K18: {=IFERROR(IF(B18="","",IF(SUMPRODUCT((LeaseLock!$D$2:$D$500=B18)*ISNUMBER(SEARCH(LEFT(C18,FIND(",",C18&",")-1),LeaseLock!$C$2:$C$500)))=0,"",IF(LOOKUP(2,1/((LeaseLock!$D$2:$D$500=B18)*ISNUMBER(SEARCH(LEFT(C18,FIND(",",C18&",")-1),LeaseLock!$C$2:$C$500))),LeaseLock!$F$2:$F$500)="Claim Denied","Claim Denied ("&LOOKUP(2,1/((LeaseLock!$D$2:$D$500=B18)*ISNUMBER(SEARCH(LEFT(C18,FIND(",",C18&",")-1),LeaseLock!$C$2:$C$500))),LeaseLock!$G$2:$G$500)&")",IF(LOOKUP(2,1/((LeaseLock!$D$2:$D$500=B18)*ISNUMBER(SEARCH(LEFT(C18,FIND(",",C18&",")-1),LeaseLock!$C$2:$C$500))),LeaseLock!$F$2:$F$500)="Open","Open - "&LOOKUP(2,1/((LeaseLock!$D$2:$D$500=B18)*ISNUMBER(SEARCH(LEFT(C18,FIND(",",C18&",")-1),LeaseLock!$C$2:$C$500))),LeaseLock!$G$2:$G$500),IF(LOOKUP(2,1/((LeaseLock!$D$2:$D$500=B18)*ISNUMBER(SEARCH(LEFT(C18,FIND(",",C18&",")-1),LeaseLock!$C$2:$C$500))),LeaseLock!$M$2:$M$500)>0,LOOKUP(2,1/((LeaseLock!$D$2:$D$500=B18)*ISNUMBER(SEARCH(LEFT(C18,FIND(",",C18&",")-1),LeaseLock!$C$2:$C$500))),LeaseLock!$F$2:$F$500)&" - $"&TEXT(LOOKUP(2,1/((LeaseLock!$D$2:$D$500=B18)*ISNUMBER(SEARCH(LEFT(C18,FIND(",",C18&",")-1),LeaseLock!$C$2:$C$500))),LeaseLock!$M$2:$M$500),"#,##0.00")&" paid",LOOKUP(2,1/((LeaseLock!$D$2:$D$500=B18)*ISNUMBER(SEARCH(LEFT(C18,FIND(",",C18&",")-1),LeaseLock!$C$2:$C$500))),LeaseLock!$F$2:$F$500)&" - no payment"))))),"")}
A19: {=IFERROR(_xlfn.LET(_xlpm.n,ROW()-12,_xlpm.adj,IF((((ISNUMBER(SEARCH("Eviction",'resident aged receivable'!$E$2:$E$500)))+(ISNUMBER(SEARCH("Past",'resident aged receivable'!$E$2:$E$500)))+(ISNUMBER(SEARCH("Skip",'resident aged receivable'!$E$2:$E$500)))+(ISNUMBER(SEARCH("Collections",'resident aged receivable'!$E$2:$E$500)))+(COUNTIF($N$3:$N$24,'resident aged receivable'!$D$2:$D$500)>0))>0)*(COUNTIF($P$3:$P$24,'resident aged receivable'!$D$2:$D$500)=0)*('resident aged receivable'!$I$2:$I$500>0),'resident aged receivable'!$I$2:$I$500-ROW('resident aged receivable'!$I$2:$I$500)/1000000),_xlpm.tgt,LARGE(_xlpm.adj,_xlpm.n),MATCH(_xlpm.tgt,_xlpm.adj,0)+1),"")} -> 113 | B19: {=IF($A19="","",INDEX('resident aged receivable'!$B:$B,$A19))} -> W07-1-0715 | C19: {=IF($A19="","",INDEX('resident aged receivable'!$D:$D,$A19))} -> Miller, Faye | D19: {=IF($A19="","",INDEX('resident aged receivable'!$F:$F,$A19))} -> 45485 | E19: {=IF($A19="","",_xlfn.LET(_xlpm.leaseEnd,INDEX('resident aged receivable'!$H:$H,$A19),_xlpm.moLookup,IFERROR(_xlfn.LET(_xlpm.lastFirst,C19,_xlpm.lastName,IFERROR(TRIM(LEFT(_xlpm.lastFirst,FIND(",",_xlpm.lastFirst)-1)),_xlpm.lastFirst),_xlpm.firstName,IFERROR(TRIM(MID(_xlpm.lastFirst,FIND(",",_xlpm.lastFirst)+1,100)),""),_xlpm.matches,IF((ISNUMBER(SEARCH(_xlpm.lastName,Move_Outs_ResMan!$C$8:$C$500)))*(ISNUMBER(SEARCH(_xlpm.firstName,Move_Outs_ResMan!$C$8:$C$500))),Move_Outs_ResMan!$G$8:$G$500),_xlpm.maxDate,MAX(_xlpm.matches),IF(_xlpm.maxDate=0,"",_xlpm.maxDate)),""),IF(ISNUMBER(_xlpm.leaseEnd),_xlpm.leaseEnd,IF(_xlpm.moLookup="","",_xlpm.moLookup))))} -> 46276 | F19: =IF(D19="","",IF(D19<DATE(2025,12,15),"IPS","CAF")) -> IPS | G19: {=IF($A19="","",IF(COUNTIF($N$3:$N$24,C19)>0,"Former",_xlfn.LET(_xlpm.s,INDEX('resident aged receivable'!$E:$E,$A19),IF(ISNUMBER(SEARCH("Eviction",_xlpm.s)),"Eviction",IF(ISNUMBER(SEARCH("Skip",_xlpm.s)),"Skip",IF(ISNUMBER(SEARCH("Past",_xlpm.s))+ISNUMBER(SEARCH("Collections",_xlpm.s)),"Former",_xlpm.s))))))} -> Skip | H19: {=IF($A19="","",INDEX('resident aged receivable'!$I:$I,$A19))} -> 13430.36 | I19: {=IF($A19="","",INDEX('resident aged receivable'!$J:$J,$A19))} -> 4358.15 | J19: {=IF($A19="","",INDEX('resident aged receivable'!$K:$K,$A19))} -> 1226.11 | K19: {=IFERROR(IF(B19="","",IF(SUMPRODUCT((LeaseLock!$D$2:$D$500=B19)*ISNUMBER(SEARCH(LEFT(C19,FIND(",",C19&",")-1),LeaseLock!$C$2:$C$500)))=0,"",IF(LOOKUP(2,1/((LeaseLock!$D$2:$D$500=B19)*ISNUMBER(SEARCH(LEFT(C19,FIND(",",C19&",")-1),LeaseLock!$C$2:$C$500))),LeaseLock!$F$2:$F$500)="Claim Denied","Claim Denied ("&LOOKUP(2,1/((LeaseLock!$D$2:$D$500=B19)*ISNUMBER(SEARCH(LEFT(C19,FIND(",",C19&",")-1),LeaseLock!$C$2:$C$500))),LeaseLock!$G$2:$G$500)&")",IF(LOOKUP(2,1/((LeaseLock!$D$2:$D$500=B19)*ISNUMBER(SEARCH(LEFT(C19,FIND(",",C19&",")-1),LeaseLock!$C$2:$C$500))),LeaseLock!$F$2:$F$500)="Open","Open - "&LOOKUP(2,1/((LeaseLock!$D$2:$D$500=B19)*ISNUMBER(SEARCH(LEFT(C19,FIND(",",C19&",")-1),LeaseLock!$C$2:$C$500))),LeaseLock!$G$2:$G$500),IF(LOOKUP(2,1/((LeaseLock!$D$2:$D$500=B19)*ISNUMBER(SEARCH(LEFT(C19,FIND(",",C19&",")-1),LeaseLock!$C$2:$C$500))),LeaseLock!$M$2:$M$500)>0,LOOKUP(2,1/((LeaseLock!$D$2:$D$500=B19)*ISNUMBER(SEARCH(LEFT(C19,FIND(",",C19&",")-1),LeaseLock!$C$2:$C$500))),LeaseLock!$F$2:$F$500)&" - $"&TEXT(LOOKUP(2,1/((LeaseLock!$D$2:$D$500=B19)*ISNUMBER(SEARCH(LEFT(C19,FIND(",",C19&",")-1),LeaseLock!$C$2:$C$500))),LeaseLock!$M$2:$M$500),"#,##0.00")&" paid",LOOKUP(2,1/((LeaseLock!$D$2:$D$500=B19)*ISNUMBER(SEARCH(LEFT(C19,FIND(",",C19&",")-1),LeaseLock!$C$2:$C$500))),LeaseLock!$F$2:$F$500)&" - no payment"))))),"")} | L19: pending lease lock
A20: {=IFERROR(_xlfn.LET(_xlpm.n,ROW()-12,_xlpm.adj,IF((((ISNUMBER(SEARCH("Eviction",'resident aged receivable'!$E$2:$E$500)))+(ISNUMBER(SEARCH("Past",'resident aged receivable'!$E$2:$E$500)))+(ISNUMBER(SEARCH("Skip",'resident aged receivable'!$E$2:$E$500)))+(ISNUMBER(SEARCH("Collections",'resident aged receivable'!$E$2:$E$500)))+(COUNTIF($N$3:$N$24,'resident aged receivable'!$D$2:$D$500)>0))>0)*(COUNTIF($P$3:$P$24,'resident aged receivable'!$D$2:$D$500)=0)*('resident aged receivable'!$I$2:$I$500>0),'resident aged receivable'!$I$2:$I$500-ROW('resident aged receivable'!$I$2:$I$500)/1000000),_xlpm.tgt,LARGE(_xlpm.adj,_xlpm.n),MATCH(_xlpm.tgt,_xlpm.adj,0)+1),"")} -> 170 | B20: {=IF($A20="","",INDEX('resident aged receivable'!$B:$B,$A20))} -> W18-2-2070 | C20: {=IF($A20="","",INDEX('resident aged receivable'!$D:$D,$A20))} -> Candler, Brittany | D20: {=IF($A20="","",INDEX('resident aged receivable'!$F:$F,$A20))} -> 45706 | E20: {=IF($A20="","",_xlfn.LET(_xlpm.leaseEnd,INDEX('resident aged receivable'!$H:$H,$A20),_xlpm.moLookup,IFERROR(_xlfn.LET(_xlpm.lastFirst,C20,_xlpm.lastName,IFERROR(TRIM(LEFT(_xlpm.lastFirst,FIND(",",_xlpm.lastFirst)-1)),_xlpm.lastFirst),_xlpm.firstName,IFERROR(TRIM(MID(_xlpm.lastFirst,FIND(",",_xlpm.lastFirst)+1,100)),""),_xlpm.matches,IF((ISNUMBER(SEARCH(_xlpm.lastName,Move_Outs_ResMan!$C$8:$C$500)))*(ISNUMBER(SEARCH(_xlpm.firstName,Move_Outs_ResMan!$C$8:$C$500))),Move_Outs_ResMan!$G$8:$G$500),_xlpm.maxDate,MAX(_xlpm.matches),IF(_xlpm.maxDate=0,"",_xlpm.maxDate)),""),IF(ISNUMBER(_xlpm.leaseEnd),_xlpm.leaseEnd,IF(_xlpm.moLookup="","",_xlpm.moLookup))))} -> 46070 | F20: =IF(D20="","",IF(D20<DATE(2025,12,15),"IPS","CAF")) -> IPS | G20: {=IF($A20="","",IF(COUNTIF($N$3:$N$24,C20)>0,"Former",_xlfn.LET(_xlpm.s,INDEX('resident aged receivable'!$E:$E,$A20),IF(ISNUMBER(SEARCH("Eviction",_xlpm.s)),"Eviction",IF(ISNUMBER(SEARCH("Skip",_xlpm.s)),"Skip",IF(ISNUMBER(SEARCH("Past",_xlpm.s))+ISNUMBER(SEARCH("Collections",_xlpm.s)),"Former",_xlpm.s))))))} -> Eviction | H20: {=IF($A20="","",INDEX('resident aged receivable'!$I:$I,$A20))} -> 12763.04 | I20: {=IF($A20="","",INDEX('resident aged receivable'!$J:$J,$A20))} -> 0 | J20: {=IF($A20="","",INDEX('resident aged receivable'!$K:$K,$A20))} -> 1201.18 | K20: {=IFERROR(IF(B20="","",IF(SUMPRODUCT((LeaseLock!$D$2:$D$500=B20)*ISNUMBER(SEARCH(LEFT(C20,FIND(",",C20&",")-1),LeaseLock!$C$2:$C$500)))=0,"",IF(LOOKUP(2,1/((LeaseLock!$D$2:$D$500=B20)*ISNUMBER(SEARCH(LEFT(C20,FIND(",",C20&",")-1),LeaseLock!$C$2:$C$500))),LeaseLock!$F$2:$F$500)="Claim Denied","Claim Denied ("&LOOKUP(2,1/((LeaseLock!$D$2:$D$500=B20)*ISNUMBER(SEARCH(LEFT(C20,FIND(",",C20&",")-1),LeaseLock!$C$2:$C$500))),LeaseLock!$G$2:$G$500)&")",IF(LOOKUP(2,1/((LeaseLock!$D$2:$D$500=B20)*ISNUMBER(SEARCH(LEFT(C20,FIND(",",C20&",")-1),LeaseLock!$C$2:$C$500))),LeaseLock!$F$2:$F$500)="Open","Open - "&LOOKUP(2,1/((LeaseLock!$D$2:$D$500=B20)*ISNUMBER(SEARCH(LEFT(C20,FIND(",",C20&",")-1),LeaseLock!$C$2:$C$500))),LeaseLock!$G$2:$G$500),IF(LOOKUP(2,1/((LeaseLock!$D$2:$D$500=B20)*ISNUMBER(SEARCH(LEFT(C20,FIND(",",C20&",")-1),LeaseLock!$C$2:$C$500))),LeaseLock!$M$2:$M$500)>0,LOOKUP(2,1/((LeaseLock!$D$2:$D$500=B20)*ISNUMBER(SEARCH(LEFT(C20,FIND(",",C20&",")-1),LeaseLock!$C$2:$C$500))),LeaseLock!$F$2:$F$500)&" - $"&TEXT(LOOKUP(2,1/((LeaseLock!$D$2:$D$500=B20)*ISNUMBER(SEARCH(LEFT(C20,FIND(",",C20&",")-1),LeaseLock!$C$2:$C$500))),LeaseLock!$M$2:$M$500),"#,##0.00")&" paid",LOOKUP(2,1/((LeaseLock!$D$2:$D$500=B20)*ISNUMBER(SEARCH(LEFT(C20,FIND(",",C20&",")-1),LeaseLock!$C$2:$C$500))),LeaseLock!$F$2:$F$500)&" - no payment"))))),"")} -> Closed - $750.00 paid
